telegram.ext.dispatcher - ERROR - No error handlers are registered, logging exception.
Traceback (most recent call last):
  File "/home/maximreutov/.local/lib/python3.7/site-packages/telegram/ext/dispatcher.py", line 555, in process_update
    handler.handle_update(update, self, check, context)
  File "/home/maximreutov/.local/lib/python3.7/site-packages/telegram/ext/handler.py", line 198, in handle_update
    return self.callback(update, context)
  File "botik.py", line 24, in message_handler
    chat_id = update.message.chat.id
AttributeError: 'NoneType' object has no attribute 'chat'
telegram.ext.dispatcher - ERROR - No error handlers are registered, logging exception.
Traceback (most recent call last):
  File "/home/maximreutov/.local/lib/python3.7/site-packages/telegram/ext/dispatcher.py", line 555, in process_update
    handler.handle_update(update, self, check, context)
  File "/home/maximreutov/.local/lib/python3.7/site-packages/telegram/ext/handler.py", line 198, in handle_update
    return self.callback(update, context)
  File "botik.py", line 24, in message_handler
    chat_id = update.message.chat.id
AttributeError: 'NoneType' object has no attribute 'chat'
telegram.ext.dispatcher - ERROR - No error handlers are registered, logging exception.
Traceback (most recent call last):
  File "/home/maximreutov/.local/lib/python3.7/site-packages/telegram/ext/dispatcher.py", line 555, in process_update
    handler.handle_update(update, self, check, context)
  File "/home/maximreutov/.local/lib/python3.7/site-packages/telegram/ext/handler.py", line 198, in handle_update
    return self.callback(update, context)
  File "botik.py", line 19, in start
    update.message.reply_text('ID чата - ', chat_id)
  File "/home/maximreutov/.local/lib/python3.7/site-packages/telegram/message.py", line 801, in reply_text
    entities=entities,
  File "/home/maximreutov/.local/lib/python3.7/site-packages/telegram/bot.py", line 130, in decorator
    result = func(*args, **kwargs)
  File "/home/maximreutov/.local/lib/python3.7/site-packages/telegram/bot.py", line 521, in send_message
    api_kwargs=api_kwargs,
  File "/home/maximreutov/.local/lib/python3.7/site-packages/telegram/ext/extbot.py", line 207, in _message
    api_kwargs=api_kwargs,
  File "/home/maximreutov/.local/lib/python3.7/site-packages/telegram/bot.py", line 332, in _message
    result = self._post(endpoint, data, timeout=timeout, api_kwargs=api_kwargs)
  File "/home/maximreutov/.local/lib/python3.7/site-packages/telegram/bot.py", line 296, in _post
    f'{self.base_url}/{endpoint}', data=data, timeout=effective_timeout
  File "/home/maximreutov/.local/lib/python3.7/site-packages/telegram/utils/request.py", line 366, in post
    **urlopen_kwargs,
  File "/home/maximreutov/.local/lib/python3.7/site-packages/telegram/utils/request.py", line 279, in _request_wrapper
    raise BadRequest(message)
telegram.error.BadRequest: Unsupported parse_mode
telegram.ext.dispatcher - ERROR - No error handlers are registered, logging exception.
Traceback (most recent call last):
  File "/home/maximreutov/.local/lib/python3.7/site-packages/telegram/ext/dispatcher.py", line 555, in process_update
    handler.handle_update(update, self, check, context)
  File "/home/maximreutov/.local/lib/python3.7/site-packages/telegram/ext/handler.py", line 198, in handle_update
    return self.callback(update, context)
  File "botik.py", line 24, in message_handler
    chat_id = update.message.chat.id
AttributeError: 'NoneType' object has no attribute 'chat'
telegram.ext.dispatcher - ERROR - No error handlers are registered, logging exception.
Traceback (most recent call last):
  File "/home/maximreutov/.local/lib/python3.7/site-packages/telegram/ext/dispatcher.py", line 555, in process_update
    handler.handle_update(update, self, check, context)
  File "/home/maximreutov/.local/lib/python3.7/site-packages/telegram/ext/handler.py", line 198, in handle_update
    return self.callback(update, context)
  File "botik.py", line 24, in message_handler
    chat_id = update.message.chat.id
AttributeError: 'NoneType' object has no attribute 'chat'
telegram.ext.dispatcher - ERROR - No error handlers are registered, logging exception.
Traceback (most recent call last):
  File "/home/maximreutov/.local/lib/python3.7/site-packages/telegram/ext/dispatcher.py", line 555, in process_update
    handler.handle_update(update, self, check, context)
  File "/home/maximreutov/.local/lib/python3.7/site-packages/telegram/ext/handler.py", line 198, in handle_update
    return self.callback(update, context)
  File "botik.py", line 24, in message_handler
    chat_id = update.message.chat.id
AttributeError: 'NoneType' object has no attribute 'chat'
telegram.ext.dispatcher - ERROR - No error handlers are registered, logging exception.
Traceback (most recent call last):
  File "/home/maximreutov/.local/lib/python3.7/site-packages/telegram/ext/dispatcher.py", line 555, in process_update
    handler.handle_update(update, self, check, context)
  File "/home/maximreutov/.local/lib/python3.7/site-packages/telegram/ext/handler.py", line 198, in handle_update
    return self.callback(update, context)
  File "botik.py", line 24, in message_handler
    chat_id = update.message.chat.id
AttributeError: 'NoneType' object has no attribute 'chat'
telegram.ext.dispatcher - ERROR - No error handlers are registered, logging exception.
Traceback (most recent call last):
  File "/home/maximreutov/.local/lib/python3.7/site-packages/telegram/ext/dispatcher.py", line 555, in process_update
    handler.handle_update(update, self, check, context)
  File "/home/maximreutov/.local/lib/python3.7/site-packages/telegram/ext/handler.py", line 198, in handle_update
    return self.callback(update, context)
  File "botik.py", line 24, in message_handler
    chat_id = update.message.chat.id
AttributeError: 'NoneType' object has no attribute 'chat'
telegram.ext.dispatcher - ERROR - No error handlers are registered, logging exception.
Traceback (most recent call last):
  File "/home/maximreutov/.local/lib/python3.7/site-packages/telegram/ext/dispatcher.py", line 555, in process_update
    handler.handle_update(update, self, check, context)
  File "/home/maximreutov/.local/lib/python3.7/site-packages/telegram/ext/handler.py", line 198, in handle_update
    return self.callback(update, context)
  File "botik.py", line 24, in message_handler
    chat_id = update.message.chat.id
AttributeError: 'NoneType' object has no attribute 'chat'
telegram.ext.dispatcher - ERROR - No error handlers are registered, logging exception.
Traceback (most recent call last):
  File "/home/maximreutov/.local/lib/python3.7/site-packages/telegram/ext/dispatcher.py", line 555, in process_update
    handler.handle_update(update, self, check, context)
  File "/home/maximreutov/.local/lib/python3.7/site-packages/telegram/ext/handler.py", line 198, in handle_update
    return self.callback(update, context)
  File "botik.py", line 24, in message_handler
    chat_id = update.message.chat.id
AttributeError: 'NoneType' object has no attribute 'chat'
telegram.ext.dispatcher - ERROR - No error handlers are registered, logging exception.
Traceback (most recent call last):
  File "/home/maximreutov/.local/lib/python3.7/site-packages/telegram/ext/dispatcher.py", line 555, in process_update
    handler.handle_update(update, self, check, context)
  File "/home/maximreutov/.local/lib/python3.7/site-packages/telegram/ext/handler.py", line 198, in handle_update
    return self.callback(update, context)
  File "botik.py", line 24, in message_handler
    chat_id = update.message.chat.id
AttributeError: 'NoneType' object has no attribute 'chat'
telegram.ext.dispatcher - ERROR - No error handlers are registered, logging exception.
Traceback (most recent call last):
  File "/home/maximreutov/.local/lib/python3.7/site-packages/telegram/ext/dispatcher.py", line 555, in process_update
    handler.handle_update(update, self, check, context)
  File "/home/maximreutov/.local/lib/python3.7/site-packages/telegram/ext/handler.py", line 198, in handle_update
    return self.callback(update, context)
  File "botik.py", line 24, in message_handler
    chat_id = update.message.chat.id
AttributeError: 'NoneType' object has no attribute 'chat'
telegram.ext.dispatcher - ERROR - No error handlers are registered, logging exception.
Traceback (most recent call last):
  File "/home/maximreutov/.local/lib/python3.7/site-packages/telegram/ext/dispatcher.py", line 555, in process_update
    handler.handle_update(update, self, check, context)
  File "/home/maximreutov/.local/lib/python3.7/site-packages/telegram/ext/handler.py", line 198, in handle_update
    return self.callback(update, context)
  File "botik.py", line 24, in message_handler
    chat_id = update.message.chat.id
AttributeError: 'NoneType' object has no attribute 'chat'
telegram.ext.dispatcher - ERROR - No error handlers are registered, logging exception.
Traceback (most recent call last):
  File "/home/maximreutov/.local/lib/python3.7/site-packages/telegram/ext/dispatcher.py", line 555, in process_update
    handler.handle_update(update, self, check, context)
  File "/home/maximreutov/.local/lib/python3.7/site-packages/telegram/ext/handler.py", line 198, in handle_update
    return self.callback(update, context)
  File "botik.py", line 24, in message_handler
    chat_id = update.message.chat.id
AttributeError: 'NoneType' object has no attribute 'chat'
telegram.ext.dispatcher - ERROR - No error handlers are registered, logging exception.
Traceback (most recent call last):
  File "/home/maximreutov/.local/lib/python3.7/site-packages/telegram/ext/dispatcher.py", line 555, in process_update
    handler.handle_update(update, self, check, context)
  File "/home/maximreutov/.local/lib/python3.7/site-packages/telegram/ext/handler.py", line 198, in handle_update
    return self.callback(update, context)
  File "botik.py", line 24, in message_handler
    chat_id = update.message.chat.id
AttributeError: 'NoneType' object has no attribute 'chat'
telegram.ext.dispatcher - ERROR - No error handlers are registered, logging exception.
Traceback (most recent call last):
  File "/home/maximreutov/.local/lib/python3.7/site-packages/telegram/ext/dispatcher.py", line 555, in process_update
    handler.handle_update(update, self, check, context)
  File "/home/maximreutov/.local/lib/python3.7/site-packages/telegram/ext/handler.py", line 198, in handle_update
    return self.callback(update, context)
  File "botik.py", line 24, in message_handler
    chat_id = update.message.chat.id
AttributeError: 'NoneType' object has no attribute 'chat'
telegram.ext.dispatcher - ERROR - No error handlers are registered, logging exception.
Traceback (most recent call last):
  File "/home/maximreutov/.local/lib/python3.7/site-packages/telegram/ext/dispatcher.py", line 555, in process_update
    handler.handle_update(update, self, check, context)
  File "/home/maximreutov/.local/lib/python3.7/site-packages/telegram/ext/handler.py", line 198, in handle_update
    return self.callback(update, context)
  File "botik.py", line 24, in message_handler
    chat_id = update.message.chat.id
AttributeError: 'NoneType' object has no attribute 'chat'
telegram.ext.dispatcher - ERROR - No error handlers are registered, logging exception.
Traceback (most recent call last):
  File "/home/maximreutov/.local/lib/python3.7/site-packages/telegram/ext/dispatcher.py", line 555, in process_update
    handler.handle_update(update, self, check, context)
  File "/home/maximreutov/.local/lib/python3.7/site-packages/telegram/ext/handler.py", line 198, in handle_update
    return self.callback(update, context)
  File "botik.py", line 24, in message_handler
    chat_id = update.message.chat.id
AttributeError: 'NoneType' object has no attribute 'chat'
telegram.ext.dispatcher - ERROR - No error handlers are registered, logging exception.
Traceback (most recent call last):
  File "/home/maximreutov/.local/lib/python3.7/site-packages/telegram/ext/dispatcher.py", line 555, in process_update
    handler.handle_update(update, self, check, context)
  File "/home/maximreutov/.local/lib/python3.7/site-packages/telegram/ext/handler.py", line 198, in handle_update
    return self.callback(update, context)
  File "botik.py", line 24, in message_handler
    chat_id = update.message.chat.id
AttributeError: 'NoneType' object has no attribute 'chat'
telegram.ext.dispatcher - ERROR - No error handlers are registered, logging exception.
Traceback (most recent call last):
  File "/home/maximreutov/.local/lib/python3.7/site-packages/telegram/ext/dispatcher.py", line 555, in process_update
    handler.handle_update(update, self, check, context)
  File "/home/maximreutov/.local/lib/python3.7/site-packages/telegram/ext/handler.py", line 198, in handle_update
    return self.callback(update, context)
  File "botik.py", line 24, in message_handler
    chat_id = update.message.chat.id
AttributeError: 'NoneType' object has no attribute 'chat'
telegram.ext.dispatcher - ERROR - No error handlers are registered, logging exception.
Traceback (most recent call last):
  File "/home/maximreutov/.local/lib/python3.7/site-packages/telegram/ext/dispatcher.py", line 555, in process_update
    handler.handle_update(update, self, check, context)
  File "/home/maximreutov/.local/lib/python3.7/site-packages/telegram/ext/handler.py", line 198, in handle_update
    return self.callback(update, context)
  File "botik.py", line 24, in message_handler
    chat_id = update.message.chat.id
AttributeError: 'NoneType' object has no attribute 'chat'
telegram.ext.dispatcher - ERROR - No error handlers are registered, logging exception.
Traceback (most recent call last):
  File "/home/maximreutov/.local/lib/python3.7/site-packages/telegram/ext/dispatcher.py", line 555, in process_update
    handler.handle_update(update, self, check, context)
  File "/home/maximreutov/.local/lib/python3.7/site-packages/telegram/ext/handler.py", line 198, in handle_update
    return self.callback(update, context)
  File "botik.py", line 24, in message_handler
    chat_id = update.message.chat.id
AttributeError: 'NoneType' object has no attribute 'chat'
telegram.ext.dispatcher - ERROR - No error handlers are registered, logging exception.
Traceback (most recent call last):
  File "/home/maximreutov/.local/lib/python3.7/site-packages/telegram/ext/dispatcher.py", line 555, in process_update
    handler.handle_update(update, self, check, context)
  File "/home/maximreutov/.local/lib/python3.7/site-packages/telegram/ext/handler.py", line 198, in handle_update
    return self.callback(update, context)
  File "botik.py", line 24, in message_handler
    chat_id = update.message.chat.id
AttributeError: 'NoneType' object has no attribute 'chat'
telegram.ext.dispatcher - ERROR - No error handlers are registered, logging exception.
Traceback (most recent call last):
  File "/home/maximreutov/.local/lib/python3.7/site-packages/telegram/ext/dispatcher.py", line 555, in process_update
    handler.handle_update(update, self, check, context)
  File "/home/maximreutov/.local/lib/python3.7/site-packages/telegram/ext/handler.py", line 198, in handle_update
    return self.callback(update, context)
  File "botik.py", line 28, in message_handler
    context.bot.send_message(chat_id = update.message.chat_id, text = generate_message(message, chat_id))
  File "/home/maximreutov/.local/lib/python3.7/site-packages/telegram/bot.py", line 130, in decorator
    result = func(*args, **kwargs)
  File "/home/maximreutov/.local/lib/python3.7/site-packages/telegram/bot.py", line 521, in send_message
    api_kwargs=api_kwargs,
  File "/home/maximreutov/.local/lib/python3.7/site-packages/telegram/ext/extbot.py", line 207, in _message
    api_kwargs=api_kwargs,
  File "/home/maximreutov/.local/lib/python3.7/site-packages/telegram/bot.py", line 332, in _message
    result = self._post(endpoint, data, timeout=timeout, api_kwargs=api_kwargs)
  File "/home/maximreutov/.local/lib/python3.7/site-packages/telegram/bot.py", line 296, in _post
    f'{self.base_url}/{endpoint}', data=data, timeout=effective_timeout
  File "/home/maximreutov/.local/lib/python3.7/site-packages/telegram/utils/request.py", line 366, in post
    **urlopen_kwargs,
  File "/home/maximreutov/.local/lib/python3.7/site-packages/telegram/utils/request.py", line 279, in _request_wrapper
    raise BadRequest(message)
telegram.error.BadRequest: Message text is empty
telegram.ext.dispatcher - ERROR - No error handlers are registered, logging exception.
Traceback (most recent call last):
  File "/home/maximreutov/.local/lib/python3.7/site-packages/telegram/ext/dispatcher.py", line 555, in process_update
    handler.handle_update(update, self, check, context)
  File "/home/maximreutov/.local/lib/python3.7/site-packages/telegram/ext/handler.py", line 198, in handle_update
    return self.callback(update, context)
  File "botik.py", line 24, in message_handler
    chat_id = update.message.chat.id
AttributeError: 'NoneType' object has no attribute 'chat'
telegram.ext.dispatcher - ERROR - No error handlers are registered, logging exception.
Traceback (most recent call last):
  File "/home/maximreutov/.local/lib/python3.7/site-packages/telegram/ext/dispatcher.py", line 555, in process_update
    handler.handle_update(update, self, check, context)
  File "/home/maximreutov/.local/lib/python3.7/site-packages/telegram/ext/handler.py", line 198, in handle_update
    return self.callback(update, context)
  File "botik.py", line 24, in message_handler
    chat_id = update.message.chat.id
AttributeError: 'NoneType' object has no attribute 'chat'
telegram.ext.dispatcher - ERROR - No error handlers are registered, logging exception.
Traceback (most recent call last):
  File "/home/maximreutov/.local/lib/python3.7/site-packages/telegram/ext/dispatcher.py", line 555, in process_update
    handler.handle_update(update, self, check, context)
  File "/home/maximreutov/.local/lib/python3.7/site-packages/telegram/ext/handler.py", line 198, in handle_update
    return self.callback(update, context)
  File "botik.py", line 24, in message_handler
    chat_id = update.message.chat.id
AttributeError: 'NoneType' object has no attribute 'chat'
telegram.ext.dispatcher - ERROR - No error handlers are registered, logging exception.
Traceback (most recent call last):
  File "/home/maximreutov/.local/lib/python3.7/site-packages/telegram/ext/dispatcher.py", line 555, in process_update
    handler.handle_update(update, self, check, context)
  File "/home/maximreutov/.local/lib/python3.7/site-packages/telegram/ext/handler.py", line 198, in handle_update
    return self.callback(update, context)
  File "botik.py", line 24, in message_handler
    chat_id = update.message.chat.id
AttributeError: 'NoneType' object has no attribute 'chat'
telegram.ext.dispatcher - ERROR - No error handlers are registered, logging exception.
Traceback (most recent call last):
  File "/home/maximreutov/.local/lib/python3.7/site-packages/telegram/ext/dispatcher.py", line 555, in process_update
    handler.handle_update(update, self, check, context)
  File "/home/maximreutov/.local/lib/python3.7/site-packages/telegram/ext/handler.py", line 198, in handle_update
    return self.callback(update, context)
  File "botik.py", line 24, in message_handler
    chat_id = update.message.chat.id
AttributeError: 'NoneType' object has no attribute 'chat'
telegram.ext.dispatcher - ERROR - No error handlers are registered, logging exception.
Traceback (most recent call last):
  File "/home/maximreutov/.local/lib/python3.7/site-packages/telegram/ext/dispatcher.py", line 555, in process_update
    handler.handle_update(update, self, check, context)
  File "/home/maximreutov/.local/lib/python3.7/site-packages/telegram/ext/handler.py", line 198, in handle_update
    return self.callback(update, context)
  File "botik.py", line 24, in message_handler
    chat_id = update.message.chat.id
AttributeError: 'NoneType' object has no attribute 'chat'
telegram.ext.dispatcher - ERROR - No error handlers are registered, logging exception.
Traceback (most recent call last):
  File "/home/maximreutov/.local/lib/python3.7/site-packages/telegram/ext/dispatcher.py", line 555, in process_update
    handler.handle_update(update, self, check, context)
  File "/home/maximreutov/.local/lib/python3.7/site-packages/telegram/ext/handler.py", line 198, in handle_update
    return self.callback(update, context)
  File "botik.py", line 24, in message_handler
    chat_id = update.message.chat.id
AttributeError: 'NoneType' object has no attribute 'chat'
telegram.ext.dispatcher - ERROR - No error handlers are registered, logging exception.
Traceback (most recent call last):
  File "/home/maximreutov/.local/lib/python3.7/site-packages/telegram/ext/dispatcher.py", line 555, in process_update
    handler.handle_update(update, self, check, context)
  File "/home/maximreutov/.local/lib/python3.7/site-packages/telegram/ext/handler.py", line 198, in handle_update
    return self.callback(update, context)
  File "botik.py", line 24, in message_handler
    chat_id = update.message.chat.id
AttributeError: 'NoneType' object has no attribute 'chat'
telegram.ext.dispatcher - ERROR - No error handlers are registered, logging exception.
Traceback (most recent call last):
  File "/home/maximreutov/.local/lib/python3.7/site-packages/telegram/ext/dispatcher.py", line 555, in process_update
    handler.handle_update(update, self, check, context)
  File "/home/maximreutov/.local/lib/python3.7/site-packages/telegram/ext/handler.py", line 198, in handle_update
    return self.callback(update, context)
  File "botik.py", line 24, in message_handler
    chat_id = update.message.chat.id
AttributeError: 'NoneType' object has no attribute 'chat'
telegram.ext.dispatcher - ERROR - No error handlers are registered, logging exception.
Traceback (most recent call last):
  File "/home/maximreutov/.local/lib/python3.7/site-packages/telegram/ext/dispatcher.py", line 555, in process_update
    handler.handle_update(update, self, check, context)
  File "/home/maximreutov/.local/lib/python3.7/site-packages/telegram/ext/handler.py", line 198, in handle_update
    return self.callback(update, context)
  File "botik.py", line 24, in message_handler
    chat_id = update.message.chat.id
AttributeError: 'NoneType' object has no attribute 'chat'
telegram.ext.dispatcher - ERROR - No error handlers are registered, logging exception.
Traceback (most recent call last):
  File "/home/maximreutov/.local/lib/python3.7/site-packages/telegram/ext/dispatcher.py", line 555, in process_update
    handler.handle_update(update, self, check, context)
  File "/home/maximreutov/.local/lib/python3.7/site-packages/telegram/ext/handler.py", line 198, in handle_update
    return self.callback(update, context)
  File "botik.py", line 24, in message_handler
    chat_id = update.message.chat.id
AttributeError: 'NoneType' object has no attribute 'chat'
telegram.ext.dispatcher - ERROR - No error handlers are registered, logging exception.
Traceback (most recent call last):
  File "/home/maximreutov/.local/lib/python3.7/site-packages/telegram/ext/dispatcher.py", line 555, in process_update
    handler.handle_update(update, self, check, context)
  File "/home/maximreutov/.local/lib/python3.7/site-packages/telegram/ext/handler.py", line 198, in handle_update
    return self.callback(update, context)
  File "botik.py", line 24, in message_handler
    chat_id = update.message.chat.id
AttributeError: 'NoneType' object has no attribute 'chat'
telegram.ext.dispatcher - ERROR - No error handlers are registered, logging exception.
Traceback (most recent call last):
  File "/home/maximreutov/.local/lib/python3.7/site-packages/telegram/ext/dispatcher.py", line 555, in process_update
    handler.handle_update(update, self, check, context)
  File "/home/maximreutov/.local/lib/python3.7/site-packages/telegram/ext/handler.py", line 198, in handle_update
    return self.callback(update, context)
  File "botik.py", line 24, in message_handler
    chat_id = update.message.chat.id
AttributeError: 'NoneType' object has no attribute 'chat'
telegram.ext.dispatcher - ERROR - No error handlers are registered, logging exception.
Traceback (most recent call last):
  File "/home/maximreutov/.local/lib/python3.7/site-packages/telegram/ext/dispatcher.py", line 555, in process_update
    handler.handle_update(update, self, check, context)
  File "/home/maximreutov/.local/lib/python3.7/site-packages/telegram/ext/handler.py", line 198, in handle_update
    return self.callback(update, context)
  File "botik.py", line 24, in message_handler
    chat_id = update.message.chat.id
AttributeError: 'NoneType' object has no attribute 'chat'
telegram.ext.dispatcher - ERROR - No error handlers are registered, logging exception.
Traceback (most recent call last):
  File "/home/maximreutov/.local/lib/python3.7/site-packages/telegram/ext/dispatcher.py", line 555, in process_update
    handler.handle_update(update, self, check, context)
  File "/home/maximreutov/.local/lib/python3.7/site-packages/telegram/ext/handler.py", line 198, in handle_update
    return self.callback(update, context)
  File "botik.py", line 24, in message_handler
    chat_id = update.message.chat.id
AttributeError: 'NoneType' object has no attribute 'chat'
telegram.ext.dispatcher - ERROR - No error handlers are registered, logging exception.
Traceback (most recent call last):
  File "/home/maximreutov/.local/lib/python3.7/site-packages/telegram/ext/dispatcher.py", line 555, in process_update
    handler.handle_update(update, self, check, context)
  File "/home/maximreutov/.local/lib/python3.7/site-packages/telegram/ext/handler.py", line 198, in handle_update
    return self.callback(update, context)
  File "botik.py", line 24, in message_handler
    chat_id = update.message.chat.id
AttributeError: 'NoneType' object has no attribute 'chat'
telegram.ext.dispatcher - ERROR - No error handlers are registered, logging exception.
Traceback (most recent call last):
  File "/home/maximreutov/.local/lib/python3.7/site-packages/telegram/ext/dispatcher.py", line 555, in process_update
    handler.handle_update(update, self, check, context)
  File "/home/maximreutov/.local/lib/python3.7/site-packages/telegram/ext/handler.py", line 198, in handle_update
    return self.callback(update, context)
  File "botik.py", line 24, in message_handler
    chat_id = update.message.chat.id
AttributeError: 'NoneType' object has no attribute 'chat'
telegram.ext.dispatcher - ERROR - No error handlers are registered, logging exception.
Traceback (most recent call last):
  File "/home/maximreutov/.local/lib/python3.7/site-packages/telegram/ext/dispatcher.py", line 555, in process_update
    handler.handle_update(update, self, check, context)
  File "/home/maximreutov/.local/lib/python3.7/site-packages/telegram/ext/handler.py", line 198, in handle_update
    return self.callback(update, context)
  File "botik.py", line 24, in message_handler
    chat_id = update.message.chat.id
AttributeError: 'NoneType' object has no attribute 'chat'
telegram.ext.dispatcher - ERROR - No error handlers are registered, logging exception.
Traceback (most recent call last):
  File "/home/maximreutov/.local/lib/python3.7/site-packages/telegram/ext/dispatcher.py", line 555, in process_update
    handler.handle_update(update, self, check, context)
  File "/home/maximreutov/.local/lib/python3.7/site-packages/telegram/ext/handler.py", line 198, in handle_update
    return self.callback(update, context)
  File "botik.py", line 24, in message_handler
    chat_id = update.message.chat.id
AttributeError: 'NoneType' object has no attribute 'chat'
telegram.ext.dispatcher - ERROR - No error handlers are registered, logging exception.
Traceback (most recent call last):
  File "/home/maximreutov/.local/lib/python3.7/site-packages/telegram/ext/dispatcher.py", line 555, in process_update
    handler.handle_update(update, self, check, context)
  File "/home/maximreutov/.local/lib/python3.7/site-packages/telegram/ext/handler.py", line 198, in handle_update
    return self.callback(update, context)
  File "botik.py", line 24, in message_handler
    chat_id = update.message.chat.id
AttributeError: 'NoneType' object has no attribute 'chat'
telegram.ext.dispatcher - ERROR - No error handlers are registered, logging exception.
Traceback (most recent call last):
  File "/home/maximreutov/.local/lib/python3.7/site-packages/telegram/ext/dispatcher.py", line 555, in process_update
    handler.handle_update(update, self, check, context)
  File "/home/maximreutov/.local/lib/python3.7/site-packages/telegram/ext/handler.py", line 198, in handle_update
    return self.callback(update, context)
  File "botik.py", line 24, in message_handler
    chat_id = update.message.chat.id
AttributeError: 'NoneType' object has no attribute 'chat'
telegram.ext.dispatcher - ERROR - No error handlers are registered, logging exception.
Traceback (most recent call last):
  File "/home/maximreutov/.local/lib/python3.7/site-packages/telegram/ext/dispatcher.py", line 555, in process_update
    handler.handle_update(update, self, check, context)
  File "/home/maximreutov/.local/lib/python3.7/site-packages/telegram/ext/handler.py", line 198, in handle_update
    return self.callback(update, context)
  File "botik.py", line 24, in message_handler
    chat_id = update.message.chat.id
AttributeError: 'NoneType' object has no attribute 'chat'
telegram.ext.dispatcher - ERROR - No error handlers are registered, logging exception.
Traceback (most recent call last):
  File "/home/maximreutov/.local/lib/python3.7/site-packages/telegram/ext/dispatcher.py", line 555, in process_update
    handler.handle_update(update, self, check, context)
  File "/home/maximreutov/.local/lib/python3.7/site-packages/telegram/ext/handler.py", line 198, in handle_update
    return self.callback(update, context)
  File "botik.py", line 24, in message_handler
    chat_id = update.message.chat.id
AttributeError: 'NoneType' object has no attribute 'chat'
telegram.ext.dispatcher - ERROR - No error handlers are registered, logging exception.
Traceback (most recent call last):
  File "/home/maximreutov/.local/lib/python3.7/site-packages/telegram/ext/dispatcher.py", line 555, in process_update
    handler.handle_update(update, self, check, context)
  File "/home/maximreutov/.local/lib/python3.7/site-packages/telegram/ext/handler.py", line 198, in handle_update
    return self.callback(update, context)
  File "botik.py", line 24, in message_handler
    chat_id = update.message.chat.id
AttributeError: 'NoneType' object has no attribute 'chat'
telegram.ext.dispatcher - ERROR - No error handlers are registered, logging exception.
Traceback (most recent call last):
  File "/home/maximreutov/.local/lib/python3.7/site-packages/telegram/ext/dispatcher.py", line 555, in process_update
    handler.handle_update(update, self, check, context)
  File "/home/maximreutov/.local/lib/python3.7/site-packages/telegram/ext/handler.py", line 198, in handle_update
    return self.callback(update, context)
  File "botik.py", line 24, in message_handler
    chat_id = update.message.chat.id
AttributeError: 'NoneType' object has no attribute 'chat'
telegram.ext.dispatcher - ERROR - No error handlers are registered, logging exception.
Traceback (most recent call last):
  File "/home/maximreutov/.local/lib/python3.7/site-packages/telegram/ext/dispatcher.py", line 555, in process_update
    handler.handle_update(update, self, check, context)
  File "/home/maximreutov/.local/lib/python3.7/site-packages/telegram/ext/handler.py", line 198, in handle_update
    return self.callback(update, context)
  File "botik.py", line 24, in message_handler
    chat_id = update.message.chat.id
AttributeError: 'NoneType' object has no attribute 'chat'
telegram.ext.dispatcher - ERROR - No error handlers are registered, logging exception.
Traceback (most recent call last):
  File "/home/maximreutov/.local/lib/python3.7/site-packages/telegram/ext/dispatcher.py", line 555, in process_update
    handler.handle_update(update, self, check, context)
  File "/home/maximreutov/.local/lib/python3.7/site-packages/telegram/ext/handler.py", line 198, in handle_update
    return self.callback(update, context)
  File "botik.py", line 24, in message_handler
    chat_id = update.message.chat.id
AttributeError: 'NoneType' object has no attribute 'chat'
telegram.ext.dispatcher - ERROR - No error handlers are registered, logging exception.
Traceback (most recent call last):
  File "/home/maximreutov/.local/lib/python3.7/site-packages/telegram/ext/dispatcher.py", line 555, in process_update
    handler.handle_update(update, self, check, context)
  File "/home/maximreutov/.local/lib/python3.7/site-packages/telegram/ext/handler.py", line 198, in handle_update
    return self.callback(update, context)
  File "botik.py", line 24, in message_handler
    chat_id = update.message.chat.id
AttributeError: 'NoneType' object has no attribute 'chat'
telegram.ext.dispatcher - ERROR - No error handlers are registered, logging exception.
Traceback (most recent call last):
  File "/home/maximreutov/.local/lib/python3.7/site-packages/telegram/ext/dispatcher.py", line 555, in process_update
    handler.handle_update(update, self, check, context)
  File "/home/maximreutov/.local/lib/python3.7/site-packages/telegram/ext/handler.py", line 198, in handle_update
    return self.callback(update, context)
  File "botik.py", line 24, in message_handler
    chat_id = update.message.chat.id
AttributeError: 'NoneType' object has no attribute 'chat'
telegram.ext.dispatcher - ERROR - No error handlers are registered, logging exception.
Traceback (most recent call last):
  File "/home/maximreutov/.local/lib/python3.7/site-packages/telegram/ext/dispatcher.py", line 555, in process_update
    handler.handle_update(update, self, check, context)
  File "/home/maximreutov/.local/lib/python3.7/site-packages/telegram/ext/handler.py", line 198, in handle_update
    return self.callback(update, context)
  File "botik.py", line 24, in message_handler
    chat_id = update.message.chat.id
AttributeError: 'NoneType' object has no attribute 'chat'
telegram.ext.dispatcher - ERROR - No error handlers are registered, logging exception.
Traceback (most recent call last):
  File "/home/maximreutov/.local/lib/python3.7/site-packages/telegram/ext/dispatcher.py", line 555, in process_update
    handler.handle_update(update, self, check, context)
  File "/home/maximreutov/.local/lib/python3.7/site-packages/telegram/ext/handler.py", line 198, in handle_update
    return self.callback(update, context)
  File "botik.py", line 24, in message_handler
    chat_id = update.message.chat.id
AttributeError: 'NoneType' object has no attribute 'chat'
telegram.ext.dispatcher - ERROR - No error handlers are registered, logging exception.
Traceback (most recent call last):
  File "/home/maximreutov/.local/lib/python3.7/site-packages/telegram/ext/dispatcher.py", line 555, in process_update
    handler.handle_update(update, self, check, context)
  File "/home/maximreutov/.local/lib/python3.7/site-packages/telegram/ext/handler.py", line 198, in handle_update
    return self.callback(update, context)
  File "botik.py", line 24, in message_handler
    chat_id = update.message.chat.id
AttributeError: 'NoneType' object has no attribute 'chat'
telegram.ext.dispatcher - ERROR - No error handlers are registered, logging exception.
Traceback (most recent call last):
  File "/home/maximreutov/.local/lib/python3.7/site-packages/telegram/ext/dispatcher.py", line 555, in process_update
    handler.handle_update(update, self, check, context)
  File "/home/maximreutov/.local/lib/python3.7/site-packages/telegram/ext/handler.py", line 198, in handle_update
    return self.callback(update, context)
  File "botik.py", line 24, in message_handler
    chat_id = update.message.chat.id
AttributeError: 'NoneType' object has no attribute 'chat'
telegram.ext.dispatcher - ERROR - No error handlers are registered, logging exception.
Traceback (most recent call last):
  File "/home/maximreutov/.local/lib/python3.7/site-packages/telegram/ext/dispatcher.py", line 555, in process_update
    handler.handle_update(update, self, check, context)
  File "/home/maximreutov/.local/lib/python3.7/site-packages/telegram/ext/handler.py", line 198, in handle_update
    return self.callback(update, context)
  File "botik.py", line 24, in message_handler
    chat_id = update.message.chat.id
AttributeError: 'NoneType' object has no attribute 'chat'
telegram.ext.dispatcher - ERROR - No error handlers are registered, logging exception.
Traceback (most recent call last):
  File "/home/maximreutov/.local/lib/python3.7/site-packages/telegram/ext/dispatcher.py", line 555, in process_update
    handler.handle_update(update, self, check, context)
  File "/home/maximreutov/.local/lib/python3.7/site-packages/telegram/ext/handler.py", line 198, in handle_update
    return self.callback(update, context)
  File "botik.py", line 24, in message_handler
    chat_id = update.message.chat.id
AttributeError: 'NoneType' object has no attribute 'chat'
telegram.ext.dispatcher - ERROR - No error handlers are registered, logging exception.
Traceback (most recent call last):
  File "/home/maximreutov/.local/lib/python3.7/site-packages/telegram/ext/dispatcher.py", line 555, in process_update
    handler.handle_update(update, self, check, context)
  File "/home/maximreutov/.local/lib/python3.7/site-packages/telegram/ext/handler.py", line 198, in handle_update
    return self.callback(update, context)
  File "botik.py", line 24, in message_handler
    chat_id = update.message.chat.id
AttributeError: 'NoneType' object has no attribute 'chat'
telegram.ext.dispatcher - ERROR - No error handlers are registered, logging exception.
Traceback (most recent call last):
  File "/home/maximreutov/.local/lib/python3.7/site-packages/telegram/ext/dispatcher.py", line 555, in process_update
    handler.handle_update(update, self, check, context)
  File "/home/maximreutov/.local/lib/python3.7/site-packages/telegram/ext/handler.py", line 198, in handle_update
    return self.callback(update, context)
  File "botik.py", line 24, in message_handler
    chat_id = update.message.chat.id
AttributeError: 'NoneType' object has no attribute 'chat'
telegram.ext.dispatcher - ERROR - No error handlers are registered, logging exception.
Traceback (most recent call last):
  File "/home/maximreutov/.local/lib/python3.7/site-packages/telegram/ext/dispatcher.py", line 555, in process_update
    handler.handle_update(update, self, check, context)
  File "/home/maximreutov/.local/lib/python3.7/site-packages/telegram/ext/handler.py", line 198, in handle_update
    return self.callback(update, context)
  File "botik.py", line 24, in message_handler
    chat_id = update.message.chat.id
AttributeError: 'NoneType' object has no attribute 'chat'
telegram.ext.dispatcher - ERROR - No error handlers are registered, logging exception.
Traceback (most recent call last):
  File "/home/maximreutov/.local/lib/python3.7/site-packages/telegram/ext/dispatcher.py", line 555, in process_update
    handler.handle_update(update, self, check, context)
  File "/home/maximreutov/.local/lib/python3.7/site-packages/telegram/ext/handler.py", line 198, in handle_update
    return self.callback(update, context)
  File "botik.py", line 24, in message_handler
    chat_id = update.message.chat.id
AttributeError: 'NoneType' object has no attribute 'chat'
telegram.ext.dispatcher - ERROR - No error handlers are registered, logging exception.
Traceback (most recent call last):
  File "/home/maximreutov/.local/lib/python3.7/site-packages/telegram/ext/dispatcher.py", line 555, in process_update
    handler.handle_update(update, self, check, context)
  File "/home/maximreutov/.local/lib/python3.7/site-packages/telegram/ext/handler.py", line 198, in handle_update
    return self.callback(update, context)
  File "botik.py", line 24, in message_handler
    chat_id = update.message.chat.id
AttributeError: 'NoneType' object has no attribute 'chat'
telegram.ext.dispatcher - ERROR - No error handlers are registered, logging exception.
Traceback (most recent call last):
  File "/home/maximreutov/.local/lib/python3.7/site-packages/telegram/ext/dispatcher.py", line 555, in process_update
    handler.handle_update(update, self, check, context)
  File "/home/maximreutov/.local/lib/python3.7/site-packages/telegram/ext/handler.py", line 198, in handle_update
    return self.callback(update, context)
  File "botik.py", line 24, in message_handler
    chat_id = update.message.chat.id
AttributeError: 'NoneType' object has no attribute 'chat'
telegram.ext.dispatcher - ERROR - No error handlers are registered, logging exception.
Traceback (most recent call last):
  File "/home/maximreutov/.local/lib/python3.7/site-packages/telegram/ext/dispatcher.py", line 555, in process_update
    handler.handle_update(update, self, check, context)
  File "/home/maximreutov/.local/lib/python3.7/site-packages/telegram/ext/handler.py", line 198, in handle_update
    return self.callback(update, context)
  File "botik.py", line 24, in message_handler
    chat_id = update.message.chat.id
AttributeError: 'NoneType' object has no attribute 'chat'
telegram.ext.dispatcher - ERROR - No error handlers are registered, logging exception.
Traceback (most recent call last):
  File "/home/maximreutov/.local/lib/python3.7/site-packages/telegram/ext/dispatcher.py", line 555, in process_update
    handler.handle_update(update, self, check, context)
  File "/home/maximreutov/.local/lib/python3.7/site-packages/telegram/ext/handler.py", line 198, in handle_update
    return self.callback(update, context)
  File "botik.py", line 24, in message_handler
    chat_id = update.message.chat.id
AttributeError: 'NoneType' object has no attribute 'chat'
telegram.ext.dispatcher - ERROR - No error handlers are registered, logging exception.
Traceback (most recent call last):
  File "/home/maximreutov/.local/lib/python3.7/site-packages/telegram/ext/dispatcher.py", line 555, in process_update
    handler.handle_update(update, self, check, context)
  File "/home/maximreutov/.local/lib/python3.7/site-packages/telegram/ext/handler.py", line 198, in handle_update
    return self.callback(update, context)
  File "botik.py", line 24, in message_handler
    chat_id = update.message.chat.id
AttributeError: 'NoneType' object has no attribute 'chat'
telegram.ext.dispatcher - ERROR - No error handlers are registered, logging exception.
Traceback (most recent call last):
  File "/home/maximreutov/.local/lib/python3.7/site-packages/telegram/ext/dispatcher.py", line 555, in process_update
    handler.handle_update(update, self, check, context)
  File "/home/maximreutov/.local/lib/python3.7/site-packages/telegram/ext/handler.py", line 198, in handle_update
    return self.callback(update, context)
  File "botik.py", line 24, in message_handler
    chat_id = update.message.chat.id
AttributeError: 'NoneType' object has no attribute 'chat'
telegram.ext.dispatcher - ERROR - No error handlers are registered, logging exception.
Traceback (most recent call last):
  File "/home/maximreutov/.local/lib/python3.7/site-packages/telegram/ext/dispatcher.py", line 555, in process_update
    handler.handle_update(update, self, check, context)
  File "/home/maximreutov/.local/lib/python3.7/site-packages/telegram/ext/handler.py", line 198, in handle_update
    return self.callback(update, context)
  File "botik.py", line 24, in message_handler
    chat_id = update.message.chat.id
AttributeError: 'NoneType' object has no attribute 'chat'
telegram.ext.dispatcher - ERROR - No error handlers are registered, logging exception.
Traceback (most recent call last):
  File "/home/maximreutov/.local/lib/python3.7/site-packages/telegram/ext/dispatcher.py", line 555, in process_update
    handler.handle_update(update, self, check, context)
  File "/home/maximreutov/.local/lib/python3.7/site-packages/telegram/ext/handler.py", line 198, in handle_update
    return self.callback(update, context)
  File "botik.py", line 24, in message_handler
    chat_id = update.message.chat.id
AttributeError: 'NoneType' object has no attribute 'chat'
telegram.ext.dispatcher - ERROR - No error handlers are registered, logging exception.
Traceback (most recent call last):
  File "/home/maximreutov/.local/lib/python3.7/site-packages/telegram/ext/dispatcher.py", line 555, in process_update
    handler.handle_update(update, self, check, context)
  File "/home/maximreutov/.local/lib/python3.7/site-packages/telegram/ext/handler.py", line 198, in handle_update
    return self.callback(update, context)
  File "botik.py", line 24, in message_handler
    chat_id = update.message.chat.id
AttributeError: 'NoneType' object has no attribute 'chat'
telegram.ext.dispatcher - ERROR - No error handlers are registered, logging exception.
Traceback (most recent call last):
  File "/home/maximreutov/.local/lib/python3.7/site-packages/telegram/ext/dispatcher.py", line 555, in process_update
    handler.handle_update(update, self, check, context)
  File "/home/maximreutov/.local/lib/python3.7/site-packages/telegram/ext/handler.py", line 198, in handle_update
    return self.callback(update, context)
  File "botik.py", line 24, in message_handler
    chat_id = update.message.chat.id
AttributeError: 'NoneType' object has no attribute 'chat'
telegram.ext.dispatcher - ERROR - No error handlers are registered, logging exception.
Traceback (most recent call last):
  File "/home/maximreutov/.local/lib/python3.7/site-packages/telegram/ext/dispatcher.py", line 555, in process_update
    handler.handle_update(update, self, check, context)
  File "/home/maximreutov/.local/lib/python3.7/site-packages/telegram/ext/handler.py", line 198, in handle_update
    return self.callback(update, context)
  File "botik.py", line 24, in message_handler
    chat_id = update.message.chat.id
AttributeError: 'NoneType' object has no attribute 'chat'
telegram.ext.dispatcher - ERROR - No error handlers are registered, logging exception.
Traceback (most recent call last):
  File "/home/maximreutov/.local/lib/python3.7/site-packages/telegram/ext/dispatcher.py", line 555, in process_update
    handler.handle_update(update, self, check, context)
  File "/home/maximreutov/.local/lib/python3.7/site-packages/telegram/ext/handler.py", line 198, in handle_update
    return self.callback(update, context)
  File "botik.py", line 24, in message_handler
    chat_id = update.message.chat.id
AttributeError: 'NoneType' object has no attribute 'chat'
telegram.ext.dispatcher - ERROR - No error handlers are registered, logging exception.
Traceback (most recent call last):
  File "/home/maximreutov/.local/lib/python3.7/site-packages/telegram/ext/dispatcher.py", line 555, in process_update
    handler.handle_update(update, self, check, context)
  File "/home/maximreutov/.local/lib/python3.7/site-packages/telegram/ext/handler.py", line 198, in handle_update
    return self.callback(update, context)
  File "botik.py", line 24, in message_handler
    chat_id = update.message.chat.id
AttributeError: 'NoneType' object has no attribute 'chat'
telegram.ext.dispatcher - ERROR - No error handlers are registered, logging exception.
Traceback (most recent call last):
  File "/home/maximreutov/.local/lib/python3.7/site-packages/telegram/ext/dispatcher.py", line 555, in process_update
    handler.handle_update(update, self, check, context)
  File "/home/maximreutov/.local/lib/python3.7/site-packages/telegram/ext/handler.py", line 198, in handle_update
    return self.callback(update, context)
  File "botik.py", line 24, in message_handler
    chat_id = update.message.chat.id
AttributeError: 'NoneType' object has no attribute 'chat'
telegram.ext.dispatcher - ERROR - No error handlers are registered, logging exception.
Traceback (most recent call last):
  File "/home/maximreutov/.local/lib/python3.7/site-packages/telegram/ext/dispatcher.py", line 555, in process_update
    handler.handle_update(update, self, check, context)
  File "/home/maximreutov/.local/lib/python3.7/site-packages/telegram/ext/handler.py", line 198, in handle_update
    return self.callback(update, context)
  File "botik.py", line 24, in message_handler
    chat_id = update.message.chat.id
AttributeError: 'NoneType' object has no attribute 'chat'
telegram.ext.dispatcher - ERROR - No error handlers are registered, logging exception.
Traceback (most recent call last):
  File "/home/maximreutov/.local/lib/python3.7/site-packages/telegram/ext/dispatcher.py", line 555, in process_update
    handler.handle_update(update, self, check, context)
  File "/home/maximreutov/.local/lib/python3.7/site-packages/telegram/ext/handler.py", line 198, in handle_update
    return self.callback(update, context)
  File "botik.py", line 24, in message_handler
    chat_id = update.message.chat.id
AttributeError: 'NoneType' object has no attribute 'chat'
telegram.ext.dispatcher - ERROR - No error handlers are registered, logging exception.
Traceback (most recent call last):
  File "/home/maximreutov/.local/lib/python3.7/site-packages/telegram/ext/dispatcher.py", line 555, in process_update
    handler.handle_update(update, self, check, context)
  File "/home/maximreutov/.local/lib/python3.7/site-packages/telegram/ext/handler.py", line 198, in handle_update
    return self.callback(update, context)
  File "botik.py", line 24, in message_handler
    chat_id = update.message.chat.id
AttributeError: 'NoneType' object has no attribute 'chat'
telegram.ext.dispatcher - ERROR - No error handlers are registered, logging exception.
Traceback (most recent call last):
  File "/home/maximreutov/.local/lib/python3.7/site-packages/telegram/ext/dispatcher.py", line 555, in process_update
    handler.handle_update(update, self, check, context)
  File "/home/maximreutov/.local/lib/python3.7/site-packages/telegram/ext/handler.py", line 198, in handle_update
    return self.callback(update, context)
  File "botik.py", line 24, in message_handler
    chat_id = update.message.chat.id
AttributeError: 'NoneType' object has no attribute 'chat'
telegram.ext.dispatcher - ERROR - No error handlers are registered, logging exception.
Traceback (most recent call last):
  File "/home/maximreutov/.local/lib/python3.7/site-packages/telegram/ext/dispatcher.py", line 555, in process_update
    handler.handle_update(update, self, check, context)
  File "/home/maximreutov/.local/lib/python3.7/site-packages/telegram/ext/handler.py", line 198, in handle_update
    return self.callback(update, context)
  File "botik.py", line 24, in message_handler
    chat_id = update.message.chat.id
AttributeError: 'NoneType' object has no attribute 'chat'
telegram.ext.dispatcher - ERROR - No error handlers are registered, logging exception.
Traceback (most recent call last):
  File "/home/maximreutov/.local/lib/python3.7/site-packages/telegram/ext/dispatcher.py", line 555, in process_update
    handler.handle_update(update, self, check, context)
  File "/home/maximreutov/.local/lib/python3.7/site-packages/telegram/ext/handler.py", line 198, in handle_update
    return self.callback(update, context)
  File "botik.py", line 24, in message_handler
    chat_id = update.message.chat.id
AttributeError: 'NoneType' object has no attribute 'chat'
telegram.ext.dispatcher - ERROR - No error handlers are registered, logging exception.
Traceback (most recent call last):
  File "/home/maximreutov/.local/lib/python3.7/site-packages/telegram/ext/dispatcher.py", line 555, in process_update
    handler.handle_update(update, self, check, context)
  File "/home/maximreutov/.local/lib/python3.7/site-packages/telegram/ext/handler.py", line 198, in handle_update
    return self.callback(update, context)
  File "botik.py", line 24, in message_handler
    chat_id = update.message.chat.id
AttributeError: 'NoneType' object has no attribute 'chat'
telegram.ext.dispatcher - ERROR - No error handlers are registered, logging exception.
Traceback (most recent call last):
  File "/home/maximreutov/.local/lib/python3.7/site-packages/telegram/ext/dispatcher.py", line 555, in process_update
    handler.handle_update(update, self, check, context)
  File "/home/maximreutov/.local/lib/python3.7/site-packages/telegram/ext/handler.py", line 198, in handle_update
    return self.callback(update, context)
  File "botik.py", line 24, in message_handler
    chat_id = update.message.chat.id
AttributeError: 'NoneType' object has no attribute 'chat'
telegram.ext.dispatcher - ERROR - No error handlers are registered, logging exception.
Traceback (most recent call last):
  File "/home/maximreutov/.local/lib/python3.7/site-packages/telegram/ext/dispatcher.py", line 555, in process_update
    handler.handle_update(update, self, check, context)
  File "/home/maximreutov/.local/lib/python3.7/site-packages/telegram/ext/handler.py", line 198, in handle_update
    return self.callback(update, context)
  File "botik.py", line 24, in message_handler
    chat_id = update.message.chat.id
AttributeError: 'NoneType' object has no attribute 'chat'
telegram.ext.dispatcher - ERROR - No error handlers are registered, logging exception.
Traceback (most recent call last):
  File "/home/maximreutov/.local/lib/python3.7/site-packages/telegram/ext/dispatcher.py", line 555, in process_update
    handler.handle_update(update, self, check, context)
  File "/home/maximreutov/.local/lib/python3.7/site-packages/telegram/ext/handler.py", line 198, in handle_update
    return self.callback(update, context)
  File "botik.py", line 24, in message_handler
    chat_id = update.message.chat.id
AttributeError: 'NoneType' object has no attribute 'chat'
telegram.ext.dispatcher - ERROR - No error handlers are registered, logging exception.
Traceback (most recent call last):
  File "/home/maximreutov/.local/lib/python3.7/site-packages/telegram/ext/dispatcher.py", line 555, in process_update
    handler.handle_update(update, self, check, context)
  File "/home/maximreutov/.local/lib/python3.7/site-packages/telegram/ext/handler.py", line 198, in handle_update
    return self.callback(update, context)
  File "botik.py", line 24, in message_handler
    chat_id = update.message.chat.id
AttributeError: 'NoneType' object has no attribute 'chat'
telegram.ext.dispatcher - ERROR - No error handlers are registered, logging exception.
Traceback (most recent call last):
  File "/home/maximreutov/.local/lib/python3.7/site-packages/telegram/ext/dispatcher.py", line 555, in process_update
    handler.handle_update(update, self, check, context)
  File "/home/maximreutov/.local/lib/python3.7/site-packages/telegram/ext/handler.py", line 198, in handle_update
    return self.callback(update, context)
  File "botik.py", line 24, in message_handler
    chat_id = update.message.chat.id
AttributeError: 'NoneType' object has no attribute 'chat'
telegram.ext.dispatcher - ERROR - No error handlers are registered, logging exception.
Traceback (most recent call last):
  File "/home/maximreutov/.local/lib/python3.7/site-packages/telegram/ext/dispatcher.py", line 555, in process_update
    handler.handle_update(update, self, check, context)
  File "/home/maximreutov/.local/lib/python3.7/site-packages/telegram/ext/handler.py", line 198, in handle_update
    return self.callback(update, context)
  File "botik.py", line 24, in message_handler
    chat_id = update.message.chat.id
AttributeError: 'NoneType' object has no attribute 'chat'
telegram.ext.dispatcher - ERROR - No error handlers are registered, logging exception.
Traceback (most recent call last):
  File "/home/maximreutov/.local/lib/python3.7/site-packages/telegram/ext/dispatcher.py", line 555, in process_update
    handler.handle_update(update, self, check, context)
  File "/home/maximreutov/.local/lib/python3.7/site-packages/telegram/ext/handler.py", line 198, in handle_update
    return self.callback(update, context)
  File "botik.py", line 24, in message_handler
    chat_id = update.message.chat.id
AttributeError: 'NoneType' object has no attribute 'chat'
telegram.ext.dispatcher - ERROR - No error handlers are registered, logging exception.
Traceback (most recent call last):
  File "/home/maximreutov/.local/lib/python3.7/site-packages/telegram/ext/dispatcher.py", line 555, in process_update
    handler.handle_update(update, self, check, context)
  File "/home/maximreutov/.local/lib/python3.7/site-packages/telegram/ext/handler.py", line 198, in handle_update
    return self.callback(update, context)
  File "botik.py", line 24, in message_handler
    chat_id = update.message.chat.id
AttributeError: 'NoneType' object has no attribute 'chat'
telegram.vendor.ptb_urllib3.urllib3.connectionpool - WARNING - Retrying (Retry(total=2, connect=None, read=None, redirect=None)) after connection broken by 'NewConnectionError('<telegram.vendor.ptb_urllib3.urllib3.connection.VerifiedHTTPSConnection object at 0x7f77cb7e85f8>: Failed to establish a new connection: [Errno 101] Network is unreachable')': /bot485079174:AAHwotM-mDKdGCtFOjjPze_hfIj-l94-8PQ/getUpdates
telegram.vendor.ptb_urllib3.urllib3.connectionpool - WARNING - Retrying (Retry(total=1, connect=None, read=None, redirect=None)) after connection broken by 'NewConnectionError('<telegram.vendor.ptb_urllib3.urllib3.connection.VerifiedHTTPSConnection object at 0x7f77cb7e8ba8>: Failed to establish a new connection: [Errno 101] Network is unreachable')': /bot485079174:AAHwotM-mDKdGCtFOjjPze_hfIj-l94-8PQ/getUpdates
telegram.vendor.ptb_urllib3.urllib3.connectionpool - WARNING - Retrying (Retry(total=0, connect=None, read=None, redirect=None)) after connection broken by 'NewConnectionError('<telegram.vendor.ptb_urllib3.urllib3.connection.VerifiedHTTPSConnection object at 0x7f77cb7e8ef0>: Failed to establish a new connection: [Errno 101] Network is unreachable')': /bot485079174:AAHwotM-mDKdGCtFOjjPze_hfIj-l94-8PQ/getUpdates
telegram.vendor.ptb_urllib3.urllib3.connectionpool - WARNING - Retrying (Retry(total=2, connect=None, read=None, redirect=None)) after connection broken by 'NewConnectionError('<telegram.vendor.ptb_urllib3.urllib3.connection.VerifiedHTTPSConnection object at 0x7f77cb7f6160>: Failed to establish a new connection: [Errno 101] Network is unreachable')': /bot485079174:AAHwotM-mDKdGCtFOjjPze_hfIj-l94-8PQ/getUpdates
telegram.vendor.ptb_urllib3.urllib3.connectionpool - WARNING - Retrying (Retry(total=2, connect=None, read=None, redirect=None)) after connection broken by 'NewConnectionError('<telegram.vendor.ptb_urllib3.urllib3.connection.VerifiedHTTPSConnection object at 0x7f77cb7e8f28>: Failed to establish a new connection: [Errno 101] Network is unreachable')': /bot485079174:AAHwotM-mDKdGCtFOjjPze_hfIj-l94-8PQ/getUpdates
telegram.vendor.ptb_urllib3.urllib3.connectionpool - WARNING - Retrying (Retry(total=1, connect=None, read=None, redirect=None)) after connection broken by 'ConnectTimeoutError(<telegram.vendor.ptb_urllib3.urllib3.connectionpool.HTTPSConnectionPool object at 0x7f77caa86e10>, 'Connect timed out. (connect timeout=5.0)')': /bot485079174:AAHwotM-mDKdGCtFOjjPze_hfIj-l94-8PQ/getUpdates
telegram.vendor.ptb_urllib3.urllib3.connectionpool - WARNING - Retrying (Retry(total=0, connect=None, read=None, redirect=None)) after connection broken by 'NewConnectionError('<telegram.vendor.ptb_urllib3.urllib3.connection.VerifiedHTTPSConnection object at 0x7f77cb7e87f0>: Failed to establish a new connection: [Errno 101] Network is unreachable')': /bot485079174:AAHwotM-mDKdGCtFOjjPze_hfIj-l94-8PQ/getUpdates
telegram.ext.updater - ERROR - Error while getting Updates: urllib3 HTTPError HTTPSConnectionPool(host='api.telegram.org', port=443): Max retries exceeded with url: /bot485079174:AAHwotM-mDKdGCtFOjjPze_hfIj-l94-8PQ/getUpdates (Caused by NewConnectionError('<telegram.vendor.ptb_urllib3.urllib3.connection.VerifiedHTTPSConnection object at 0x7f77cb7e8278>: Failed to establish a new connection: [Errno 101] Network is unreachable'))
telegram.ext.dispatcher - ERROR - No error handlers are registered, logging exception.
Traceback (most recent call last):
  File "/home/maximreutov/.local/lib/python3.7/site-packages/telegram/vendor/ptb_urllib3/urllib3/connection.py", line 141, in _new_conn
    (self.host, self.port), self.timeout, **extra_kw)
  File "/home/maximreutov/.local/lib/python3.7/site-packages/telegram/vendor/ptb_urllib3/urllib3/util/connection.py", line 83, in create_connection
    raise err
  File "/home/maximreutov/.local/lib/python3.7/site-packages/telegram/vendor/ptb_urllib3/urllib3/util/connection.py", line 73, in create_connection
    sock.connect(sa)
OSError: [Errno 101] Network is unreachable

During handling of the above exception, another exception occurred:

Traceback (most recent call last):
  File "/home/maximreutov/.local/lib/python3.7/site-packages/telegram/vendor/ptb_urllib3/urllib3/connectionpool.py", line 617, in urlopen
    chunked=chunked)
  File "/home/maximreutov/.local/lib/python3.7/site-packages/telegram/vendor/ptb_urllib3/urllib3/connectionpool.py", line 360, in _make_request
    self._validate_conn(conn)
  File "/home/maximreutov/.local/lib/python3.7/site-packages/telegram/vendor/ptb_urllib3/urllib3/connectionpool.py", line 857, in _validate_conn
    super(HTTPSConnectionPool, self)._validate_conn(conn)
  File "/home/maximreutov/.local/lib/python3.7/site-packages/telegram/vendor/ptb_urllib3/urllib3/connectionpool.py", line 289, in _validate_conn
    conn.connect()
  File "/home/maximreutov/.local/lib/python3.7/site-packages/telegram/vendor/ptb_urllib3/urllib3/connection.py", line 284, in connect
    conn = self._new_conn()
  File "/home/maximreutov/.local/lib/python3.7/site-packages/telegram/vendor/ptb_urllib3/urllib3/connection.py", line 150, in _new_conn
    self, "Failed to establish a new connection: %s" % e)
telegram.vendor.ptb_urllib3.urllib3.exceptions.NewConnectionError: <telegram.vendor.ptb_urllib3.urllib3.connection.VerifiedHTTPSConnection object at 0x7f77cb7e8278>: Failed to establish a new connection: [Errno 101] Network is unreachable

During handling of the above exception, another exception occurred:

Traceback (most recent call last):
  File "/home/maximreutov/.local/lib/python3.7/site-packages/telegram/utils/request.py", line 259, in _request_wrapper
    resp = self._con_pool.request(*args, **kwargs)
  File "/home/maximreutov/.local/lib/python3.7/site-packages/telegram/vendor/ptb_urllib3/urllib3/request.py", line 70, in request
    **urlopen_kw)
  File "/home/maximreutov/.local/lib/python3.7/site-packages/telegram/vendor/ptb_urllib3/urllib3/request.py", line 148, in request_encode_body
    return self.urlopen(method, url, **extra_kw)
  File "/home/maximreutov/.local/lib/python3.7/site-packages/telegram/vendor/ptb_urllib3/urllib3/poolmanager.py", line 244, in urlopen
    response = conn.urlopen(method, u.request_uri, **kw)
  File "/home/maximreutov/.local/lib/python3.7/site-packages/telegram/vendor/ptb_urllib3/urllib3/connectionpool.py", line 695, in urlopen
    **response_kw)
  File "/home/maximreutov/.local/lib/python3.7/site-packages/telegram/vendor/ptb_urllib3/urllib3/connectionpool.py", line 695, in urlopen
    **response_kw)
  File "/home/maximreutov/.local/lib/python3.7/site-packages/telegram/vendor/ptb_urllib3/urllib3/connectionpool.py", line 695, in urlopen
    **response_kw)
  File "/home/maximreutov/.local/lib/python3.7/site-packages/telegram/vendor/ptb_urllib3/urllib3/connectionpool.py", line 666, in urlopen
    _stacktrace=sys.exc_info()[2])
  File "/home/maximreutov/.local/lib/python3.7/site-packages/telegram/vendor/ptb_urllib3/urllib3/util/retry.py", line 376, in increment
    raise MaxRetryError(_pool, url, error or ResponseError(cause))
telegram.vendor.ptb_urllib3.urllib3.exceptions.MaxRetryError: HTTPSConnectionPool(host='api.telegram.org', port=443): Max retries exceeded with url: /bot485079174:AAHwotM-mDKdGCtFOjjPze_hfIj-l94-8PQ/getUpdates (Caused by NewConnectionError('<telegram.vendor.ptb_urllib3.urllib3.connection.VerifiedHTTPSConnection object at 0x7f77cb7e8278>: Failed to establish a new connection: [Errno 101] Network is unreachable'))

The above exception was the direct cause of the following exception:

Traceback (most recent call last):
  File "/home/maximreutov/.local/lib/python3.7/site-packages/telegram/ext/updater.py", line 646, in _network_loop_retry
    if not action_cb():
  File "/home/maximreutov/.local/lib/python3.7/site-packages/telegram/ext/updater.py", line 601, in polling_action_cb
    allowed_updates=allowed_updates,
  File "/home/maximreutov/.local/lib/python3.7/site-packages/telegram/ext/extbot.py", line 228, in get_updates
    api_kwargs=api_kwargs,
  File "/home/maximreutov/.local/lib/python3.7/site-packages/telegram/bot.py", line 130, in decorator
    result = func(*args, **kwargs)
  File "/home/maximreutov/.local/lib/python3.7/site-packages/telegram/bot.py", line 2949, in get_updates
    api_kwargs=api_kwargs,
  File "/home/maximreutov/.local/lib/python3.7/site-packages/telegram/bot.py", line 296, in _post
    f'{self.base_url}/{endpoint}', data=data, timeout=effective_timeout
  File "/home/maximreutov/.local/lib/python3.7/site-packages/telegram/utils/request.py", line 366, in post
    **urlopen_kwargs,
  File "/home/maximreutov/.local/lib/python3.7/site-packages/telegram/utils/request.py", line 265, in _request_wrapper
    raise NetworkError(f'urllib3 HTTPError {error}') from error
telegram.error.NetworkError: urllib3 HTTPError HTTPSConnectionPool(host='api.telegram.org', port=443): Max retries exceeded with url: /bot485079174:AAHwotM-mDKdGCtFOjjPze_hfIj-l94-8PQ/getUpdates (Caused by NewConnectionError('<telegram.vendor.ptb_urllib3.urllib3.connection.VerifiedHTTPSConnection object at 0x7f77cb7e8278>: Failed to establish a new connection: [Errno 101] Network is unreachable'))
telegram.vendor.ptb_urllib3.urllib3.connectionpool - WARNING - Retrying (Retry(total=2, connect=None, read=None, redirect=None)) after connection broken by 'NewConnectionError('<telegram.vendor.ptb_urllib3.urllib3.connection.VerifiedHTTPSConnection object at 0x7f77cb7e85c0>: Failed to establish a new connection: [Errno 101] Network is unreachable')': /bot485079174:AAHwotM-mDKdGCtFOjjPze_hfIj-l94-8PQ/getUpdates
telegram.ext.dispatcher - ERROR - No error handlers are registered, logging exception.
Traceback (most recent call last):
  File "/home/maximreutov/.local/lib/python3.7/site-packages/telegram/ext/dispatcher.py", line 555, in process_update
    handler.handle_update(update, self, check, context)
  File "/home/maximreutov/.local/lib/python3.7/site-packages/telegram/ext/handler.py", line 198, in handle_update
    return self.callback(update, context)
  File "botik.py", line 24, in message_handler
    chat_id = update.message.chat.id
AttributeError: 'NoneType' object has no attribute 'chat'
telegram.ext.dispatcher - ERROR - No error handlers are registered, logging exception.
Traceback (most recent call last):
  File "/home/maximreutov/.local/lib/python3.7/site-packages/telegram/ext/dispatcher.py", line 555, in process_update
    handler.handle_update(update, self, check, context)
  File "/home/maximreutov/.local/lib/python3.7/site-packages/telegram/ext/handler.py", line 198, in handle_update
    return self.callback(update, context)
  File "botik.py", line 24, in message_handler
    chat_id = update.message.chat.id
AttributeError: 'NoneType' object has no attribute 'chat'
telegram.vendor.ptb_urllib3.urllib3.connectionpool - WARNING - Retrying (Retry(total=2, connect=None, read=None, redirect=None)) after connection broken by 'NewConnectionError('<telegram.vendor.ptb_urllib3.urllib3.connection.VerifiedHTTPSConnection object at 0x7f77c8234898>: Failed to establish a new connection: [Errno 101] Network is unreachable')': /bot485079174:AAHwotM-mDKdGCtFOjjPze_hfIj-l94-8PQ/getUpdates
