telegram.ext.dispatcher - ERROR - No error handlers are registered, logging exception.
Traceback (most recent call last):
  File "/home/ubuntu/.local/lib/python3.6/site-packages/telegram/ext/dispatcher.py", line 340, in process_update
    handler.handle_update(update, self, check, context)
  File "/home/ubuntu/.local/lib/python3.6/site-packages/telegram/ext/handler.py", line 119, in handle_update
    return self.callback(update, context)
  File "botik.py", line 67, in message_handler
    if random.random() < markov_chance/100 or update.message.reply_to_message.from_user.username == "puklengtime_bot":
AttributeError: 'NoneType' object has no attribute 'from_user'
telegram.ext.dispatcher - ERROR - No error handlers are registered, logging exception.
Traceback (most recent call last):
  File "/home/ubuntu/.local/lib/python3.6/site-packages/telegram/ext/dispatcher.py", line 340, in process_update
    handler.handle_update(update, self, check, context)
  File "/home/ubuntu/.local/lib/python3.6/site-packages/telegram/ext/handler.py", line 119, in handle_update
    return self.callback(update, context)
  File "botik.py", line 67, in message_handler
    if random.random() < markov_chance/100 or update.message.reply_to_message.from_user.username == "puklengtime_bot":
AttributeError: 'NoneType' object has no attribute 'from_user'
telegram.ext.dispatcher - ERROR - No error handlers are registered, logging exception.
Traceback (most recent call last):
  File "/home/ubuntu/.local/lib/python3.6/site-packages/telegram/ext/dispatcher.py", line 340, in process_update
    handler.handle_update(update, self, check, context)
  File "/home/ubuntu/.local/lib/python3.6/site-packages/telegram/ext/handler.py", line 119, in handle_update
    return self.callback(update, context)
  File "botik.py", line 67, in message_handler
    if random.random() < markov_chance/100 or update.message.reply_to_message.from_user.username == "puklengtime_bot":
AttributeError: 'NoneType' object has no attribute 'from_user'
telegram.ext.dispatcher - ERROR - No error handlers are registered, logging exception.
Traceback (most recent call last):
  File "/home/ubuntu/.local/lib/python3.6/site-packages/telegram/ext/dispatcher.py", line 340, in process_update
    handler.handle_update(update, self, check, context)
  File "/home/ubuntu/.local/lib/python3.6/site-packages/telegram/ext/handler.py", line 119, in handle_update
    return self.callback(update, context)
  File "botik.py", line 67, in message_handler
    if random.random() < markov_chance/100 or update.message.reply_to_message.from_user.username == "puklengtime_bot":
AttributeError: 'NoneType' object has no attribute 'from_user'
telegram.ext.dispatcher - ERROR - No error handlers are registered, logging exception.
Traceback (most recent call last):
  File "/home/ubuntu/.local/lib/python3.6/site-packages/telegram/ext/dispatcher.py", line 340, in process_update
    handler.handle_update(update, self, check, context)
  File "/home/ubuntu/.local/lib/python3.6/site-packages/telegram/ext/handler.py", line 119, in handle_update
    return self.callback(update, context)
  File "botik.py", line 67, in message_handler
    if random.random() < markov_chance/100 or update.message.reply_to_message.from_user.username == "puklengtime_bot":
AttributeError: 'NoneType' object has no attribute 'from_user'
telegram.ext.dispatcher - ERROR - No error handlers are registered, logging exception.
Traceback (most recent call last):
  File "/home/ubuntu/.local/lib/python3.6/site-packages/telegram/ext/dispatcher.py", line 340, in process_update
    handler.handle_update(update, self, check, context)
  File "/home/ubuntu/.local/lib/python3.6/site-packages/telegram/ext/handler.py", line 119, in handle_update
    return self.callback(update, context)
  File "botik.py", line 67, in message_handler
    if random.random() < markov_chance/100 or update.message.reply_to_message.from_user.username == "puklengtime_bot":
AttributeError: 'NoneType' object has no attribute 'from_user'
telegram.ext.dispatcher - ERROR - No error handlers are registered, logging exception.
Traceback (most recent call last):
  File "/home/ubuntu/.local/lib/python3.6/site-packages/telegram/ext/dispatcher.py", line 340, in process_update
    handler.handle_update(update, self, check, context)
  File "/home/ubuntu/.local/lib/python3.6/site-packages/telegram/ext/handler.py", line 119, in handle_update
    return self.callback(update, context)
  File "botik.py", line 67, in message_handler
    if random.random() < markov_chance/100 or update.message.reply_to_message.from_user.username == "puklengtime_bot":
AttributeError: 'NoneType' object has no attribute 'from_user'
telegram.ext.dispatcher - ERROR - No error handlers are registered, logging exception.
Traceback (most recent call last):
  File "/home/ubuntu/.local/lib/python3.6/site-packages/telegram/ext/dispatcher.py", line 340, in process_update
    handler.handle_update(update, self, check, context)
  File "/home/ubuntu/.local/lib/python3.6/site-packages/telegram/ext/handler.py", line 119, in handle_update
    return self.callback(update, context)
  File "botik.py", line 67, in message_handler
    if random.random() < markov_chance/100 or update.message.reply_to_message.from_user.username == "puklengtime_bot":
AttributeError: 'NoneType' object has no attribute 'from_user'
telegram.ext.dispatcher - ERROR - No error handlers are registered, logging exception.
Traceback (most recent call last):
  File "/home/ubuntu/.local/lib/python3.6/site-packages/telegram/ext/dispatcher.py", line 340, in process_update
    handler.handle_update(update, self, check, context)
  File "/home/ubuntu/.local/lib/python3.6/site-packages/telegram/ext/handler.py", line 119, in handle_update
    return self.callback(update, context)
  File "botik.py", line 67, in message_handler
    if random.random() < markov_chance/100 or update.message.reply_to_message.from_user.username == "puklengtime_bot":
AttributeError: 'NoneType' object has no attribute 'from_user'
telegram.ext.dispatcher - ERROR - No error handlers are registered, logging exception.
Traceback (most recent call last):
  File "/home/ubuntu/.local/lib/python3.6/site-packages/telegram/ext/dispatcher.py", line 340, in process_update
    handler.handle_update(update, self, check, context)
  File "/home/ubuntu/.local/lib/python3.6/site-packages/telegram/ext/handler.py", line 119, in handle_update
    return self.callback(update, context)
  File "botik.py", line 67, in message_handler
    if random.random() < markov_chance/100 or update.message.reply_to_message.from_user.username == "puklengtime_bot":
AttributeError: 'NoneType' object has no attribute 'from_user'
telegram.ext.dispatcher - ERROR - No error handlers are registered, logging exception.
Traceback (most recent call last):
  File "/home/ubuntu/.local/lib/python3.6/site-packages/telegram/ext/dispatcher.py", line 340, in process_update
    handler.handle_update(update, self, check, context)
  File "/home/ubuntu/.local/lib/python3.6/site-packages/telegram/ext/handler.py", line 119, in handle_update
    return self.callback(update, context)
  File "botik.py", line 67, in message_handler
    if random.random() < markov_chance/100 or update.message.reply_to_message.from_user.username == "puklengtime_bot":
AttributeError: 'NoneType' object has no attribute 'from_user'
telegram.ext.dispatcher - ERROR - No error handlers are registered, logging exception.
Traceback (most recent call last):
  File "/home/ubuntu/.local/lib/python3.6/site-packages/telegram/ext/dispatcher.py", line 340, in process_update
    handler.handle_update(update, self, check, context)
  File "/home/ubuntu/.local/lib/python3.6/site-packages/telegram/ext/handler.py", line 119, in handle_update
    return self.callback(update, context)
  File "botik.py", line 67, in message_handler
    if random.random() < markov_chance/100 or update.message.reply_to_message.from_user.username == "puklengtime_bot":
AttributeError: 'NoneType' object has no attribute 'from_user'
telegram.ext.dispatcher - ERROR - No error handlers are registered, logging exception.
Traceback (most recent call last):
  File "/home/ubuntu/.local/lib/python3.6/site-packages/telegram/ext/dispatcher.py", line 340, in process_update
    handler.handle_update(update, self, check, context)
  File "/home/ubuntu/.local/lib/python3.6/site-packages/telegram/ext/handler.py", line 119, in handle_update
    return self.callback(update, context)
  File "botik.py", line 67, in message_handler
    if random.random() < markov_chance/100 or update.message.reply_to_message.from_user.username == "puklengtime_bot":
AttributeError: 'NoneType' object has no attribute 'from_user'
telegram.ext.dispatcher - ERROR - No error handlers are registered, logging exception.
Traceback (most recent call last):
  File "/home/ubuntu/.local/lib/python3.6/site-packages/telegram/ext/dispatcher.py", line 340, in process_update
    handler.handle_update(update, self, check, context)
  File "/home/ubuntu/.local/lib/python3.6/site-packages/telegram/ext/handler.py", line 119, in handle_update
    return self.callback(update, context)
  File "botik.py", line 67, in message_handler
    if random.random() < markov_chance/100 or update.message.reply_to_message.from_user.username == "puklengtime_bot":
AttributeError: 'NoneType' object has no attribute 'from_user'
telegram.ext.dispatcher - ERROR - No error handlers are registered, logging exception.
Traceback (most recent call last):
  File "/home/ubuntu/.local/lib/python3.6/site-packages/telegram/ext/dispatcher.py", line 340, in process_update
    handler.handle_update(update, self, check, context)
  File "/home/ubuntu/.local/lib/python3.6/site-packages/telegram/ext/handler.py", line 119, in handle_update
    return self.callback(update, context)
  File "botik.py", line 67, in message_handler
    if random.random() < markov_chance/100 or update.message.reply_to_message.from_user.username == "puklengtime_bot":
AttributeError: 'NoneType' object has no attribute 'from_user'
telegram.ext.dispatcher - ERROR - No error handlers are registered, logging exception.
Traceback (most recent call last):
  File "/home/ubuntu/.local/lib/python3.6/site-packages/telegram/ext/dispatcher.py", line 340, in process_update
    handler.handle_update(update, self, check, context)
  File "/home/ubuntu/.local/lib/python3.6/site-packages/telegram/ext/handler.py", line 119, in handle_update
    return self.callback(update, context)
  File "botik.py", line 67, in message_handler
    if random.random() < markov_chance/100 or update.message.reply_to_message.from_user.username == "puklengtime_bot":
AttributeError: 'NoneType' object has no attribute 'from_user'
telegram.ext.dispatcher - ERROR - No error handlers are registered, logging exception.
Traceback (most recent call last):
  File "/home/ubuntu/.local/lib/python3.6/site-packages/telegram/ext/dispatcher.py", line 340, in process_update
    handler.handle_update(update, self, check, context)
  File "/home/ubuntu/.local/lib/python3.6/site-packages/telegram/ext/handler.py", line 119, in handle_update
    return self.callback(update, context)
  File "botik.py", line 67, in message_handler
    if random.random() < markov_chance/100 or update.message.reply_to_message.from_user.username == "puklengtime_bot":
AttributeError: 'NoneType' object has no attribute 'from_user'
telegram.ext.dispatcher - ERROR - No error handlers are registered, logging exception.
Traceback (most recent call last):
  File "/home/ubuntu/.local/lib/python3.6/site-packages/telegram/ext/dispatcher.py", line 340, in process_update
    handler.handle_update(update, self, check, context)
  File "/home/ubuntu/.local/lib/python3.6/site-packages/telegram/ext/handler.py", line 119, in handle_update
    return self.callback(update, context)
  File "botik.py", line 67, in message_handler
    if random.random() < markov_chance/100 or update.message.reply_to_message.from_user.username == "puklengtime_bot":
AttributeError: 'NoneType' object has no attribute 'from_user'
telegram.ext.dispatcher - ERROR - No error handlers are registered, logging exception.
Traceback (most recent call last):
  File "/home/ubuntu/.local/lib/python3.6/site-packages/telegram/ext/dispatcher.py", line 340, in process_update
    handler.handle_update(update, self, check, context)
  File "/home/ubuntu/.local/lib/python3.6/site-packages/telegram/ext/handler.py", line 119, in handle_update
    return self.callback(update, context)
  File "botik.py", line 67, in message_handler
    if random.random() < markov_chance/100 or update.message.reply_to_message.from_user.username == "puklengtime_bot":
AttributeError: 'NoneType' object has no attribute 'from_user'
telegram.ext.dispatcher - ERROR - No error handlers are registered, logging exception.
Traceback (most recent call last):
  File "/home/ubuntu/.local/lib/python3.6/site-packages/telegram/ext/dispatcher.py", line 340, in process_update
    handler.handle_update(update, self, check, context)
  File "/home/ubuntu/.local/lib/python3.6/site-packages/telegram/ext/handler.py", line 119, in handle_update
    return self.callback(update, context)
  File "botik.py", line 67, in message_handler
    if random.random() < markov_chance/100 or update.message.reply_to_message.from_user.username == "puklengtime_bot":
AttributeError: 'NoneType' object has no attribute 'from_user'
telegram.ext.dispatcher - ERROR - No error handlers are registered, logging exception.
Traceback (most recent call last):
  File "/home/ubuntu/.local/lib/python3.6/site-packages/telegram/ext/dispatcher.py", line 340, in process_update
    handler.handle_update(update, self, check, context)
  File "/home/ubuntu/.local/lib/python3.6/site-packages/telegram/ext/handler.py", line 119, in handle_update
    return self.callback(update, context)
  File "botik.py", line 62, in message_handler
    message = re.sub(r'''(?i)\b((?:https?://|www\d{0,3}[.]|[a-z0-9.\-]+[.][a-z]{2,4}/)(?:[^\s()<>]+|\(([^\s()<>]+|(\([^\s()<>]+\)))*\))+(?:\(([^\s()<>]+|(\([^\s()<>]+\)))*\)|[^\s`!()\[\]{};:'".,<>?«»“”‘’]))''', " ", update.message.text)
AttributeError: 'NoneType' object has no attribute 'text'
telegram.ext.dispatcher - ERROR - No error handlers are registered, logging exception.
Traceback (most recent call last):
  File "/home/ubuntu/.local/lib/python3.6/site-packages/telegram/ext/dispatcher.py", line 340, in process_update
    handler.handle_update(update, self, check, context)
  File "/home/ubuntu/.local/lib/python3.6/site-packages/telegram/ext/handler.py", line 119, in handle_update
    return self.callback(update, context)
  File "botik.py", line 67, in message_handler
    if random.random() < markov_chance/100 or update.message.reply_to_message.from_user.username == "puklengtime_bot":
AttributeError: 'NoneType' object has no attribute 'from_user'
telegram.ext.dispatcher - ERROR - No error handlers are registered, logging exception.
Traceback (most recent call last):
  File "/home/ubuntu/.local/lib/python3.6/site-packages/telegram/ext/dispatcher.py", line 340, in process_update
    handler.handle_update(update, self, check, context)
  File "/home/ubuntu/.local/lib/python3.6/site-packages/telegram/ext/handler.py", line 119, in handle_update
    return self.callback(update, context)
  File "botik.py", line 67, in message_handler
    if random.random() < markov_chance/100 or update.message.reply_to_message.from_user.username == "puklengtime_bot":
AttributeError: 'NoneType' object has no attribute 'from_user'
telegram.ext.dispatcher - ERROR - No error handlers are registered, logging exception.
Traceback (most recent call last):
  File "/home/ubuntu/.local/lib/python3.6/site-packages/telegram/ext/dispatcher.py", line 340, in process_update
    handler.handle_update(update, self, check, context)
  File "/home/ubuntu/.local/lib/python3.6/site-packages/telegram/ext/handler.py", line 119, in handle_update
    return self.callback(update, context)
  File "botik.py", line 67, in message_handler
    if random.random() < markov_chance/100 or update.message.reply_to_message.from_user.username == "puklengtime_bot":
AttributeError: 'NoneType' object has no attribute 'from_user'
telegram.ext.dispatcher - ERROR - No error handlers are registered, logging exception.
Traceback (most recent call last):
  File "/home/ubuntu/.local/lib/python3.6/site-packages/telegram/ext/dispatcher.py", line 340, in process_update
    handler.handle_update(update, self, check, context)
  File "/home/ubuntu/.local/lib/python3.6/site-packages/telegram/ext/handler.py", line 119, in handle_update
    return self.callback(update, context)
  File "botik.py", line 67, in message_handler
    if random.random() < markov_chance/100 or update.message.reply_to_message.from_user.username == "puklengtime_bot":
AttributeError: 'NoneType' object has no attribute 'from_user'
telegram.ext.dispatcher - ERROR - No error handlers are registered, logging exception.
Traceback (most recent call last):
  File "/home/ubuntu/.local/lib/python3.6/site-packages/telegram/ext/dispatcher.py", line 340, in process_update
    handler.handle_update(update, self, check, context)
  File "/home/ubuntu/.local/lib/python3.6/site-packages/telegram/ext/handler.py", line 119, in handle_update
    return self.callback(update, context)
  File "botik.py", line 67, in message_handler
    if random.random() < markov_chance/100 or update.message.reply_to_message.from_user.username == "puklengtime_bot":
AttributeError: 'NoneType' object has no attribute 'from_user'
telegram.ext.dispatcher - ERROR - No error handlers are registered, logging exception.
Traceback (most recent call last):
  File "/home/ubuntu/.local/lib/python3.6/site-packages/telegram/ext/dispatcher.py", line 340, in process_update
    handler.handle_update(update, self, check, context)
  File "/home/ubuntu/.local/lib/python3.6/site-packages/telegram/ext/handler.py", line 119, in handle_update
    return self.callback(update, context)
  File "botik.py", line 67, in message_handler
    if random.random() < markov_chance/100 or update.message.reply_to_message.from_user.username == "puklengtime_bot":
AttributeError: 'NoneType' object has no attribute 'from_user'
telegram.ext.dispatcher - ERROR - No error handlers are registered, logging exception.
Traceback (most recent call last):
  File "/home/ubuntu/.local/lib/python3.6/site-packages/telegram/ext/dispatcher.py", line 340, in process_update
    handler.handle_update(update, self, check, context)
  File "/home/ubuntu/.local/lib/python3.6/site-packages/telegram/ext/handler.py", line 119, in handle_update
    return self.callback(update, context)
  File "botik.py", line 67, in message_handler
    if random.random() < markov_chance/100 or update.message.reply_to_message.from_user.username == "puklengtime_bot":
AttributeError: 'NoneType' object has no attribute 'from_user'
telegram.ext.dispatcher - ERROR - No error handlers are registered, logging exception.
Traceback (most recent call last):
  File "/home/ubuntu/.local/lib/python3.6/site-packages/telegram/ext/dispatcher.py", line 340, in process_update
    handler.handle_update(update, self, check, context)
  File "/home/ubuntu/.local/lib/python3.6/site-packages/telegram/ext/handler.py", line 119, in handle_update
    return self.callback(update, context)
  File "botik.py", line 67, in message_handler
    if random.random() < markov_chance/100 or update.message.reply_to_message.from_user.username == "puklengtime_bot":
AttributeError: 'NoneType' object has no attribute 'from_user'
telegram.ext.dispatcher - ERROR - No error handlers are registered, logging exception.
Traceback (most recent call last):
  File "/home/ubuntu/.local/lib/python3.6/site-packages/telegram/ext/dispatcher.py", line 340, in process_update
    handler.handle_update(update, self, check, context)
  File "/home/ubuntu/.local/lib/python3.6/site-packages/telegram/ext/handler.py", line 119, in handle_update
    return self.callback(update, context)
  File "botik.py", line 67, in message_handler
    if random.random() < markov_chance/100 or update.message.reply_to_message.from_user.username == "puklengtime_bot":
AttributeError: 'NoneType' object has no attribute 'from_user'
telegram.ext.dispatcher - ERROR - No error handlers are registered, logging exception.
Traceback (most recent call last):
  File "/home/ubuntu/.local/lib/python3.6/site-packages/telegram/ext/dispatcher.py", line 340, in process_update
    handler.handle_update(update, self, check, context)
  File "/home/ubuntu/.local/lib/python3.6/site-packages/telegram/ext/handler.py", line 119, in handle_update
    return self.callback(update, context)
  File "botik.py", line 67, in message_handler
    if random.random() < markov_chance/100 or update.message.reply_to_message.from_user.username == "puklengtime_bot":
AttributeError: 'NoneType' object has no attribute 'from_user'
telegram.ext.dispatcher - ERROR - No error handlers are registered, logging exception.
Traceback (most recent call last):
  File "/home/ubuntu/.local/lib/python3.6/site-packages/telegram/ext/dispatcher.py", line 340, in process_update
    handler.handle_update(update, self, check, context)
  File "/home/ubuntu/.local/lib/python3.6/site-packages/telegram/ext/handler.py", line 119, in handle_update
    return self.callback(update, context)
  File "botik.py", line 67, in message_handler
    if random.random() < markov_chance/100 or update.message.reply_to_message.from_user.username == "puklengtime_bot":
AttributeError: 'NoneType' object has no attribute 'from_user'
telegram.ext.dispatcher - ERROR - No error handlers are registered, logging exception.
Traceback (most recent call last):
  File "/home/ubuntu/.local/lib/python3.6/site-packages/telegram/ext/dispatcher.py", line 340, in process_update
    handler.handle_update(update, self, check, context)
  File "/home/ubuntu/.local/lib/python3.6/site-packages/telegram/ext/handler.py", line 119, in handle_update
    return self.callback(update, context)
  File "botik.py", line 67, in message_handler
    if random.random() < markov_chance/100 or update.message.reply_to_message.from_user.username == "puklengtime_bot":
AttributeError: 'NoneType' object has no attribute 'from_user'
telegram.ext.dispatcher - ERROR - No error handlers are registered, logging exception.
Traceback (most recent call last):
  File "/home/ubuntu/.local/lib/python3.6/site-packages/telegram/ext/dispatcher.py", line 340, in process_update
    handler.handle_update(update, self, check, context)
  File "/home/ubuntu/.local/lib/python3.6/site-packages/telegram/ext/handler.py", line 119, in handle_update
    return self.callback(update, context)
  File "botik.py", line 67, in message_handler
    if random.random() < markov_chance/100 or update.message.reply_to_message.from_user.username == "puklengtime_bot":
AttributeError: 'NoneType' object has no attribute 'from_user'
telegram.ext.dispatcher - ERROR - No error handlers are registered, logging exception.
Traceback (most recent call last):
  File "/home/ubuntu/.local/lib/python3.6/site-packages/telegram/ext/dispatcher.py", line 340, in process_update
    handler.handle_update(update, self, check, context)
  File "/home/ubuntu/.local/lib/python3.6/site-packages/telegram/ext/handler.py", line 119, in handle_update
    return self.callback(update, context)
  File "botik.py", line 67, in message_handler
    if random.random() < markov_chance/100 or update.message.reply_to_message.from_user.username == "puklengtime_bot":
AttributeError: 'NoneType' object has no attribute 'from_user'
telegram.ext.dispatcher - ERROR - No error handlers are registered, logging exception.
Traceback (most recent call last):
  File "/home/ubuntu/.local/lib/python3.6/site-packages/telegram/ext/dispatcher.py", line 340, in process_update
    handler.handle_update(update, self, check, context)
  File "/home/ubuntu/.local/lib/python3.6/site-packages/telegram/ext/handler.py", line 119, in handle_update
    return self.callback(update, context)
  File "botik.py", line 67, in message_handler
    if random.random() < markov_chance/100 or update.message.reply_to_message.from_user.username == "puklengtime_bot":
AttributeError: 'NoneType' object has no attribute 'from_user'
telegram.ext.dispatcher - ERROR - No error handlers are registered, logging exception.
Traceback (most recent call last):
  File "/home/ubuntu/.local/lib/python3.6/site-packages/telegram/ext/dispatcher.py", line 340, in process_update
    handler.handle_update(update, self, check, context)
  File "/home/ubuntu/.local/lib/python3.6/site-packages/telegram/ext/handler.py", line 119, in handle_update
    return self.callback(update, context)
  File "botik.py", line 67, in message_handler
    if random.random() < markov_chance/100 or update.message.reply_to_message.from_user.username == "puklengtime_bot":
AttributeError: 'NoneType' object has no attribute 'from_user'
telegram.ext.dispatcher - ERROR - No error handlers are registered, logging exception.
Traceback (most recent call last):
  File "/home/ubuntu/.local/lib/python3.6/site-packages/telegram/ext/dispatcher.py", line 340, in process_update
    handler.handle_update(update, self, check, context)
  File "/home/ubuntu/.local/lib/python3.6/site-packages/telegram/ext/handler.py", line 119, in handle_update
    return self.callback(update, context)
  File "botik.py", line 67, in message_handler
    if random.random() < markov_chance/100 or update.message.reply_to_message.from_user.username == "puklengtime_bot":
AttributeError: 'NoneType' object has no attribute 'from_user'
telegram.ext.dispatcher - ERROR - No error handlers are registered, logging exception.
Traceback (most recent call last):
  File "/home/ubuntu/.local/lib/python3.6/site-packages/telegram/ext/dispatcher.py", line 340, in process_update
    handler.handle_update(update, self, check, context)
  File "/home/ubuntu/.local/lib/python3.6/site-packages/telegram/ext/handler.py", line 119, in handle_update
    return self.callback(update, context)
  File "botik.py", line 67, in message_handler
    if random.random() < markov_chance/100 or update.message.reply_to_message.from_user.username == "puklengtime_bot":
AttributeError: 'NoneType' object has no attribute 'from_user'
telegram.ext.dispatcher - ERROR - No error handlers are registered, logging exception.
Traceback (most recent call last):
  File "/home/ubuntu/.local/lib/python3.6/site-packages/telegram/ext/dispatcher.py", line 340, in process_update
    handler.handle_update(update, self, check, context)
  File "/home/ubuntu/.local/lib/python3.6/site-packages/telegram/ext/handler.py", line 119, in handle_update
    return self.callback(update, context)
  File "botik.py", line 67, in message_handler
    if random.random() < markov_chance/100 or update.message.reply_to_message.from_user.username == "puklengtime_bot":
AttributeError: 'NoneType' object has no attribute 'from_user'
telegram.ext.dispatcher - ERROR - No error handlers are registered, logging exception.
Traceback (most recent call last):
  File "/home/ubuntu/.local/lib/python3.6/site-packages/telegram/ext/dispatcher.py", line 340, in process_update
    handler.handle_update(update, self, check, context)
  File "/home/ubuntu/.local/lib/python3.6/site-packages/telegram/ext/handler.py", line 119, in handle_update
    return self.callback(update, context)
  File "botik.py", line 67, in message_handler
    if random.random() < markov_chance/100 or update.message.reply_to_message.from_user.username == "puklengtime_bot":
AttributeError: 'NoneType' object has no attribute 'from_user'
telegram.ext.dispatcher - ERROR - No error handlers are registered, logging exception.
Traceback (most recent call last):
  File "/home/ubuntu/.local/lib/python3.6/site-packages/telegram/ext/dispatcher.py", line 340, in process_update
    handler.handle_update(update, self, check, context)
  File "/home/ubuntu/.local/lib/python3.6/site-packages/telegram/ext/handler.py", line 119, in handle_update
    return self.callback(update, context)
  File "botik.py", line 67, in message_handler
    if random.random() < markov_chance/100 or update.message.reply_to_message.from_user.username == "puklengtime_bot":
AttributeError: 'NoneType' object has no attribute 'from_user'
telegram.ext.dispatcher - ERROR - No error handlers are registered, logging exception.
Traceback (most recent call last):
  File "/home/ubuntu/.local/lib/python3.6/site-packages/telegram/ext/dispatcher.py", line 340, in process_update
    handler.handle_update(update, self, check, context)
  File "/home/ubuntu/.local/lib/python3.6/site-packages/telegram/ext/handler.py", line 119, in handle_update
    return self.callback(update, context)
  File "botik.py", line 67, in message_handler
    if random.random() < markov_chance/100 or update.message.reply_to_message.from_user.username == "puklengtime_bot":
AttributeError: 'NoneType' object has no attribute 'from_user'
telegram.ext.dispatcher - ERROR - No error handlers are registered, logging exception.
Traceback (most recent call last):
  File "/home/ubuntu/.local/lib/python3.6/site-packages/telegram/ext/dispatcher.py", line 340, in process_update
    handler.handle_update(update, self, check, context)
  File "/home/ubuntu/.local/lib/python3.6/site-packages/telegram/ext/handler.py", line 119, in handle_update
    return self.callback(update, context)
  File "botik.py", line 67, in message_handler
    if random.random() < markov_chance/100 or update.message.reply_to_message.from_user.username == "puklengtime_bot":
AttributeError: 'NoneType' object has no attribute 'from_user'
telegram.ext.dispatcher - ERROR - No error handlers are registered, logging exception.
Traceback (most recent call last):
  File "/home/ubuntu/.local/lib/python3.6/site-packages/telegram/ext/dispatcher.py", line 340, in process_update
    handler.handle_update(update, self, check, context)
  File "/home/ubuntu/.local/lib/python3.6/site-packages/telegram/ext/handler.py", line 119, in handle_update
    return self.callback(update, context)
  File "botik.py", line 67, in message_handler
    if random.random() < markov_chance/100 or update.message.reply_to_message.from_user.username == "puklengtime_bot":
AttributeError: 'NoneType' object has no attribute 'from_user'
telegram.ext.dispatcher - ERROR - No error handlers are registered, logging exception.
Traceback (most recent call last):
  File "/home/ubuntu/.local/lib/python3.6/site-packages/telegram/ext/dispatcher.py", line 340, in process_update
    handler.handle_update(update, self, check, context)
  File "/home/ubuntu/.local/lib/python3.6/site-packages/telegram/ext/handler.py", line 119, in handle_update
    return self.callback(update, context)
  File "botik.py", line 67, in message_handler
    if random.random() < markov_chance/100 or update.message.reply_to_message.from_user.username == "puklengtime_bot":
AttributeError: 'NoneType' object has no attribute 'from_user'
telegram.ext.dispatcher - ERROR - No error handlers are registered, logging exception.
Traceback (most recent call last):
  File "/home/ubuntu/.local/lib/python3.6/site-packages/telegram/ext/dispatcher.py", line 340, in process_update
    handler.handle_update(update, self, check, context)
  File "/home/ubuntu/.local/lib/python3.6/site-packages/telegram/ext/handler.py", line 119, in handle_update
    return self.callback(update, context)
  File "botik.py", line 67, in message_handler
    if random.random() < markov_chance/100 or update.message.reply_to_message.from_user.username == "puklengtime_bot":
AttributeError: 'NoneType' object has no attribute 'from_user'
telegram.ext.dispatcher - ERROR - No error handlers are registered, logging exception.
Traceback (most recent call last):
  File "/home/ubuntu/.local/lib/python3.6/site-packages/telegram/ext/dispatcher.py", line 340, in process_update
    handler.handle_update(update, self, check, context)
  File "/home/ubuntu/.local/lib/python3.6/site-packages/telegram/ext/handler.py", line 119, in handle_update
    return self.callback(update, context)
  File "botik.py", line 67, in message_handler
    if random.random() < markov_chance/100 or update.message.reply_to_message.from_user.username == "puklengtime_bot":
AttributeError: 'NoneType' object has no attribute 'from_user'
telegram.ext.dispatcher - ERROR - No error handlers are registered, logging exception.
Traceback (most recent call last):
  File "/home/ubuntu/.local/lib/python3.6/site-packages/telegram/ext/dispatcher.py", line 340, in process_update
    handler.handle_update(update, self, check, context)
  File "/home/ubuntu/.local/lib/python3.6/site-packages/telegram/ext/handler.py", line 119, in handle_update
    return self.callback(update, context)
  File "botik.py", line 67, in message_handler
    if random.random() < markov_chance/100 or update.message.reply_to_message.from_user.username == "puklengtime_bot":
AttributeError: 'NoneType' object has no attribute 'from_user'
telegram.ext.dispatcher - ERROR - No error handlers are registered, logging exception.
Traceback (most recent call last):
  File "/home/ubuntu/.local/lib/python3.6/site-packages/telegram/ext/dispatcher.py", line 340, in process_update
    handler.handle_update(update, self, check, context)
  File "/home/ubuntu/.local/lib/python3.6/site-packages/telegram/ext/handler.py", line 119, in handle_update
    return self.callback(update, context)
  File "botik.py", line 67, in message_handler
    if random.random() < markov_chance/100 or update.message.reply_to_message.from_user.username == "puklengtime_bot":
AttributeError: 'NoneType' object has no attribute 'from_user'
telegram.ext.dispatcher - ERROR - No error handlers are registered, logging exception.
Traceback (most recent call last):
  File "/home/ubuntu/.local/lib/python3.6/site-packages/telegram/ext/dispatcher.py", line 340, in process_update
    handler.handle_update(update, self, check, context)
  File "/home/ubuntu/.local/lib/python3.6/site-packages/telegram/ext/handler.py", line 119, in handle_update
    return self.callback(update, context)
  File "botik.py", line 67, in message_handler
    if random.random() < markov_chance/100 or update.message.reply_to_message.from_user.username == "puklengtime_bot":
AttributeError: 'NoneType' object has no attribute 'from_user'
telegram.ext.dispatcher - ERROR - No error handlers are registered, logging exception.
Traceback (most recent call last):
  File "/home/ubuntu/.local/lib/python3.6/site-packages/telegram/ext/dispatcher.py", line 340, in process_update
    handler.handle_update(update, self, check, context)
  File "/home/ubuntu/.local/lib/python3.6/site-packages/telegram/ext/handler.py", line 119, in handle_update
    return self.callback(update, context)
  File "botik.py", line 67, in message_handler
    if random.random() < markov_chance/100 or update.message.reply_to_message.from_user.username == "puklengtime_bot":
AttributeError: 'NoneType' object has no attribute 'from_user'
telegram.ext.dispatcher - ERROR - No error handlers are registered, logging exception.
Traceback (most recent call last):
  File "/home/ubuntu/.local/lib/python3.6/site-packages/telegram/ext/dispatcher.py", line 340, in process_update
    handler.handle_update(update, self, check, context)
  File "/home/ubuntu/.local/lib/python3.6/site-packages/telegram/ext/handler.py", line 119, in handle_update
    return self.callback(update, context)
  File "botik.py", line 67, in message_handler
    if random.random() < markov_chance/100 or update.message.reply_to_message.from_user.username == "puklengtime_bot":
AttributeError: 'NoneType' object has no attribute 'from_user'
telegram.ext.dispatcher - ERROR - No error handlers are registered, logging exception.
Traceback (most recent call last):
  File "/home/ubuntu/.local/lib/python3.6/site-packages/telegram/ext/dispatcher.py", line 340, in process_update
    handler.handle_update(update, self, check, context)
  File "/home/ubuntu/.local/lib/python3.6/site-packages/telegram/ext/handler.py", line 119, in handle_update
    return self.callback(update, context)
  File "botik.py", line 67, in message_handler
    if random.random() < markov_chance/100 or update.message.reply_to_message.from_user.username == "puklengtime_bot":
AttributeError: 'NoneType' object has no attribute 'from_user'
telegram.ext.dispatcher - ERROR - No error handlers are registered, logging exception.
Traceback (most recent call last):
  File "/home/ubuntu/.local/lib/python3.6/site-packages/telegram/ext/dispatcher.py", line 340, in process_update
    handler.handle_update(update, self, check, context)
  File "/home/ubuntu/.local/lib/python3.6/site-packages/telegram/ext/handler.py", line 119, in handle_update
    return self.callback(update, context)
  File "botik.py", line 67, in message_handler
    if random.random() < markov_chance/100 or update.message.reply_to_message.from_user.username == "puklengtime_bot":
AttributeError: 'NoneType' object has no attribute 'from_user'
telegram.ext.dispatcher - ERROR - No error handlers are registered, logging exception.
Traceback (most recent call last):
  File "/home/ubuntu/.local/lib/python3.6/site-packages/telegram/ext/dispatcher.py", line 340, in process_update
    handler.handle_update(update, self, check, context)
  File "/home/ubuntu/.local/lib/python3.6/site-packages/telegram/ext/handler.py", line 119, in handle_update
    return self.callback(update, context)
  File "botik.py", line 67, in message_handler
    if random.random() < markov_chance/100 or update.message.reply_to_message.from_user.username == "puklengtime_bot":
AttributeError: 'NoneType' object has no attribute 'from_user'
telegram.ext.dispatcher - ERROR - No error handlers are registered, logging exception.
Traceback (most recent call last):
  File "/home/ubuntu/.local/lib/python3.6/site-packages/telegram/ext/dispatcher.py", line 340, in process_update
    handler.handle_update(update, self, check, context)
  File "/home/ubuntu/.local/lib/python3.6/site-packages/telegram/ext/handler.py", line 119, in handle_update
    return self.callback(update, context)
  File "botik.py", line 67, in message_handler
    if random.random() < markov_chance/100 or update.message.reply_to_message.from_user.username == "puklengtime_bot":
AttributeError: 'NoneType' object has no attribute 'from_user'
telegram.ext.dispatcher - ERROR - No error handlers are registered, logging exception.
Traceback (most recent call last):
  File "/home/ubuntu/.local/lib/python3.6/site-packages/telegram/ext/dispatcher.py", line 340, in process_update
    handler.handle_update(update, self, check, context)
  File "/home/ubuntu/.local/lib/python3.6/site-packages/telegram/ext/handler.py", line 119, in handle_update
    return self.callback(update, context)
  File "botik.py", line 67, in message_handler
    if random.random() < markov_chance/100 or update.message.reply_to_message.from_user.username == "puklengtime_bot":
AttributeError: 'NoneType' object has no attribute 'from_user'
telegram.ext.dispatcher - ERROR - No error handlers are registered, logging exception.
Traceback (most recent call last):
  File "/home/ubuntu/.local/lib/python3.6/site-packages/telegram/ext/dispatcher.py", line 340, in process_update
    handler.handle_update(update, self, check, context)
  File "/home/ubuntu/.local/lib/python3.6/site-packages/telegram/ext/handler.py", line 119, in handle_update
    return self.callback(update, context)
  File "botik.py", line 67, in message_handler
    if random.random() < markov_chance/100 or update.message.reply_to_message.from_user.username == "puklengtime_bot":
AttributeError: 'NoneType' object has no attribute 'from_user'
telegram.ext.dispatcher - ERROR - No error handlers are registered, logging exception.
Traceback (most recent call last):
  File "/home/ubuntu/.local/lib/python3.6/site-packages/telegram/ext/dispatcher.py", line 340, in process_update
    handler.handle_update(update, self, check, context)
  File "/home/ubuntu/.local/lib/python3.6/site-packages/telegram/ext/handler.py", line 119, in handle_update
    return self.callback(update, context)
  File "botik.py", line 67, in message_handler
    if random.random() < markov_chance/100 or update.message.reply_to_message.from_user.username == "puklengtime_bot":
AttributeError: 'NoneType' object has no attribute 'from_user'
telegram.ext.dispatcher - ERROR - No error handlers are registered, logging exception.
Traceback (most recent call last):
  File "/home/ubuntu/.local/lib/python3.6/site-packages/telegram/ext/dispatcher.py", line 340, in process_update
    handler.handle_update(update, self, check, context)
  File "/home/ubuntu/.local/lib/python3.6/site-packages/telegram/ext/handler.py", line 119, in handle_update
    return self.callback(update, context)
  File "botik.py", line 67, in message_handler
    if random.random() < markov_chance/100 or update.message.reply_to_message.from_user.username == "puklengtime_bot":
AttributeError: 'NoneType' object has no attribute 'from_user'
telegram.ext.dispatcher - ERROR - No error handlers are registered, logging exception.
Traceback (most recent call last):
  File "/home/ubuntu/.local/lib/python3.6/site-packages/telegram/ext/dispatcher.py", line 340, in process_update
    handler.handle_update(update, self, check, context)
  File "/home/ubuntu/.local/lib/python3.6/site-packages/telegram/ext/handler.py", line 119, in handle_update
    return self.callback(update, context)
  File "botik.py", line 67, in message_handler
    if random.random() < markov_chance/100 or update.message.reply_to_message.from_user.username == "puklengtime_bot":
AttributeError: 'NoneType' object has no attribute 'from_user'
telegram.ext.dispatcher - ERROR - No error handlers are registered, logging exception.
Traceback (most recent call last):
  File "/home/ubuntu/.local/lib/python3.6/site-packages/telegram/ext/dispatcher.py", line 340, in process_update
    handler.handle_update(update, self, check, context)
  File "/home/ubuntu/.local/lib/python3.6/site-packages/telegram/ext/handler.py", line 119, in handle_update
    return self.callback(update, context)
  File "botik.py", line 62, in message_handler
    message = re.sub(r'''(?i)\b((?:https?://|www\d{0,3}[.]|[a-z0-9.\-]+[.][a-z]{2,4}/)(?:[^\s()<>]+|\(([^\s()<>]+|(\([^\s()<>]+\)))*\))+(?:\(([^\s()<>]+|(\([^\s()<>]+\)))*\)|[^\s`!()\[\]{};:'".,<>?«»“”‘’]))''', " ", update.message.text)
AttributeError: 'NoneType' object has no attribute 'text'
telegram.ext.dispatcher - ERROR - No error handlers are registered, logging exception.
Traceback (most recent call last):
  File "/home/ubuntu/.local/lib/python3.6/site-packages/telegram/ext/dispatcher.py", line 340, in process_update
    handler.handle_update(update, self, check, context)
  File "/home/ubuntu/.local/lib/python3.6/site-packages/telegram/ext/handler.py", line 119, in handle_update
    return self.callback(update, context)
  File "botik.py", line 67, in message_handler
    if random.random() < markov_chance/100 or update.message.reply_to_message.from_user.username == "puklengtime_bot":
AttributeError: 'NoneType' object has no attribute 'from_user'
telegram.ext.dispatcher - ERROR - No error handlers are registered, logging exception.
Traceback (most recent call last):
  File "/home/ubuntu/.local/lib/python3.6/site-packages/telegram/ext/dispatcher.py", line 340, in process_update
    handler.handle_update(update, self, check, context)
  File "/home/ubuntu/.local/lib/python3.6/site-packages/telegram/ext/handler.py", line 119, in handle_update
    return self.callback(update, context)
  File "botik.py", line 67, in message_handler
    if random.random() < markov_chance/100 or update.message.reply_to_message.from_user.username == "puklengtime_bot":
AttributeError: 'NoneType' object has no attribute 'from_user'
telegram.ext.dispatcher - ERROR - No error handlers are registered, logging exception.
Traceback (most recent call last):
  File "/home/ubuntu/.local/lib/python3.6/site-packages/telegram/ext/dispatcher.py", line 340, in process_update
    handler.handle_update(update, self, check, context)
  File "/home/ubuntu/.local/lib/python3.6/site-packages/telegram/ext/handler.py", line 119, in handle_update
    return self.callback(update, context)
  File "botik.py", line 67, in message_handler
    if random.random() < markov_chance/100 or update.message.reply_to_message.from_user.username == "puklengtime_bot":
AttributeError: 'NoneType' object has no attribute 'from_user'
telegram.ext.dispatcher - ERROR - No error handlers are registered, logging exception.
Traceback (most recent call last):
  File "/home/ubuntu/.local/lib/python3.6/site-packages/telegram/ext/dispatcher.py", line 340, in process_update
    handler.handle_update(update, self, check, context)
  File "/home/ubuntu/.local/lib/python3.6/site-packages/telegram/ext/handler.py", line 119, in handle_update
    return self.callback(update, context)
  File "botik.py", line 67, in message_handler
    if random.random() < markov_chance/100 or update.message.reply_to_message.from_user.username == "puklengtime_bot":
AttributeError: 'NoneType' object has no attribute 'from_user'
telegram.ext.dispatcher - ERROR - No error handlers are registered, logging exception.
Traceback (most recent call last):
  File "/home/ubuntu/.local/lib/python3.6/site-packages/telegram/ext/dispatcher.py", line 340, in process_update
    handler.handle_update(update, self, check, context)
  File "/home/ubuntu/.local/lib/python3.6/site-packages/telegram/ext/handler.py", line 119, in handle_update
    return self.callback(update, context)
  File "botik.py", line 67, in message_handler
    if random.random() < markov_chance/100 or update.message.reply_to_message.from_user.username == "puklengtime_bot":
AttributeError: 'NoneType' object has no attribute 'from_user'
telegram.ext.dispatcher - ERROR - No error handlers are registered, logging exception.
Traceback (most recent call last):
  File "/home/ubuntu/.local/lib/python3.6/site-packages/telegram/ext/dispatcher.py", line 340, in process_update
    handler.handle_update(update, self, check, context)
  File "/home/ubuntu/.local/lib/python3.6/site-packages/telegram/ext/handler.py", line 119, in handle_update
    return self.callback(update, context)
  File "botik.py", line 67, in message_handler
    if random.random() < markov_chance/100 or update.message.reply_to_message.from_user.username == "puklengtime_bot":
AttributeError: 'NoneType' object has no attribute 'from_user'
telegram.ext.dispatcher - ERROR - No error handlers are registered, logging exception.
Traceback (most recent call last):
  File "/home/ubuntu/.local/lib/python3.6/site-packages/telegram/ext/dispatcher.py", line 340, in process_update
    handler.handle_update(update, self, check, context)
  File "/home/ubuntu/.local/lib/python3.6/site-packages/telegram/ext/handler.py", line 119, in handle_update
    return self.callback(update, context)
  File "botik.py", line 67, in message_handler
    if random.random() < markov_chance/100 or update.message.reply_to_message.from_user.username == "puklengtime_bot":
AttributeError: 'NoneType' object has no attribute 'from_user'
telegram.ext.dispatcher - ERROR - No error handlers are registered, logging exception.
Traceback (most recent call last):
  File "/home/ubuntu/.local/lib/python3.6/site-packages/telegram/ext/dispatcher.py", line 340, in process_update
    handler.handle_update(update, self, check, context)
  File "/home/ubuntu/.local/lib/python3.6/site-packages/telegram/ext/handler.py", line 119, in handle_update
    return self.callback(update, context)
  File "botik.py", line 67, in message_handler
    if random.random() < markov_chance/100 or update.message.reply_to_message.from_user.username == "puklengtime_bot":
AttributeError: 'NoneType' object has no attribute 'from_user'
telegram.ext.dispatcher - ERROR - No error handlers are registered, logging exception.
Traceback (most recent call last):
  File "/home/ubuntu/.local/lib/python3.6/site-packages/telegram/ext/dispatcher.py", line 340, in process_update
    handler.handle_update(update, self, check, context)
  File "/home/ubuntu/.local/lib/python3.6/site-packages/telegram/ext/handler.py", line 119, in handle_update
    return self.callback(update, context)
  File "botik.py", line 67, in message_handler
    if random.random() < markov_chance/100 or update.message.reply_to_message.from_user.username == "puklengtime_bot":
AttributeError: 'NoneType' object has no attribute 'from_user'
telegram.ext.dispatcher - ERROR - No error handlers are registered, logging exception.
Traceback (most recent call last):
  File "/home/ubuntu/.local/lib/python3.6/site-packages/telegram/ext/dispatcher.py", line 340, in process_update
    handler.handle_update(update, self, check, context)
  File "/home/ubuntu/.local/lib/python3.6/site-packages/telegram/ext/handler.py", line 119, in handle_update
    return self.callback(update, context)
  File "botik.py", line 67, in message_handler
    if random.random() < markov_chance/100 or update.message.reply_to_message.from_user.username == "puklengtime_bot":
AttributeError: 'NoneType' object has no attribute 'from_user'
telegram.ext.dispatcher - ERROR - No error handlers are registered, logging exception.
Traceback (most recent call last):
  File "/home/ubuntu/.local/lib/python3.6/site-packages/telegram/ext/dispatcher.py", line 340, in process_update
    handler.handle_update(update, self, check, context)
  File "/home/ubuntu/.local/lib/python3.6/site-packages/telegram/ext/handler.py", line 119, in handle_update
    return self.callback(update, context)
  File "botik.py", line 62, in message_handler
    message = re.sub(r'''(?i)\b((?:https?://|www\d{0,3}[.]|[a-z0-9.\-]+[.][a-z]{2,4}/)(?:[^\s()<>]+|\(([^\s()<>]+|(\([^\s()<>]+\)))*\))+(?:\(([^\s()<>]+|(\([^\s()<>]+\)))*\)|[^\s`!()\[\]{};:'".,<>?«»“”‘’]))''', " ", update.message.text)
AttributeError: 'NoneType' object has no attribute 'text'
telegram.ext.dispatcher - ERROR - No error handlers are registered, logging exception.
Traceback (most recent call last):
  File "/home/ubuntu/.local/lib/python3.6/site-packages/telegram/ext/dispatcher.py", line 340, in process_update
    handler.handle_update(update, self, check, context)
  File "/home/ubuntu/.local/lib/python3.6/site-packages/telegram/ext/handler.py", line 119, in handle_update
    return self.callback(update, context)
  File "botik.py", line 67, in message_handler
    if random.random() < markov_chance/100 or update.message.reply_to_message.from_user.username == "puklengtime_bot":
AttributeError: 'NoneType' object has no attribute 'from_user'
telegram.ext.dispatcher - ERROR - No error handlers are registered, logging exception.
Traceback (most recent call last):
  File "/home/ubuntu/.local/lib/python3.6/site-packages/telegram/ext/dispatcher.py", line 340, in process_update
    handler.handle_update(update, self, check, context)
  File "/home/ubuntu/.local/lib/python3.6/site-packages/telegram/ext/handler.py", line 119, in handle_update
    return self.callback(update, context)
  File "botik.py", line 67, in message_handler
    if random.random() < markov_chance/100 or update.message.reply_to_message.from_user.username == "puklengtime_bot":
AttributeError: 'NoneType' object has no attribute 'from_user'
telegram.ext.dispatcher - ERROR - No error handlers are registered, logging exception.
Traceback (most recent call last):
  File "/home/ubuntu/.local/lib/python3.6/site-packages/telegram/ext/dispatcher.py", line 340, in process_update
    handler.handle_update(update, self, check, context)
  File "/home/ubuntu/.local/lib/python3.6/site-packages/telegram/ext/handler.py", line 119, in handle_update
    return self.callback(update, context)
  File "botik.py", line 67, in message_handler
    if random.random() < markov_chance/100 or update.message.reply_to_message.from_user.username == "puklengtime_bot":
AttributeError: 'NoneType' object has no attribute 'from_user'
telegram.ext.dispatcher - ERROR - No error handlers are registered, logging exception.
Traceback (most recent call last):
  File "/home/ubuntu/.local/lib/python3.6/site-packages/telegram/ext/dispatcher.py", line 340, in process_update
    handler.handle_update(update, self, check, context)
  File "/home/ubuntu/.local/lib/python3.6/site-packages/telegram/ext/handler.py", line 119, in handle_update
    return self.callback(update, context)
  File "botik.py", line 67, in message_handler
    if random.random() < markov_chance/100 or update.message.reply_to_message.from_user.username == "puklengtime_bot":
AttributeError: 'NoneType' object has no attribute 'from_user'
telegram.ext.dispatcher - ERROR - No error handlers are registered, logging exception.
Traceback (most recent call last):
  File "/home/ubuntu/.local/lib/python3.6/site-packages/telegram/ext/dispatcher.py", line 340, in process_update
    handler.handle_update(update, self, check, context)
  File "/home/ubuntu/.local/lib/python3.6/site-packages/telegram/ext/handler.py", line 119, in handle_update
    return self.callback(update, context)
  File "botik.py", line 67, in message_handler
    if random.random() < markov_chance/100 or update.message.reply_to_message.from_user.username == "puklengtime_bot":
AttributeError: 'NoneType' object has no attribute 'from_user'
telegram.ext.dispatcher - ERROR - No error handlers are registered, logging exception.
Traceback (most recent call last):
  File "/home/ubuntu/.local/lib/python3.6/site-packages/telegram/ext/dispatcher.py", line 340, in process_update
    handler.handle_update(update, self, check, context)
  File "/home/ubuntu/.local/lib/python3.6/site-packages/telegram/ext/handler.py", line 119, in handle_update
    return self.callback(update, context)
  File "botik.py", line 67, in message_handler
    if random.random() < markov_chance/100 or update.message.reply_to_message.from_user.username == "puklengtime_bot":
AttributeError: 'NoneType' object has no attribute 'from_user'
telegram.ext.dispatcher - ERROR - No error handlers are registered, logging exception.
Traceback (most recent call last):
  File "/home/ubuntu/.local/lib/python3.6/site-packages/telegram/ext/dispatcher.py", line 340, in process_update
    handler.handle_update(update, self, check, context)
  File "/home/ubuntu/.local/lib/python3.6/site-packages/telegram/ext/handler.py", line 119, in handle_update
    return self.callback(update, context)
  File "botik.py", line 67, in message_handler
    if random.random() < markov_chance/100 or update.message.reply_to_message.from_user.username == "puklengtime_bot":
AttributeError: 'NoneType' object has no attribute 'from_user'
telegram.ext.dispatcher - ERROR - No error handlers are registered, logging exception.
Traceback (most recent call last):
  File "/home/ubuntu/.local/lib/python3.6/site-packages/telegram/ext/dispatcher.py", line 340, in process_update
    handler.handle_update(update, self, check, context)
  File "/home/ubuntu/.local/lib/python3.6/site-packages/telegram/ext/handler.py", line 119, in handle_update
    return self.callback(update, context)
  File "botik.py", line 67, in message_handler
    if random.random() < markov_chance/100 or update.message.reply_to_message.from_user.username == "puklengtime_bot":
AttributeError: 'NoneType' object has no attribute 'from_user'
telegram.ext.dispatcher - ERROR - No error handlers are registered, logging exception.
Traceback (most recent call last):
  File "/home/ubuntu/.local/lib/python3.6/site-packages/telegram/ext/dispatcher.py", line 340, in process_update
    handler.handle_update(update, self, check, context)
  File "/home/ubuntu/.local/lib/python3.6/site-packages/telegram/ext/handler.py", line 119, in handle_update
    return self.callback(update, context)
  File "botik.py", line 67, in message_handler
    if random.random() < markov_chance/100 or update.message.reply_to_message.from_user.username == "puklengtime_bot":
AttributeError: 'NoneType' object has no attribute 'from_user'
telegram.ext.dispatcher - ERROR - No error handlers are registered, logging exception.
Traceback (most recent call last):
  File "/home/ubuntu/.local/lib/python3.6/site-packages/telegram/ext/dispatcher.py", line 340, in process_update
    handler.handle_update(update, self, check, context)
  File "/home/ubuntu/.local/lib/python3.6/site-packages/telegram/ext/handler.py", line 119, in handle_update
    return self.callback(update, context)
  File "botik.py", line 67, in message_handler
    if random.random() < markov_chance/100 or update.message.reply_to_message.from_user.username == "puklengtime_bot":
AttributeError: 'NoneType' object has no attribute 'from_user'
telegram.ext.dispatcher - ERROR - No error handlers are registered, logging exception.
Traceback (most recent call last):
  File "/home/ubuntu/.local/lib/python3.6/site-packages/telegram/ext/dispatcher.py", line 340, in process_update
    handler.handle_update(update, self, check, context)
  File "/home/ubuntu/.local/lib/python3.6/site-packages/telegram/ext/handler.py", line 119, in handle_update
    return self.callback(update, context)
  File "botik.py", line 67, in message_handler
    if random.random() < markov_chance/100 or update.message.reply_to_message.from_user.username == "puklengtime_bot":
AttributeError: 'NoneType' object has no attribute 'from_user'
telegram.ext.dispatcher - ERROR - No error handlers are registered, logging exception.
Traceback (most recent call last):
  File "/home/ubuntu/.local/lib/python3.6/site-packages/telegram/ext/dispatcher.py", line 340, in process_update
    handler.handle_update(update, self, check, context)
  File "/home/ubuntu/.local/lib/python3.6/site-packages/telegram/ext/handler.py", line 119, in handle_update
    return self.callback(update, context)
  File "botik.py", line 67, in message_handler
    if random.random() < markov_chance/100 or update.message.reply_to_message.from_user.username == "puklengtime_bot":
AttributeError: 'NoneType' object has no attribute 'from_user'
telegram.ext.dispatcher - ERROR - No error handlers are registered, logging exception.
Traceback (most recent call last):
  File "/home/ubuntu/.local/lib/python3.6/site-packages/telegram/ext/dispatcher.py", line 340, in process_update
    handler.handle_update(update, self, check, context)
  File "/home/ubuntu/.local/lib/python3.6/site-packages/telegram/ext/handler.py", line 119, in handle_update
    return self.callback(update, context)
  File "botik.py", line 67, in message_handler
    if random.random() < markov_chance/100 or update.message.reply_to_message.from_user.username == "puklengtime_bot":
AttributeError: 'NoneType' object has no attribute 'from_user'
telegram.ext.dispatcher - ERROR - No error handlers are registered, logging exception.
Traceback (most recent call last):
  File "/home/ubuntu/.local/lib/python3.6/site-packages/telegram/ext/dispatcher.py", line 340, in process_update
    handler.handle_update(update, self, check, context)
  File "/home/ubuntu/.local/lib/python3.6/site-packages/telegram/ext/handler.py", line 119, in handle_update
    return self.callback(update, context)
  File "botik.py", line 67, in message_handler
    if random.random() < markov_chance/100 or update.message.reply_to_message.from_user.username == "puklengtime_bot":
AttributeError: 'NoneType' object has no attribute 'from_user'
telegram.ext.dispatcher - ERROR - No error handlers are registered, logging exception.
Traceback (most recent call last):
  File "/home/ubuntu/.local/lib/python3.6/site-packages/telegram/ext/dispatcher.py", line 340, in process_update
    handler.handle_update(update, self, check, context)
  File "/home/ubuntu/.local/lib/python3.6/site-packages/telegram/ext/handler.py", line 119, in handle_update
    return self.callback(update, context)
  File "botik.py", line 67, in message_handler
    if random.random() < markov_chance/100 or update.message.reply_to_message.from_user.username == "puklengtime_bot":
AttributeError: 'NoneType' object has no attribute 'from_user'
telegram.ext.dispatcher - ERROR - No error handlers are registered, logging exception.
Traceback (most recent call last):
  File "/home/ubuntu/.local/lib/python3.6/site-packages/telegram/ext/dispatcher.py", line 340, in process_update
    handler.handle_update(update, self, check, context)
  File "/home/ubuntu/.local/lib/python3.6/site-packages/telegram/ext/handler.py", line 119, in handle_update
    return self.callback(update, context)
  File "botik.py", line 67, in message_handler
    if random.random() < markov_chance/100 or update.message.reply_to_message.from_user.username == "puklengtime_bot":
AttributeError: 'NoneType' object has no attribute 'from_user'
telegram.ext.dispatcher - ERROR - No error handlers are registered, logging exception.
Traceback (most recent call last):
  File "/home/ubuntu/.local/lib/python3.6/site-packages/telegram/ext/dispatcher.py", line 340, in process_update
    handler.handle_update(update, self, check, context)
  File "/home/ubuntu/.local/lib/python3.6/site-packages/telegram/ext/handler.py", line 119, in handle_update
    return self.callback(update, context)
  File "botik.py", line 67, in message_handler
    if random.random() < markov_chance/100 or update.message.reply_to_message.from_user.username == "puklengtime_bot":
AttributeError: 'NoneType' object has no attribute 'from_user'
telegram.ext.dispatcher - ERROR - No error handlers are registered, logging exception.
Traceback (most recent call last):
  File "/home/ubuntu/.local/lib/python3.6/site-packages/telegram/ext/dispatcher.py", line 340, in process_update
    handler.handle_update(update, self, check, context)
  File "/home/ubuntu/.local/lib/python3.6/site-packages/telegram/ext/handler.py", line 119, in handle_update
    return self.callback(update, context)
  File "botik.py", line 67, in message_handler
    if random.random() < markov_chance/100 or update.message.reply_to_message.from_user.username == "puklengtime_bot":
AttributeError: 'NoneType' object has no attribute 'from_user'
telegram.ext.dispatcher - ERROR - No error handlers are registered, logging exception.
Traceback (most recent call last):
  File "/home/ubuntu/.local/lib/python3.6/site-packages/telegram/ext/dispatcher.py", line 340, in process_update
    handler.handle_update(update, self, check, context)
  File "/home/ubuntu/.local/lib/python3.6/site-packages/telegram/ext/handler.py", line 119, in handle_update
    return self.callback(update, context)
  File "botik.py", line 67, in message_handler
    if random.random() < markov_chance/100 or update.message.reply_to_message.from_user.username == "puklengtime_bot":
AttributeError: 'NoneType' object has no attribute 'from_user'
telegram.ext.dispatcher - ERROR - No error handlers are registered, logging exception.
Traceback (most recent call last):
  File "/home/ubuntu/.local/lib/python3.6/site-packages/telegram/ext/dispatcher.py", line 340, in process_update
    handler.handle_update(update, self, check, context)
  File "/home/ubuntu/.local/lib/python3.6/site-packages/telegram/ext/handler.py", line 119, in handle_update
    return self.callback(update, context)
  File "botik.py", line 67, in message_handler
    if random.random() < markov_chance/100 or update.message.reply_to_message.from_user.username == "puklengtime_bot":
AttributeError: 'NoneType' object has no attribute 'from_user'
telegram.ext.dispatcher - ERROR - No error handlers are registered, logging exception.
Traceback (most recent call last):
  File "/home/ubuntu/.local/lib/python3.6/site-packages/telegram/ext/dispatcher.py", line 340, in process_update
    handler.handle_update(update, self, check, context)
  File "/home/ubuntu/.local/lib/python3.6/site-packages/telegram/ext/handler.py", line 119, in handle_update
    return self.callback(update, context)
  File "botik.py", line 67, in message_handler
    if random.random() < markov_chance/100 or update.message.reply_to_message.from_user.username == "puklengtime_bot":
AttributeError: 'NoneType' object has no attribute 'from_user'
telegram.ext.dispatcher - ERROR - No error handlers are registered, logging exception.
Traceback (most recent call last):
  File "/home/ubuntu/.local/lib/python3.6/site-packages/telegram/ext/dispatcher.py", line 340, in process_update
    handler.handle_update(update, self, check, context)
  File "/home/ubuntu/.local/lib/python3.6/site-packages/telegram/ext/handler.py", line 119, in handle_update
    return self.callback(update, context)
  File "botik.py", line 67, in message_handler
    if random.random() < markov_chance/100 or update.message.reply_to_message.from_user.username == "puklengtime_bot":
AttributeError: 'NoneType' object has no attribute 'from_user'
telegram.ext.dispatcher - ERROR - No error handlers are registered, logging exception.
Traceback (most recent call last):
  File "/home/ubuntu/.local/lib/python3.6/site-packages/telegram/ext/dispatcher.py", line 340, in process_update
    handler.handle_update(update, self, check, context)
  File "/home/ubuntu/.local/lib/python3.6/site-packages/telegram/ext/handler.py", line 119, in handle_update
    return self.callback(update, context)
  File "botik.py", line 67, in message_handler
    if random.random() < markov_chance/100 or update.message.reply_to_message.from_user.username == "puklengtime_bot":
AttributeError: 'NoneType' object has no attribute 'from_user'
telegram.ext.dispatcher - ERROR - No error handlers are registered, logging exception.
Traceback (most recent call last):
  File "/home/ubuntu/.local/lib/python3.6/site-packages/telegram/ext/dispatcher.py", line 340, in process_update
    handler.handle_update(update, self, check, context)
  File "/home/ubuntu/.local/lib/python3.6/site-packages/telegram/ext/handler.py", line 119, in handle_update
    return self.callback(update, context)
  File "botik.py", line 67, in message_handler
    if random.random() < markov_chance/100 or update.message.reply_to_message.from_user.username == "puklengtime_bot":
AttributeError: 'NoneType' object has no attribute 'from_user'
telegram.ext.dispatcher - ERROR - No error handlers are registered, logging exception.
Traceback (most recent call last):
  File "/home/ubuntu/.local/lib/python3.6/site-packages/telegram/ext/dispatcher.py", line 340, in process_update
    handler.handle_update(update, self, check, context)
  File "/home/ubuntu/.local/lib/python3.6/site-packages/telegram/ext/handler.py", line 119, in handle_update
    return self.callback(update, context)
  File "botik.py", line 67, in message_handler
    if random.random() < markov_chance/100 or update.message.reply_to_message.from_user.username == "puklengtime_bot":
AttributeError: 'NoneType' object has no attribute 'from_user'
telegram.ext.dispatcher - ERROR - No error handlers are registered, logging exception.
Traceback (most recent call last):
  File "/home/ubuntu/.local/lib/python3.6/site-packages/telegram/ext/dispatcher.py", line 340, in process_update
    handler.handle_update(update, self, check, context)
  File "/home/ubuntu/.local/lib/python3.6/site-packages/telegram/ext/handler.py", line 119, in handle_update
    return self.callback(update, context)
  File "botik.py", line 67, in message_handler
    if random.random() < markov_chance/100 or update.message.reply_to_message.from_user.username == "puklengtime_bot":
AttributeError: 'NoneType' object has no attribute 'from_user'
telegram.ext.dispatcher - ERROR - No error handlers are registered, logging exception.
Traceback (most recent call last):
  File "/home/ubuntu/.local/lib/python3.6/site-packages/telegram/ext/dispatcher.py", line 340, in process_update
    handler.handle_update(update, self, check, context)
  File "/home/ubuntu/.local/lib/python3.6/site-packages/telegram/ext/handler.py", line 119, in handle_update
    return self.callback(update, context)
  File "botik.py", line 67, in message_handler
    if random.random() < markov_chance/100 or update.message.reply_to_message.from_user.username == "puklengtime_bot":
AttributeError: 'NoneType' object has no attribute 'from_user'
telegram.ext.dispatcher - ERROR - No error handlers are registered, logging exception.
Traceback (most recent call last):
  File "/home/ubuntu/.local/lib/python3.6/site-packages/telegram/ext/dispatcher.py", line 340, in process_update
    handler.handle_update(update, self, check, context)
  File "/home/ubuntu/.local/lib/python3.6/site-packages/telegram/ext/handler.py", line 119, in handle_update
    return self.callback(update, context)
  File "botik.py", line 67, in message_handler
    if random.random() < markov_chance/100 or update.message.reply_to_message.from_user.username == "puklengtime_bot":
AttributeError: 'NoneType' object has no attribute 'from_user'
telegram.ext.dispatcher - ERROR - No error handlers are registered, logging exception.
Traceback (most recent call last):
  File "/home/ubuntu/.local/lib/python3.6/site-packages/telegram/ext/dispatcher.py", line 340, in process_update
    handler.handle_update(update, self, check, context)
  File "/home/ubuntu/.local/lib/python3.6/site-packages/telegram/ext/handler.py", line 119, in handle_update
    return self.callback(update, context)
  File "botik.py", line 67, in message_handler
    if random.random() < markov_chance/100 or update.message.reply_to_message.from_user.username == "puklengtime_bot":
AttributeError: 'NoneType' object has no attribute 'from_user'
telegram.ext.dispatcher - ERROR - No error handlers are registered, logging exception.
Traceback (most recent call last):
  File "/home/ubuntu/.local/lib/python3.6/site-packages/telegram/ext/dispatcher.py", line 340, in process_update
    handler.handle_update(update, self, check, context)
  File "/home/ubuntu/.local/lib/python3.6/site-packages/telegram/ext/handler.py", line 119, in handle_update
    return self.callback(update, context)
  File "botik.py", line 67, in message_handler
    if random.random() < markov_chance/100 or update.message.reply_to_message.from_user.username == "puklengtime_bot":
AttributeError: 'NoneType' object has no attribute 'from_user'
telegram.ext.dispatcher - ERROR - No error handlers are registered, logging exception.
Traceback (most recent call last):
  File "/home/ubuntu/.local/lib/python3.6/site-packages/telegram/ext/dispatcher.py", line 340, in process_update
    handler.handle_update(update, self, check, context)
  File "/home/ubuntu/.local/lib/python3.6/site-packages/telegram/ext/handler.py", line 119, in handle_update
    return self.callback(update, context)
  File "botik.py", line 67, in message_handler
    if random.random() < markov_chance/100 or update.message.reply_to_message.from_user.username == "puklengtime_bot":
AttributeError: 'NoneType' object has no attribute 'from_user'
telegram.ext.dispatcher - ERROR - No error handlers are registered, logging exception.
Traceback (most recent call last):
  File "/home/ubuntu/.local/lib/python3.6/site-packages/telegram/ext/dispatcher.py", line 340, in process_update
    handler.handle_update(update, self, check, context)
  File "/home/ubuntu/.local/lib/python3.6/site-packages/telegram/ext/handler.py", line 119, in handle_update
    return self.callback(update, context)
  File "botik.py", line 67, in message_handler
    if random.random() < markov_chance/100 or update.message.reply_to_message.from_user.username == "puklengtime_bot":
AttributeError: 'NoneType' object has no attribute 'from_user'
telegram.ext.dispatcher - ERROR - No error handlers are registered, logging exception.
Traceback (most recent call last):
  File "/home/ubuntu/.local/lib/python3.6/site-packages/telegram/ext/dispatcher.py", line 340, in process_update
    handler.handle_update(update, self, check, context)
  File "/home/ubuntu/.local/lib/python3.6/site-packages/telegram/ext/handler.py", line 119, in handle_update
    return self.callback(update, context)
  File "botik.py", line 67, in message_handler
    if random.random() < markov_chance/100 or update.message.reply_to_message.from_user.username == "puklengtime_bot":
AttributeError: 'NoneType' object has no attribute 'from_user'
telegram.ext.dispatcher - ERROR - No error handlers are registered, logging exception.
Traceback (most recent call last):
  File "/home/ubuntu/.local/lib/python3.6/site-packages/telegram/ext/dispatcher.py", line 340, in process_update
    handler.handle_update(update, self, check, context)
  File "/home/ubuntu/.local/lib/python3.6/site-packages/telegram/ext/handler.py", line 119, in handle_update
    return self.callback(update, context)
  File "botik.py", line 67, in message_handler
    if random.random() < markov_chance/100 or update.message.reply_to_message.from_user.username == "puklengtime_bot":
AttributeError: 'NoneType' object has no attribute 'from_user'
telegram.ext.dispatcher - ERROR - No error handlers are registered, logging exception.
Traceback (most recent call last):
  File "/home/ubuntu/.local/lib/python3.6/site-packages/telegram/ext/dispatcher.py", line 340, in process_update
    handler.handle_update(update, self, check, context)
  File "/home/ubuntu/.local/lib/python3.6/site-packages/telegram/ext/handler.py", line 119, in handle_update
    return self.callback(update, context)
  File "botik.py", line 67, in message_handler
    if random.random() < markov_chance/100 or update.message.reply_to_message.from_user.username == "puklengtime_bot":
AttributeError: 'NoneType' object has no attribute 'from_user'
telegram.ext.dispatcher - ERROR - No error handlers are registered, logging exception.
Traceback (most recent call last):
  File "/home/ubuntu/.local/lib/python3.6/site-packages/telegram/ext/dispatcher.py", line 340, in process_update
    handler.handle_update(update, self, check, context)
  File "/home/ubuntu/.local/lib/python3.6/site-packages/telegram/ext/handler.py", line 119, in handle_update
    return self.callback(update, context)
  File "botik.py", line 67, in message_handler
    if random.random() < markov_chance/100 or update.message.reply_to_message.from_user.username == "puklengtime_bot":
AttributeError: 'NoneType' object has no attribute 'from_user'
telegram.ext.dispatcher - ERROR - No error handlers are registered, logging exception.
Traceback (most recent call last):
  File "/home/ubuntu/.local/lib/python3.6/site-packages/telegram/ext/dispatcher.py", line 340, in process_update
    handler.handle_update(update, self, check, context)
  File "/home/ubuntu/.local/lib/python3.6/site-packages/telegram/ext/handler.py", line 119, in handle_update
    return self.callback(update, context)
  File "botik.py", line 67, in message_handler
    if random.random() < markov_chance/100 or update.message.reply_to_message.from_user.username == "puklengtime_bot":
AttributeError: 'NoneType' object has no attribute 'from_user'
telegram.ext.dispatcher - ERROR - No error handlers are registered, logging exception.
Traceback (most recent call last):
  File "/home/ubuntu/.local/lib/python3.6/site-packages/telegram/ext/dispatcher.py", line 340, in process_update
    handler.handle_update(update, self, check, context)
  File "/home/ubuntu/.local/lib/python3.6/site-packages/telegram/ext/handler.py", line 119, in handle_update
    return self.callback(update, context)
  File "botik.py", line 67, in message_handler
    if random.random() < markov_chance/100 or update.message.reply_to_message.from_user.username == "puklengtime_bot":
AttributeError: 'NoneType' object has no attribute 'from_user'
telegram.ext.dispatcher - ERROR - No error handlers are registered, logging exception.
Traceback (most recent call last):
  File "/home/ubuntu/.local/lib/python3.6/site-packages/telegram/ext/dispatcher.py", line 340, in process_update
    handler.handle_update(update, self, check, context)
  File "/home/ubuntu/.local/lib/python3.6/site-packages/telegram/ext/handler.py", line 119, in handle_update
    return self.callback(update, context)
  File "botik.py", line 67, in message_handler
    if random.random() < markov_chance/100 or update.message.reply_to_message.from_user.username == "puklengtime_bot":
AttributeError: 'NoneType' object has no attribute 'from_user'
telegram.ext.dispatcher - ERROR - No error handlers are registered, logging exception.
Traceback (most recent call last):
  File "/home/ubuntu/.local/lib/python3.6/site-packages/telegram/ext/dispatcher.py", line 340, in process_update
    handler.handle_update(update, self, check, context)
  File "/home/ubuntu/.local/lib/python3.6/site-packages/telegram/ext/handler.py", line 119, in handle_update
    return self.callback(update, context)
  File "botik.py", line 67, in message_handler
    if random.random() < markov_chance/100 or update.message.reply_to_message.from_user.username == "puklengtime_bot":
AttributeError: 'NoneType' object has no attribute 'from_user'
telegram.ext.dispatcher - ERROR - No error handlers are registered, logging exception.
Traceback (most recent call last):
  File "/home/ubuntu/.local/lib/python3.6/site-packages/telegram/ext/dispatcher.py", line 340, in process_update
    handler.handle_update(update, self, check, context)
  File "/home/ubuntu/.local/lib/python3.6/site-packages/telegram/ext/handler.py", line 119, in handle_update
    return self.callback(update, context)
  File "botik.py", line 67, in message_handler
    if random.random() < markov_chance/100 or update.message.reply_to_message.from_user.username == "puklengtime_bot":
AttributeError: 'NoneType' object has no attribute 'from_user'
telegram.ext.dispatcher - ERROR - No error handlers are registered, logging exception.
Traceback (most recent call last):
  File "/home/ubuntu/.local/lib/python3.6/site-packages/telegram/ext/dispatcher.py", line 340, in process_update
    handler.handle_update(update, self, check, context)
  File "/home/ubuntu/.local/lib/python3.6/site-packages/telegram/ext/handler.py", line 119, in handle_update
    return self.callback(update, context)
  File "botik.py", line 67, in message_handler
    if random.random() < markov_chance/100 or update.message.reply_to_message.from_user.username == "puklengtime_bot":
AttributeError: 'NoneType' object has no attribute 'from_user'
telegram.ext.dispatcher - ERROR - No error handlers are registered, logging exception.
Traceback (most recent call last):
  File "/home/ubuntu/.local/lib/python3.6/site-packages/telegram/ext/dispatcher.py", line 340, in process_update
    handler.handle_update(update, self, check, context)
  File "/home/ubuntu/.local/lib/python3.6/site-packages/telegram/ext/handler.py", line 119, in handle_update
    return self.callback(update, context)
  File "botik.py", line 67, in message_handler
    if random.random() < markov_chance/100 or update.message.reply_to_message.from_user.username == "puklengtime_bot":
AttributeError: 'NoneType' object has no attribute 'from_user'
telegram.ext.dispatcher - ERROR - No error handlers are registered, logging exception.
Traceback (most recent call last):
  File "/home/ubuntu/.local/lib/python3.6/site-packages/telegram/ext/dispatcher.py", line 340, in process_update
    handler.handle_update(update, self, check, context)
  File "/home/ubuntu/.local/lib/python3.6/site-packages/telegram/ext/handler.py", line 119, in handle_update
    return self.callback(update, context)
  File "botik.py", line 67, in message_handler
    if random.random() < markov_chance/100 or update.message.reply_to_message.from_user.username == "puklengtime_bot":
AttributeError: 'NoneType' object has no attribute 'from_user'
telegram.ext.dispatcher - ERROR - No error handlers are registered, logging exception.
Traceback (most recent call last):
  File "/home/ubuntu/.local/lib/python3.6/site-packages/telegram/ext/dispatcher.py", line 340, in process_update
    handler.handle_update(update, self, check, context)
  File "/home/ubuntu/.local/lib/python3.6/site-packages/telegram/ext/handler.py", line 119, in handle_update
    return self.callback(update, context)
  File "botik.py", line 67, in message_handler
    if random.random() < markov_chance/100 or update.message.reply_to_message.from_user.username == "puklengtime_bot":
AttributeError: 'NoneType' object has no attribute 'from_user'
telegram.ext.dispatcher - ERROR - No error handlers are registered, logging exception.
Traceback (most recent call last):
  File "/home/ubuntu/.local/lib/python3.6/site-packages/telegram/ext/dispatcher.py", line 340, in process_update
    handler.handle_update(update, self, check, context)
  File "/home/ubuntu/.local/lib/python3.6/site-packages/telegram/ext/handler.py", line 119, in handle_update
    return self.callback(update, context)
  File "botik.py", line 67, in message_handler
    if random.random() < markov_chance/100 or update.message.reply_to_message.from_user.username == "puklengtime_bot":
AttributeError: 'NoneType' object has no attribute 'from_user'
telegram.ext.dispatcher - ERROR - No error handlers are registered, logging exception.
Traceback (most recent call last):
  File "/home/ubuntu/.local/lib/python3.6/site-packages/telegram/ext/dispatcher.py", line 340, in process_update
    handler.handle_update(update, self, check, context)
  File "/home/ubuntu/.local/lib/python3.6/site-packages/telegram/ext/handler.py", line 119, in handle_update
    return self.callback(update, context)
  File "botik.py", line 67, in message_handler
    if random.random() < markov_chance/100 or update.message.reply_to_message.from_user.username == "puklengtime_bot":
AttributeError: 'NoneType' object has no attribute 'from_user'
telegram.ext.dispatcher - ERROR - No error handlers are registered, logging exception.
Traceback (most recent call last):
  File "/home/ubuntu/.local/lib/python3.6/site-packages/telegram/ext/dispatcher.py", line 340, in process_update
    handler.handle_update(update, self, check, context)
  File "/home/ubuntu/.local/lib/python3.6/site-packages/telegram/ext/handler.py", line 119, in handle_update
    return self.callback(update, context)
  File "botik.py", line 67, in message_handler
    if random.random() < markov_chance/100 or update.message.reply_to_message.from_user.username == "puklengtime_bot":
AttributeError: 'NoneType' object has no attribute 'from_user'
telegram.ext.dispatcher - ERROR - No error handlers are registered, logging exception.
Traceback (most recent call last):
  File "/home/ubuntu/.local/lib/python3.6/site-packages/telegram/ext/dispatcher.py", line 340, in process_update
    handler.handle_update(update, self, check, context)
  File "/home/ubuntu/.local/lib/python3.6/site-packages/telegram/ext/handler.py", line 119, in handle_update
    return self.callback(update, context)
  File "botik.py", line 67, in message_handler
    if random.random() < markov_chance/100 or update.message.reply_to_message.from_user.username == "puklengtime_bot":
AttributeError: 'NoneType' object has no attribute 'from_user'
telegram.ext.dispatcher - ERROR - No error handlers are registered, logging exception.
Traceback (most recent call last):
  File "/home/ubuntu/.local/lib/python3.6/site-packages/telegram/ext/dispatcher.py", line 340, in process_update
    handler.handle_update(update, self, check, context)
  File "/home/ubuntu/.local/lib/python3.6/site-packages/telegram/ext/handler.py", line 119, in handle_update
    return self.callback(update, context)
  File "botik.py", line 62, in message_handler
    message = re.sub(r'''(?i)\b((?:https?://|www\d{0,3}[.]|[a-z0-9.\-]+[.][a-z]{2,4}/)(?:[^\s()<>]+|\(([^\s()<>]+|(\([^\s()<>]+\)))*\))+(?:\(([^\s()<>]+|(\([^\s()<>]+\)))*\)|[^\s`!()\[\]{};:'".,<>?«»“”‘’]))''', " ", update.message.text)
AttributeError: 'NoneType' object has no attribute 'text'
telegram.ext.dispatcher - ERROR - No error handlers are registered, logging exception.
Traceback (most recent call last):
  File "/home/ubuntu/.local/lib/python3.6/site-packages/telegram/ext/dispatcher.py", line 340, in process_update
    handler.handle_update(update, self, check, context)
  File "/home/ubuntu/.local/lib/python3.6/site-packages/telegram/ext/handler.py", line 119, in handle_update
    return self.callback(update, context)
  File "botik.py", line 67, in message_handler
    if random.random() < markov_chance/100 or update.message.reply_to_message.from_user.username == "puklengtime_bot":
AttributeError: 'NoneType' object has no attribute 'from_user'
telegram.ext.dispatcher - ERROR - No error handlers are registered, logging exception.
Traceback (most recent call last):
  File "/home/ubuntu/.local/lib/python3.6/site-packages/telegram/ext/dispatcher.py", line 340, in process_update
    handler.handle_update(update, self, check, context)
  File "/home/ubuntu/.local/lib/python3.6/site-packages/telegram/ext/handler.py", line 119, in handle_update
    return self.callback(update, context)
  File "botik.py", line 67, in message_handler
    if random.random() < markov_chance/100 or update.message.reply_to_message.from_user.username == "puklengtime_bot":
AttributeError: 'NoneType' object has no attribute 'from_user'
telegram.ext.dispatcher - ERROR - No error handlers are registered, logging exception.
Traceback (most recent call last):
  File "/home/ubuntu/.local/lib/python3.6/site-packages/telegram/ext/dispatcher.py", line 340, in process_update
    handler.handle_update(update, self, check, context)
  File "/home/ubuntu/.local/lib/python3.6/site-packages/telegram/ext/handler.py", line 119, in handle_update
    return self.callback(update, context)
  File "botik.py", line 67, in message_handler
    if random.random() < markov_chance/100 or update.message.reply_to_message.from_user.username == "puklengtime_bot":
AttributeError: 'NoneType' object has no attribute 'from_user'
telegram.ext.dispatcher - ERROR - No error handlers are registered, logging exception.
Traceback (most recent call last):
  File "/home/ubuntu/.local/lib/python3.6/site-packages/telegram/ext/dispatcher.py", line 340, in process_update
    handler.handle_update(update, self, check, context)
  File "/home/ubuntu/.local/lib/python3.6/site-packages/telegram/ext/handler.py", line 119, in handle_update
    return self.callback(update, context)
  File "botik.py", line 67, in message_handler
    if random.random() < markov_chance/100 or update.message.reply_to_message.from_user.username == "puklengtime_bot":
AttributeError: 'NoneType' object has no attribute 'from_user'
telegram.ext.dispatcher - ERROR - No error handlers are registered, logging exception.
Traceback (most recent call last):
  File "/home/ubuntu/.local/lib/python3.6/site-packages/telegram/ext/dispatcher.py", line 340, in process_update
    handler.handle_update(update, self, check, context)
  File "/home/ubuntu/.local/lib/python3.6/site-packages/telegram/ext/handler.py", line 119, in handle_update
    return self.callback(update, context)
  File "botik.py", line 67, in message_handler
    if random.random() < markov_chance/100 or update.message.reply_to_message.from_user.username == "puklengtime_bot":
AttributeError: 'NoneType' object has no attribute 'from_user'
telegram.ext.dispatcher - ERROR - No error handlers are registered, logging exception.
Traceback (most recent call last):
  File "/home/ubuntu/.local/lib/python3.6/site-packages/telegram/ext/dispatcher.py", line 340, in process_update
    handler.handle_update(update, self, check, context)
  File "/home/ubuntu/.local/lib/python3.6/site-packages/telegram/ext/handler.py", line 119, in handle_update
    return self.callback(update, context)
  File "botik.py", line 67, in message_handler
    if random.random() < markov_chance/100 or update.message.reply_to_message.from_user.username == "puklengtime_bot":
AttributeError: 'NoneType' object has no attribute 'from_user'
telegram.ext.dispatcher - ERROR - No error handlers are registered, logging exception.
Traceback (most recent call last):
  File "/home/ubuntu/.local/lib/python3.6/site-packages/telegram/ext/dispatcher.py", line 340, in process_update
    handler.handle_update(update, self, check, context)
  File "/home/ubuntu/.local/lib/python3.6/site-packages/telegram/ext/handler.py", line 119, in handle_update
    return self.callback(update, context)
  File "botik.py", line 62, in message_handler
    message = re.sub(r'''(?i)\b((?:https?://|www\d{0,3}[.]|[a-z0-9.\-]+[.][a-z]{2,4}/)(?:[^\s()<>]+|\(([^\s()<>]+|(\([^\s()<>]+\)))*\))+(?:\(([^\s()<>]+|(\([^\s()<>]+\)))*\)|[^\s`!()\[\]{};:'".,<>?«»“”‘’]))''', " ", update.message.text)
AttributeError: 'NoneType' object has no attribute 'text'
telegram.ext.dispatcher - ERROR - No error handlers are registered, logging exception.
Traceback (most recent call last):
  File "/home/ubuntu/.local/lib/python3.6/site-packages/telegram/ext/dispatcher.py", line 340, in process_update
    handler.handle_update(update, self, check, context)
  File "/home/ubuntu/.local/lib/python3.6/site-packages/telegram/ext/handler.py", line 119, in handle_update
    return self.callback(update, context)
  File "botik.py", line 67, in message_handler
    if random.random() < markov_chance/100 or update.message.reply_to_message.from_user.username == "puklengtime_bot":
AttributeError: 'NoneType' object has no attribute 'from_user'
telegram.ext.dispatcher - ERROR - No error handlers are registered, logging exception.
Traceback (most recent call last):
  File "/home/ubuntu/.local/lib/python3.6/site-packages/telegram/ext/dispatcher.py", line 340, in process_update
    handler.handle_update(update, self, check, context)
  File "/home/ubuntu/.local/lib/python3.6/site-packages/telegram/ext/handler.py", line 119, in handle_update
    return self.callback(update, context)
  File "botik.py", line 67, in message_handler
    if random.random() < markov_chance/100 or update.message.reply_to_message.from_user.username == "puklengtime_bot":
AttributeError: 'NoneType' object has no attribute 'from_user'
telegram.ext.dispatcher - ERROR - No error handlers are registered, logging exception.
Traceback (most recent call last):
  File "/home/ubuntu/.local/lib/python3.6/site-packages/telegram/ext/dispatcher.py", line 340, in process_update
    handler.handle_update(update, self, check, context)
  File "/home/ubuntu/.local/lib/python3.6/site-packages/telegram/ext/handler.py", line 119, in handle_update
    return self.callback(update, context)
  File "botik.py", line 67, in message_handler
    if random.random() < markov_chance/100 or update.message.reply_to_message.from_user.username == "puklengtime_bot":
AttributeError: 'NoneType' object has no attribute 'from_user'
telegram.ext.dispatcher - ERROR - No error handlers are registered, logging exception.
Traceback (most recent call last):
  File "/home/ubuntu/.local/lib/python3.6/site-packages/telegram/ext/dispatcher.py", line 340, in process_update
    handler.handle_update(update, self, check, context)
  File "/home/ubuntu/.local/lib/python3.6/site-packages/telegram/ext/handler.py", line 119, in handle_update
    return self.callback(update, context)
  File "botik.py", line 67, in message_handler
    if random.random() < markov_chance/100 or update.message.reply_to_message.from_user.username == "puklengtime_bot":
AttributeError: 'NoneType' object has no attribute 'from_user'
telegram.ext.dispatcher - ERROR - No error handlers are registered, logging exception.
Traceback (most recent call last):
  File "/home/ubuntu/.local/lib/python3.6/site-packages/telegram/ext/dispatcher.py", line 340, in process_update
    handler.handle_update(update, self, check, context)
  File "/home/ubuntu/.local/lib/python3.6/site-packages/telegram/ext/handler.py", line 119, in handle_update
    return self.callback(update, context)
  File "botik.py", line 67, in message_handler
    if random.random() < markov_chance/100 or update.message.reply_to_message.from_user.username == "puklengtime_bot":
AttributeError: 'NoneType' object has no attribute 'from_user'
telegram.ext.dispatcher - ERROR - No error handlers are registered, logging exception.
Traceback (most recent call last):
  File "/home/ubuntu/.local/lib/python3.6/site-packages/telegram/ext/dispatcher.py", line 340, in process_update
    handler.handle_update(update, self, check, context)
  File "/home/ubuntu/.local/lib/python3.6/site-packages/telegram/ext/handler.py", line 119, in handle_update
    return self.callback(update, context)
  File "botik.py", line 67, in message_handler
    if random.random() < markov_chance/100 or update.message.reply_to_message.from_user.username == "puklengtime_bot":
AttributeError: 'NoneType' object has no attribute 'from_user'
telegram.ext.dispatcher - ERROR - No error handlers are registered, logging exception.
Traceback (most recent call last):
  File "/home/ubuntu/.local/lib/python3.6/site-packages/telegram/ext/dispatcher.py", line 340, in process_update
    handler.handle_update(update, self, check, context)
  File "/home/ubuntu/.local/lib/python3.6/site-packages/telegram/ext/handler.py", line 119, in handle_update
    return self.callback(update, context)
  File "botik.py", line 67, in message_handler
    if random.random() < markov_chance/100 or update.message.reply_to_message.from_user.username == "puklengtime_bot":
AttributeError: 'NoneType' object has no attribute 'from_user'
telegram.ext.dispatcher - ERROR - No error handlers are registered, logging exception.
Traceback (most recent call last):
  File "/home/ubuntu/.local/lib/python3.6/site-packages/telegram/ext/dispatcher.py", line 340, in process_update
    handler.handle_update(update, self, check, context)
  File "/home/ubuntu/.local/lib/python3.6/site-packages/telegram/ext/handler.py", line 119, in handle_update
    return self.callback(update, context)
  File "botik.py", line 67, in message_handler
    if random.random() < markov_chance/100 or update.message.reply_to_message.from_user.username == "puklengtime_bot":
AttributeError: 'NoneType' object has no attribute 'from_user'
telegram.ext.dispatcher - ERROR - No error handlers are registered, logging exception.
Traceback (most recent call last):
  File "/home/ubuntu/.local/lib/python3.6/site-packages/telegram/ext/dispatcher.py", line 340, in process_update
    handler.handle_update(update, self, check, context)
  File "/home/ubuntu/.local/lib/python3.6/site-packages/telegram/ext/handler.py", line 119, in handle_update
    return self.callback(update, context)
  File "botik.py", line 67, in message_handler
    if random.random() < markov_chance/100 or update.message.reply_to_message.from_user.username == "puklengtime_bot":
AttributeError: 'NoneType' object has no attribute 'from_user'
telegram.ext.dispatcher - ERROR - No error handlers are registered, logging exception.
Traceback (most recent call last):
  File "/home/ubuntu/.local/lib/python3.6/site-packages/telegram/ext/dispatcher.py", line 340, in process_update
    handler.handle_update(update, self, check, context)
  File "/home/ubuntu/.local/lib/python3.6/site-packages/telegram/ext/handler.py", line 119, in handle_update
    return self.callback(update, context)
  File "botik.py", line 67, in message_handler
    if random.random() < markov_chance/100 or update.message.reply_to_message.from_user.username == "puklengtime_bot":
AttributeError: 'NoneType' object has no attribute 'from_user'
telegram.ext.dispatcher - ERROR - No error handlers are registered, logging exception.
Traceback (most recent call last):
  File "/home/ubuntu/.local/lib/python3.6/site-packages/telegram/ext/dispatcher.py", line 340, in process_update
    handler.handle_update(update, self, check, context)
  File "/home/ubuntu/.local/lib/python3.6/site-packages/telegram/ext/handler.py", line 119, in handle_update
    return self.callback(update, context)
  File "botik.py", line 67, in message_handler
    if random.random() < markov_chance/100 or update.message.reply_to_message.from_user.username == "puklengtime_bot":
AttributeError: 'NoneType' object has no attribute 'from_user'
telegram.ext.dispatcher - ERROR - No error handlers are registered, logging exception.
Traceback (most recent call last):
  File "/home/ubuntu/.local/lib/python3.6/site-packages/telegram/ext/dispatcher.py", line 340, in process_update
    handler.handle_update(update, self, check, context)
  File "/home/ubuntu/.local/lib/python3.6/site-packages/telegram/ext/handler.py", line 119, in handle_update
    return self.callback(update, context)
  File "botik.py", line 67, in message_handler
    if random.random() < markov_chance/100 or update.message.reply_to_message.from_user.username == "puklengtime_bot":
AttributeError: 'NoneType' object has no attribute 'from_user'
telegram.ext.dispatcher - ERROR - No error handlers are registered, logging exception.
Traceback (most recent call last):
  File "/home/ubuntu/.local/lib/python3.6/site-packages/telegram/ext/dispatcher.py", line 340, in process_update
    handler.handle_update(update, self, check, context)
  File "/home/ubuntu/.local/lib/python3.6/site-packages/telegram/ext/handler.py", line 119, in handle_update
    return self.callback(update, context)
  File "botik.py", line 67, in message_handler
    if random.random() < markov_chance/100 or update.message.reply_to_message.from_user.username == "puklengtime_bot":
AttributeError: 'NoneType' object has no attribute 'from_user'
telegram.ext.dispatcher - ERROR - No error handlers are registered, logging exception.
Traceback (most recent call last):
  File "/home/ubuntu/.local/lib/python3.6/site-packages/telegram/ext/dispatcher.py", line 340, in process_update
    handler.handle_update(update, self, check, context)
  File "/home/ubuntu/.local/lib/python3.6/site-packages/telegram/ext/handler.py", line 119, in handle_update
    return self.callback(update, context)
  File "botik.py", line 67, in message_handler
    if random.random() < markov_chance/100 or update.message.reply_to_message.from_user.username == "puklengtime_bot":
AttributeError: 'NoneType' object has no attribute 'from_user'
telegram.ext.dispatcher - ERROR - No error handlers are registered, logging exception.
Traceback (most recent call last):
  File "/home/ubuntu/.local/lib/python3.6/site-packages/telegram/ext/dispatcher.py", line 340, in process_update
    handler.handle_update(update, self, check, context)
  File "/home/ubuntu/.local/lib/python3.6/site-packages/telegram/ext/handler.py", line 119, in handle_update
    return self.callback(update, context)
  File "botik.py", line 67, in message_handler
    if random.random() < markov_chance/100 or update.message.reply_to_message.from_user.username == "puklengtime_bot":
AttributeError: 'NoneType' object has no attribute 'from_user'
telegram.ext.dispatcher - ERROR - No error handlers are registered, logging exception.
Traceback (most recent call last):
  File "/home/ubuntu/.local/lib/python3.6/site-packages/telegram/ext/dispatcher.py", line 340, in process_update
    handler.handle_update(update, self, check, context)
  File "/home/ubuntu/.local/lib/python3.6/site-packages/telegram/ext/handler.py", line 119, in handle_update
    return self.callback(update, context)
  File "botik.py", line 67, in message_handler
    if random.random() < markov_chance/100 or update.message.reply_to_message.from_user.username == "puklengtime_bot":
AttributeError: 'NoneType' object has no attribute 'from_user'
telegram.ext.dispatcher - ERROR - No error handlers are registered, logging exception.
Traceback (most recent call last):
  File "/home/ubuntu/.local/lib/python3.6/site-packages/telegram/ext/dispatcher.py", line 340, in process_update
    handler.handle_update(update, self, check, context)
  File "/home/ubuntu/.local/lib/python3.6/site-packages/telegram/ext/handler.py", line 119, in handle_update
    return self.callback(update, context)
  File "botik.py", line 67, in message_handler
    if random.random() < markov_chance/100 or update.message.reply_to_message.from_user.username == "puklengtime_bot":
AttributeError: 'NoneType' object has no attribute 'from_user'
telegram.ext.dispatcher - ERROR - No error handlers are registered, logging exception.
Traceback (most recent call last):
  File "/home/ubuntu/.local/lib/python3.6/site-packages/telegram/ext/dispatcher.py", line 340, in process_update
    handler.handle_update(update, self, check, context)
  File "/home/ubuntu/.local/lib/python3.6/site-packages/telegram/ext/handler.py", line 119, in handle_update
    return self.callback(update, context)
  File "botik.py", line 67, in message_handler
    if random.random() < markov_chance/100 or update.message.reply_to_message.from_user.username == "puklengtime_bot":
AttributeError: 'NoneType' object has no attribute 'from_user'
telegram.ext.dispatcher - ERROR - No error handlers are registered, logging exception.
Traceback (most recent call last):
  File "/home/ubuntu/.local/lib/python3.6/site-packages/telegram/ext/dispatcher.py", line 340, in process_update
    handler.handle_update(update, self, check, context)
  File "/home/ubuntu/.local/lib/python3.6/site-packages/telegram/ext/handler.py", line 119, in handle_update
    return self.callback(update, context)
  File "botik.py", line 67, in message_handler
    if random.random() < markov_chance/100 or update.message.reply_to_message.from_user.username == "puklengtime_bot":
AttributeError: 'NoneType' object has no attribute 'from_user'
telegram.ext.dispatcher - ERROR - No error handlers are registered, logging exception.
Traceback (most recent call last):
  File "/home/ubuntu/.local/lib/python3.6/site-packages/telegram/ext/dispatcher.py", line 340, in process_update
    handler.handle_update(update, self, check, context)
  File "/home/ubuntu/.local/lib/python3.6/site-packages/telegram/ext/handler.py", line 119, in handle_update
    return self.callback(update, context)
  File "botik.py", line 67, in message_handler
    if random.random() < markov_chance/100 or update.message.reply_to_message.from_user.username == "puklengtime_bot":
AttributeError: 'NoneType' object has no attribute 'from_user'
telegram.ext.dispatcher - ERROR - No error handlers are registered, logging exception.
Traceback (most recent call last):
  File "/home/ubuntu/.local/lib/python3.6/site-packages/telegram/ext/dispatcher.py", line 340, in process_update
    handler.handle_update(update, self, check, context)
  File "/home/ubuntu/.local/lib/python3.6/site-packages/telegram/ext/handler.py", line 119, in handle_update
    return self.callback(update, context)
  File "botik.py", line 67, in message_handler
    if random.random() < markov_chance/100 or update.message.reply_to_message.from_user.username == "puklengtime_bot":
AttributeError: 'NoneType' object has no attribute 'from_user'
telegram.ext.dispatcher - ERROR - No error handlers are registered, logging exception.
Traceback (most recent call last):
  File "/home/ubuntu/.local/lib/python3.6/site-packages/telegram/ext/dispatcher.py", line 340, in process_update
    handler.handle_update(update, self, check, context)
  File "/home/ubuntu/.local/lib/python3.6/site-packages/telegram/ext/handler.py", line 119, in handle_update
    return self.callback(update, context)
  File "botik.py", line 67, in message_handler
    if random.random() < markov_chance/100 or update.message.reply_to_message.from_user.username == "puklengtime_bot":
AttributeError: 'NoneType' object has no attribute 'from_user'
telegram.ext.dispatcher - ERROR - No error handlers are registered, logging exception.
Traceback (most recent call last):
  File "/home/ubuntu/.local/lib/python3.6/site-packages/telegram/ext/dispatcher.py", line 340, in process_update
    handler.handle_update(update, self, check, context)
  File "/home/ubuntu/.local/lib/python3.6/site-packages/telegram/ext/handler.py", line 119, in handle_update
    return self.callback(update, context)
  File "botik.py", line 67, in message_handler
    if random.random() < markov_chance/100 or update.message.reply_to_message.from_user.username == "puklengtime_bot":
AttributeError: 'NoneType' object has no attribute 'from_user'
telegram.ext.dispatcher - ERROR - No error handlers are registered, logging exception.
Traceback (most recent call last):
  File "/home/ubuntu/.local/lib/python3.6/site-packages/telegram/ext/dispatcher.py", line 340, in process_update
    handler.handle_update(update, self, check, context)
  File "/home/ubuntu/.local/lib/python3.6/site-packages/telegram/ext/handler.py", line 119, in handle_update
    return self.callback(update, context)
  File "botik.py", line 67, in message_handler
    if random.random() < markov_chance/100 or update.message.reply_to_message.from_user.username == "puklengtime_bot":
AttributeError: 'NoneType' object has no attribute 'from_user'
telegram.ext.dispatcher - ERROR - No error handlers are registered, logging exception.
Traceback (most recent call last):
  File "/home/ubuntu/.local/lib/python3.6/site-packages/telegram/ext/dispatcher.py", line 340, in process_update
    handler.handle_update(update, self, check, context)
  File "/home/ubuntu/.local/lib/python3.6/site-packages/telegram/ext/handler.py", line 119, in handle_update
    return self.callback(update, context)
  File "botik.py", line 67, in message_handler
    if random.random() < markov_chance/100 or update.message.reply_to_message.from_user.username == "puklengtime_bot":
AttributeError: 'NoneType' object has no attribute 'from_user'
telegram.ext.dispatcher - ERROR - No error handlers are registered, logging exception.
Traceback (most recent call last):
  File "/home/ubuntu/.local/lib/python3.6/site-packages/telegram/ext/dispatcher.py", line 340, in process_update
    handler.handle_update(update, self, check, context)
  File "/home/ubuntu/.local/lib/python3.6/site-packages/telegram/ext/handler.py", line 119, in handle_update
    return self.callback(update, context)
  File "botik.py", line 67, in message_handler
    if random.random() < markov_chance/100 or update.message.reply_to_message.from_user.username == "puklengtime_bot":
AttributeError: 'NoneType' object has no attribute 'from_user'
telegram.ext.dispatcher - ERROR - No error handlers are registered, logging exception.
Traceback (most recent call last):
  File "/home/ubuntu/.local/lib/python3.6/site-packages/telegram/ext/dispatcher.py", line 340, in process_update
    handler.handle_update(update, self, check, context)
  File "/home/ubuntu/.local/lib/python3.6/site-packages/telegram/ext/handler.py", line 119, in handle_update
    return self.callback(update, context)
  File "botik.py", line 67, in message_handler
    if random.random() < markov_chance/100 or update.message.reply_to_message.from_user.username == "puklengtime_bot":
AttributeError: 'NoneType' object has no attribute 'from_user'
telegram.ext.dispatcher - ERROR - No error handlers are registered, logging exception.
Traceback (most recent call last):
  File "/home/ubuntu/.local/lib/python3.6/site-packages/telegram/ext/dispatcher.py", line 340, in process_update
    handler.handle_update(update, self, check, context)
  File "/home/ubuntu/.local/lib/python3.6/site-packages/telegram/ext/handler.py", line 119, in handle_update
    return self.callback(update, context)
  File "botik.py", line 67, in message_handler
    if random.random() < markov_chance/100 or update.message.reply_to_message.from_user.username == "puklengtime_bot":
AttributeError: 'NoneType' object has no attribute 'from_user'
telegram.ext.dispatcher - ERROR - No error handlers are registered, logging exception.
Traceback (most recent call last):
  File "/home/ubuntu/.local/lib/python3.6/site-packages/telegram/ext/dispatcher.py", line 340, in process_update
    handler.handle_update(update, self, check, context)
  File "/home/ubuntu/.local/lib/python3.6/site-packages/telegram/ext/handler.py", line 119, in handle_update
    return self.callback(update, context)
  File "botik.py", line 67, in message_handler
    if random.random() < markov_chance/100 or update.message.reply_to_message.from_user.username == "puklengtime_bot":
AttributeError: 'NoneType' object has no attribute 'from_user'
telegram.ext.dispatcher - ERROR - No error handlers are registered, logging exception.
Traceback (most recent call last):
  File "/home/ubuntu/.local/lib/python3.6/site-packages/telegram/ext/dispatcher.py", line 340, in process_update
    handler.handle_update(update, self, check, context)
  File "/home/ubuntu/.local/lib/python3.6/site-packages/telegram/ext/handler.py", line 119, in handle_update
    return self.callback(update, context)
  File "botik.py", line 67, in message_handler
    if random.random() < markov_chance/100 or update.message.reply_to_message.from_user.username == "puklengtime_bot":
AttributeError: 'NoneType' object has no attribute 'from_user'
telegram.ext.dispatcher - ERROR - No error handlers are registered, logging exception.
Traceback (most recent call last):
  File "/home/ubuntu/.local/lib/python3.6/site-packages/telegram/ext/dispatcher.py", line 340, in process_update
    handler.handle_update(update, self, check, context)
  File "/home/ubuntu/.local/lib/python3.6/site-packages/telegram/ext/handler.py", line 119, in handle_update
    return self.callback(update, context)
  File "botik.py", line 67, in message_handler
    if random.random() < markov_chance/100 or update.message.reply_to_message.from_user.username == "puklengtime_bot":
AttributeError: 'NoneType' object has no attribute 'from_user'
telegram.ext.dispatcher - ERROR - No error handlers are registered, logging exception.
Traceback (most recent call last):
  File "/home/ubuntu/.local/lib/python3.6/site-packages/telegram/ext/dispatcher.py", line 340, in process_update
    handler.handle_update(update, self, check, context)
  File "/home/ubuntu/.local/lib/python3.6/site-packages/telegram/ext/handler.py", line 119, in handle_update
    return self.callback(update, context)
  File "botik.py", line 67, in message_handler
    if random.random() < markov_chance/100 or update.message.reply_to_message.from_user.username == "puklengtime_bot":
AttributeError: 'NoneType' object has no attribute 'from_user'
telegram.ext.dispatcher - ERROR - No error handlers are registered, logging exception.
Traceback (most recent call last):
  File "/home/ubuntu/.local/lib/python3.6/site-packages/telegram/ext/dispatcher.py", line 340, in process_update
    handler.handle_update(update, self, check, context)
  File "/home/ubuntu/.local/lib/python3.6/site-packages/telegram/ext/handler.py", line 119, in handle_update
    return self.callback(update, context)
  File "botik.py", line 67, in message_handler
    if random.random() < markov_chance/100 or update.message.reply_to_message.from_user.username == "puklengtime_bot":
AttributeError: 'NoneType' object has no attribute 'from_user'
telegram.ext.dispatcher - ERROR - No error handlers are registered, logging exception.
Traceback (most recent call last):
  File "/home/ubuntu/.local/lib/python3.6/site-packages/telegram/ext/dispatcher.py", line 340, in process_update
    handler.handle_update(update, self, check, context)
  File "/home/ubuntu/.local/lib/python3.6/site-packages/telegram/ext/handler.py", line 119, in handle_update
    return self.callback(update, context)
  File "botik.py", line 67, in message_handler
    if random.random() < markov_chance/100 or update.message.reply_to_message.from_user.username == "puklengtime_bot":
AttributeError: 'NoneType' object has no attribute 'from_user'
telegram.ext.dispatcher - ERROR - No error handlers are registered, logging exception.
Traceback (most recent call last):
  File "/home/ubuntu/.local/lib/python3.6/site-packages/telegram/ext/dispatcher.py", line 340, in process_update
    handler.handle_update(update, self, check, context)
  File "/home/ubuntu/.local/lib/python3.6/site-packages/telegram/ext/handler.py", line 119, in handle_update
    return self.callback(update, context)
  File "botik.py", line 67, in message_handler
    if random.random() < markov_chance/100 or update.message.reply_to_message.from_user.username == "puklengtime_bot":
AttributeError: 'NoneType' object has no attribute 'from_user'
telegram.ext.dispatcher - ERROR - No error handlers are registered, logging exception.
Traceback (most recent call last):
  File "/home/ubuntu/.local/lib/python3.6/site-packages/telegram/ext/dispatcher.py", line 340, in process_update
    handler.handle_update(update, self, check, context)
  File "/home/ubuntu/.local/lib/python3.6/site-packages/telegram/ext/handler.py", line 119, in handle_update
    return self.callback(update, context)
  File "botik.py", line 67, in message_handler
    if random.random() < markov_chance/100 or update.message.reply_to_message.from_user.username == "puklengtime_bot":
AttributeError: 'NoneType' object has no attribute 'from_user'
telegram.ext.dispatcher - ERROR - No error handlers are registered, logging exception.
Traceback (most recent call last):
  File "/home/ubuntu/.local/lib/python3.6/site-packages/telegram/ext/dispatcher.py", line 340, in process_update
    handler.handle_update(update, self, check, context)
  File "/home/ubuntu/.local/lib/python3.6/site-packages/telegram/ext/handler.py", line 119, in handle_update
    return self.callback(update, context)
  File "botik.py", line 67, in message_handler
    if random.random() < markov_chance/100 or update.message.reply_to_message.from_user.username == "puklengtime_bot":
AttributeError: 'NoneType' object has no attribute 'from_user'
telegram.ext.dispatcher - ERROR - No error handlers are registered, logging exception.
Traceback (most recent call last):
  File "/home/ubuntu/.local/lib/python3.6/site-packages/telegram/ext/dispatcher.py", line 340, in process_update
    handler.handle_update(update, self, check, context)
  File "/home/ubuntu/.local/lib/python3.6/site-packages/telegram/ext/handler.py", line 119, in handle_update
    return self.callback(update, context)
  File "botik.py", line 67, in message_handler
    if random.random() < markov_chance/100 or update.message.reply_to_message.from_user.username == "puklengtime_bot":
AttributeError: 'NoneType' object has no attribute 'from_user'
telegram.ext.dispatcher - ERROR - No error handlers are registered, logging exception.
Traceback (most recent call last):
  File "/home/ubuntu/.local/lib/python3.6/site-packages/telegram/ext/dispatcher.py", line 340, in process_update
    handler.handle_update(update, self, check, context)
  File "/home/ubuntu/.local/lib/python3.6/site-packages/telegram/ext/handler.py", line 119, in handle_update
    return self.callback(update, context)
  File "botik.py", line 67, in message_handler
    if random.random() < markov_chance/100 or update.message.reply_to_message.from_user.username == "puklengtime_bot":
AttributeError: 'NoneType' object has no attribute 'from_user'
telegram.ext.dispatcher - ERROR - No error handlers are registered, logging exception.
Traceback (most recent call last):
  File "/home/ubuntu/.local/lib/python3.6/site-packages/telegram/ext/dispatcher.py", line 340, in process_update
    handler.handle_update(update, self, check, context)
  File "/home/ubuntu/.local/lib/python3.6/site-packages/telegram/ext/handler.py", line 119, in handle_update
    return self.callback(update, context)
  File "botik.py", line 67, in message_handler
    if random.random() < markov_chance/100 or update.message.reply_to_message.from_user.username == "puklengtime_bot":
AttributeError: 'NoneType' object has no attribute 'from_user'
telegram.ext.dispatcher - ERROR - No error handlers are registered, logging exception.
Traceback (most recent call last):
  File "/home/ubuntu/.local/lib/python3.6/site-packages/telegram/ext/dispatcher.py", line 340, in process_update
    handler.handle_update(update, self, check, context)
  File "/home/ubuntu/.local/lib/python3.6/site-packages/telegram/ext/handler.py", line 119, in handle_update
    return self.callback(update, context)
  File "botik.py", line 67, in message_handler
    if random.random() < markov_chance/100 or update.message.reply_to_message.from_user.username == "puklengtime_bot":
AttributeError: 'NoneType' object has no attribute 'from_user'
telegram.ext.dispatcher - ERROR - No error handlers are registered, logging exception.
Traceback (most recent call last):
  File "/home/ubuntu/.local/lib/python3.6/site-packages/telegram/ext/dispatcher.py", line 340, in process_update
    handler.handle_update(update, self, check, context)
  File "/home/ubuntu/.local/lib/python3.6/site-packages/telegram/ext/handler.py", line 119, in handle_update
    return self.callback(update, context)
  File "botik.py", line 67, in message_handler
    if random.random() < markov_chance/100 or update.message.reply_to_message.from_user.username == "puklengtime_bot":
AttributeError: 'NoneType' object has no attribute 'from_user'
telegram.ext.dispatcher - ERROR - No error handlers are registered, logging exception.
Traceback (most recent call last):
  File "/home/ubuntu/.local/lib/python3.6/site-packages/telegram/ext/dispatcher.py", line 340, in process_update
    handler.handle_update(update, self, check, context)
  File "/home/ubuntu/.local/lib/python3.6/site-packages/telegram/ext/handler.py", line 119, in handle_update
    return self.callback(update, context)
  File "botik.py", line 67, in message_handler
    if random.random() < markov_chance/100 or update.message.reply_to_message.from_user.username == "puklengtime_bot":
AttributeError: 'NoneType' object has no attribute 'from_user'
telegram.ext.dispatcher - ERROR - No error handlers are registered, logging exception.
Traceback (most recent call last):
  File "/home/ubuntu/.local/lib/python3.6/site-packages/telegram/ext/dispatcher.py", line 340, in process_update
    handler.handle_update(update, self, check, context)
  File "/home/ubuntu/.local/lib/python3.6/site-packages/telegram/ext/handler.py", line 119, in handle_update
    return self.callback(update, context)
  File "botik.py", line 67, in message_handler
    if random.random() < markov_chance/100 or update.message.reply_to_message.from_user.username == "puklengtime_bot":
AttributeError: 'NoneType' object has no attribute 'from_user'
telegram.ext.dispatcher - ERROR - No error handlers are registered, logging exception.
Traceback (most recent call last):
  File "/home/ubuntu/.local/lib/python3.6/site-packages/telegram/ext/dispatcher.py", line 340, in process_update
    handler.handle_update(update, self, check, context)
  File "/home/ubuntu/.local/lib/python3.6/site-packages/telegram/ext/handler.py", line 119, in handle_update
    return self.callback(update, context)
  File "botik.py", line 67, in message_handler
    if random.random() < markov_chance/100 or update.message.reply_to_message.from_user.username == "puklengtime_bot":
AttributeError: 'NoneType' object has no attribute 'from_user'
telegram.ext.dispatcher - ERROR - No error handlers are registered, logging exception.
Traceback (most recent call last):
  File "/home/ubuntu/.local/lib/python3.6/site-packages/telegram/ext/dispatcher.py", line 340, in process_update
    handler.handle_update(update, self, check, context)
  File "/home/ubuntu/.local/lib/python3.6/site-packages/telegram/ext/handler.py", line 119, in handle_update
    return self.callback(update, context)
  File "botik.py", line 67, in message_handler
    if random.random() < markov_chance/100 or update.message.reply_to_message.from_user.username == "puklengtime_bot":
AttributeError: 'NoneType' object has no attribute 'from_user'
telegram.ext.dispatcher - ERROR - No error handlers are registered, logging exception.
Traceback (most recent call last):
  File "/home/ubuntu/.local/lib/python3.6/site-packages/telegram/ext/dispatcher.py", line 340, in process_update
    handler.handle_update(update, self, check, context)
  File "/home/ubuntu/.local/lib/python3.6/site-packages/telegram/ext/handler.py", line 119, in handle_update
    return self.callback(update, context)
  File "botik.py", line 67, in message_handler
    if random.random() < markov_chance/100 or update.message.reply_to_message.from_user.username == "puklengtime_bot":
AttributeError: 'NoneType' object has no attribute 'from_user'
telegram.ext.dispatcher - ERROR - No error handlers are registered, logging exception.
Traceback (most recent call last):
  File "/home/ubuntu/.local/lib/python3.6/site-packages/telegram/ext/dispatcher.py", line 340, in process_update
    handler.handle_update(update, self, check, context)
  File "/home/ubuntu/.local/lib/python3.6/site-packages/telegram/ext/handler.py", line 119, in handle_update
    return self.callback(update, context)
  File "botik.py", line 67, in message_handler
    if random.random() < markov_chance/100 or update.message.reply_to_message.from_user.username == "puklengtime_bot":
AttributeError: 'NoneType' object has no attribute 'from_user'
telegram.ext.dispatcher - ERROR - No error handlers are registered, logging exception.
Traceback (most recent call last):
  File "/home/ubuntu/.local/lib/python3.6/site-packages/telegram/ext/dispatcher.py", line 340, in process_update
    handler.handle_update(update, self, check, context)
  File "/home/ubuntu/.local/lib/python3.6/site-packages/telegram/ext/handler.py", line 119, in handle_update
    return self.callback(update, context)
  File "botik.py", line 67, in message_handler
    if random.random() < markov_chance/100 or update.message.reply_to_message.from_user.username == "puklengtime_bot":
AttributeError: 'NoneType' object has no attribute 'from_user'
telegram.ext.dispatcher - ERROR - No error handlers are registered, logging exception.
Traceback (most recent call last):
  File "/home/ubuntu/.local/lib/python3.6/site-packages/telegram/ext/dispatcher.py", line 340, in process_update
    handler.handle_update(update, self, check, context)
  File "/home/ubuntu/.local/lib/python3.6/site-packages/telegram/ext/handler.py", line 119, in handle_update
    return self.callback(update, context)
  File "botik.py", line 67, in message_handler
    if random.random() < markov_chance/100 or update.message.reply_to_message.from_user.username == "puklengtime_bot":
AttributeError: 'NoneType' object has no attribute 'from_user'
telegram.ext.dispatcher - ERROR - No error handlers are registered, logging exception.
Traceback (most recent call last):
  File "/home/ubuntu/.local/lib/python3.6/site-packages/telegram/ext/dispatcher.py", line 340, in process_update
    handler.handle_update(update, self, check, context)
  File "/home/ubuntu/.local/lib/python3.6/site-packages/telegram/ext/handler.py", line 119, in handle_update
    return self.callback(update, context)
  File "botik.py", line 67, in message_handler
    if random.random() < markov_chance/100 or update.message.reply_to_message.from_user.username == "puklengtime_bot":
AttributeError: 'NoneType' object has no attribute 'from_user'
telegram.ext.dispatcher - ERROR - No error handlers are registered, logging exception.
Traceback (most recent call last):
  File "/home/ubuntu/.local/lib/python3.6/site-packages/telegram/ext/dispatcher.py", line 340, in process_update
    handler.handle_update(update, self, check, context)
  File "/home/ubuntu/.local/lib/python3.6/site-packages/telegram/ext/handler.py", line 119, in handle_update
    return self.callback(update, context)
  File "botik.py", line 67, in message_handler
    if random.random() < markov_chance/100 or update.message.reply_to_message.from_user.username == "puklengtime_bot":
AttributeError: 'NoneType' object has no attribute 'from_user'
telegram.ext.dispatcher - ERROR - No error handlers are registered, logging exception.
Traceback (most recent call last):
  File "/home/ubuntu/.local/lib/python3.6/site-packages/telegram/ext/dispatcher.py", line 340, in process_update
    handler.handle_update(update, self, check, context)
  File "/home/ubuntu/.local/lib/python3.6/site-packages/telegram/ext/handler.py", line 119, in handle_update
    return self.callback(update, context)
  File "botik.py", line 67, in message_handler
    if random.random() < markov_chance/100 or update.message.reply_to_message.from_user.username == "puklengtime_bot":
AttributeError: 'NoneType' object has no attribute 'from_user'
telegram.ext.dispatcher - ERROR - No error handlers are registered, logging exception.
Traceback (most recent call last):
  File "/home/ubuntu/.local/lib/python3.6/site-packages/telegram/ext/dispatcher.py", line 340, in process_update
    handler.handle_update(update, self, check, context)
  File "/home/ubuntu/.local/lib/python3.6/site-packages/telegram/ext/handler.py", line 119, in handle_update
    return self.callback(update, context)
  File "botik.py", line 67, in message_handler
    if random.random() < markov_chance/100 or update.message.reply_to_message.from_user.username == "puklengtime_bot":
AttributeError: 'NoneType' object has no attribute 'from_user'
telegram.ext.dispatcher - ERROR - No error handlers are registered, logging exception.
Traceback (most recent call last):
  File "/home/ubuntu/.local/lib/python3.6/site-packages/telegram/ext/dispatcher.py", line 340, in process_update
    handler.handle_update(update, self, check, context)
  File "/home/ubuntu/.local/lib/python3.6/site-packages/telegram/ext/handler.py", line 119, in handle_update
    return self.callback(update, context)
  File "botik.py", line 67, in message_handler
    if random.random() < markov_chance/100 or update.message.reply_to_message.from_user.username == "puklengtime_bot":
AttributeError: 'NoneType' object has no attribute 'from_user'
telegram.ext.dispatcher - ERROR - No error handlers are registered, logging exception.
Traceback (most recent call last):
  File "/home/ubuntu/.local/lib/python3.6/site-packages/telegram/ext/dispatcher.py", line 340, in process_update
    handler.handle_update(update, self, check, context)
  File "/home/ubuntu/.local/lib/python3.6/site-packages/telegram/ext/handler.py", line 119, in handle_update
    return self.callback(update, context)
  File "botik.py", line 67, in message_handler
    if random.random() < markov_chance/100 or update.message.reply_to_message.from_user.username == "puklengtime_bot":
AttributeError: 'NoneType' object has no attribute 'from_user'
telegram.ext.dispatcher - ERROR - No error handlers are registered, logging exception.
Traceback (most recent call last):
  File "/home/ubuntu/.local/lib/python3.6/site-packages/telegram/ext/dispatcher.py", line 340, in process_update
    handler.handle_update(update, self, check, context)
  File "/home/ubuntu/.local/lib/python3.6/site-packages/telegram/ext/handler.py", line 119, in handle_update
    return self.callback(update, context)
  File "botik.py", line 67, in message_handler
    if random.random() < markov_chance/100 or update.message.reply_to_message.from_user.username == "puklengtime_bot":
AttributeError: 'NoneType' object has no attribute 'from_user'
telegram.ext.dispatcher - ERROR - No error handlers are registered, logging exception.
Traceback (most recent call last):
  File "/home/ubuntu/.local/lib/python3.6/site-packages/telegram/ext/dispatcher.py", line 340, in process_update
    handler.handle_update(update, self, check, context)
  File "/home/ubuntu/.local/lib/python3.6/site-packages/telegram/ext/handler.py", line 119, in handle_update
    return self.callback(update, context)
  File "botik.py", line 67, in message_handler
    if random.random() < markov_chance/100 or update.message.reply_to_message.from_user.username == "puklengtime_bot":
AttributeError: 'NoneType' object has no attribute 'from_user'
telegram.ext.dispatcher - ERROR - No error handlers are registered, logging exception.
Traceback (most recent call last):
  File "/home/ubuntu/.local/lib/python3.6/site-packages/telegram/ext/dispatcher.py", line 340, in process_update
    handler.handle_update(update, self, check, context)
  File "/home/ubuntu/.local/lib/python3.6/site-packages/telegram/ext/handler.py", line 119, in handle_update
    return self.callback(update, context)
  File "botik.py", line 67, in message_handler
    if random.random() < markov_chance/100 or update.message.reply_to_message.from_user.username == "puklengtime_bot":
AttributeError: 'NoneType' object has no attribute 'from_user'
telegram.ext.dispatcher - ERROR - No error handlers are registered, logging exception.
Traceback (most recent call last):
  File "/home/ubuntu/.local/lib/python3.6/site-packages/telegram/ext/dispatcher.py", line 340, in process_update
    handler.handle_update(update, self, check, context)
  File "/home/ubuntu/.local/lib/python3.6/site-packages/telegram/ext/handler.py", line 119, in handle_update
    return self.callback(update, context)
  File "botik.py", line 67, in message_handler
    if random.random() < markov_chance/100 or update.message.reply_to_message.from_user.username == "puklengtime_bot":
AttributeError: 'NoneType' object has no attribute 'from_user'
telegram.ext.dispatcher - ERROR - No error handlers are registered, logging exception.
Traceback (most recent call last):
  File "/home/ubuntu/.local/lib/python3.6/site-packages/telegram/ext/dispatcher.py", line 340, in process_update
    handler.handle_update(update, self, check, context)
  File "/home/ubuntu/.local/lib/python3.6/site-packages/telegram/ext/handler.py", line 119, in handle_update
    return self.callback(update, context)
  File "botik.py", line 67, in message_handler
    if random.random() < markov_chance/100 or update.message.reply_to_message.from_user.username == "puklengtime_bot":
AttributeError: 'NoneType' object has no attribute 'from_user'
telegram.ext.dispatcher - ERROR - No error handlers are registered, logging exception.
Traceback (most recent call last):
  File "/home/ubuntu/.local/lib/python3.6/site-packages/telegram/ext/dispatcher.py", line 340, in process_update
    handler.handle_update(update, self, check, context)
  File "/home/ubuntu/.local/lib/python3.6/site-packages/telegram/ext/handler.py", line 119, in handle_update
    return self.callback(update, context)
  File "botik.py", line 67, in message_handler
    if random.random() < markov_chance/100 or update.message.reply_to_message.from_user.username == "puklengtime_bot":
AttributeError: 'NoneType' object has no attribute 'from_user'
telegram.ext.dispatcher - ERROR - No error handlers are registered, logging exception.
Traceback (most recent call last):
  File "/home/ubuntu/.local/lib/python3.6/site-packages/telegram/ext/dispatcher.py", line 340, in process_update
    handler.handle_update(update, self, check, context)
  File "/home/ubuntu/.local/lib/python3.6/site-packages/telegram/ext/handler.py", line 119, in handle_update
    return self.callback(update, context)
  File "botik.py", line 67, in message_handler
    if random.random() < markov_chance/100 or update.message.reply_to_message.from_user.username == "puklengtime_bot":
AttributeError: 'NoneType' object has no attribute 'from_user'
telegram.ext.dispatcher - ERROR - No error handlers are registered, logging exception.
Traceback (most recent call last):
  File "/home/ubuntu/.local/lib/python3.6/site-packages/telegram/ext/dispatcher.py", line 340, in process_update
    handler.handle_update(update, self, check, context)
  File "/home/ubuntu/.local/lib/python3.6/site-packages/telegram/ext/handler.py", line 119, in handle_update
    return self.callback(update, context)
  File "botik.py", line 67, in message_handler
    if random.random() < markov_chance/100 or update.message.reply_to_message.from_user.username == "puklengtime_bot":
AttributeError: 'NoneType' object has no attribute 'from_user'
telegram.ext.dispatcher - ERROR - No error handlers are registered, logging exception.
Traceback (most recent call last):
  File "/home/ubuntu/.local/lib/python3.6/site-packages/telegram/ext/dispatcher.py", line 340, in process_update
    handler.handle_update(update, self, check, context)
  File "/home/ubuntu/.local/lib/python3.6/site-packages/telegram/ext/handler.py", line 119, in handle_update
    return self.callback(update, context)
  File "botik.py", line 67, in message_handler
    if random.random() < markov_chance/100 or update.message.reply_to_message.from_user.username == "puklengtime_bot":
AttributeError: 'NoneType' object has no attribute 'from_user'
telegram.ext.dispatcher - ERROR - No error handlers are registered, logging exception.
Traceback (most recent call last):
  File "/home/ubuntu/.local/lib/python3.6/site-packages/telegram/ext/dispatcher.py", line 340, in process_update
    handler.handle_update(update, self, check, context)
  File "/home/ubuntu/.local/lib/python3.6/site-packages/telegram/ext/handler.py", line 119, in handle_update
    return self.callback(update, context)
  File "botik.py", line 67, in message_handler
    if random.random() < markov_chance/100 or update.message.reply_to_message.from_user.username == "puklengtime_bot":
AttributeError: 'NoneType' object has no attribute 'from_user'
telegram.ext.dispatcher - ERROR - No error handlers are registered, logging exception.
Traceback (most recent call last):
  File "/home/ubuntu/.local/lib/python3.6/site-packages/telegram/ext/dispatcher.py", line 340, in process_update
    handler.handle_update(update, self, check, context)
  File "/home/ubuntu/.local/lib/python3.6/site-packages/telegram/ext/handler.py", line 119, in handle_update
    return self.callback(update, context)
  File "botik.py", line 67, in message_handler
    if random.random() < markov_chance/100 or update.message.reply_to_message.from_user.username == "puklengtime_bot":
AttributeError: 'NoneType' object has no attribute 'from_user'
telegram.ext.dispatcher - ERROR - No error handlers are registered, logging exception.
Traceback (most recent call last):
  File "/home/ubuntu/.local/lib/python3.6/site-packages/telegram/ext/dispatcher.py", line 340, in process_update
    handler.handle_update(update, self, check, context)
  File "/home/ubuntu/.local/lib/python3.6/site-packages/telegram/ext/handler.py", line 119, in handle_update
    return self.callback(update, context)
  File "botik.py", line 67, in message_handler
    if random.random() < markov_chance/100 or update.message.reply_to_message.from_user.username == "puklengtime_bot":
AttributeError: 'NoneType' object has no attribute 'from_user'
telegram.ext.dispatcher - ERROR - No error handlers are registered, logging exception.
Traceback (most recent call last):
  File "/home/ubuntu/.local/lib/python3.6/site-packages/telegram/ext/dispatcher.py", line 340, in process_update
    handler.handle_update(update, self, check, context)
  File "/home/ubuntu/.local/lib/python3.6/site-packages/telegram/ext/handler.py", line 119, in handle_update
    return self.callback(update, context)
  File "botik.py", line 67, in message_handler
    if random.random() < markov_chance/100 or update.message.reply_to_message.from_user.username == "puklengtime_bot":
AttributeError: 'NoneType' object has no attribute 'from_user'
telegram.ext.dispatcher - ERROR - No error handlers are registered, logging exception.
Traceback (most recent call last):
  File "/home/ubuntu/.local/lib/python3.6/site-packages/telegram/ext/dispatcher.py", line 340, in process_update
    handler.handle_update(update, self, check, context)
  File "/home/ubuntu/.local/lib/python3.6/site-packages/telegram/ext/handler.py", line 119, in handle_update
    return self.callback(update, context)
  File "botik.py", line 67, in message_handler
    if random.random() < markov_chance/100 or update.message.reply_to_message.from_user.username == "puklengtime_bot":
AttributeError: 'NoneType' object has no attribute 'from_user'
telegram.ext.dispatcher - ERROR - No error handlers are registered, logging exception.
Traceback (most recent call last):
  File "/home/ubuntu/.local/lib/python3.6/site-packages/telegram/ext/dispatcher.py", line 340, in process_update
    handler.handle_update(update, self, check, context)
  File "/home/ubuntu/.local/lib/python3.6/site-packages/telegram/ext/handler.py", line 119, in handle_update
    return self.callback(update, context)
  File "botik.py", line 67, in message_handler
    if random.random() < markov_chance/100 or update.message.reply_to_message.from_user.username == "puklengtime_bot":
AttributeError: 'NoneType' object has no attribute 'from_user'
telegram.ext.dispatcher - ERROR - No error handlers are registered, logging exception.
Traceback (most recent call last):
  File "/home/ubuntu/.local/lib/python3.6/site-packages/telegram/ext/dispatcher.py", line 340, in process_update
    handler.handle_update(update, self, check, context)
  File "/home/ubuntu/.local/lib/python3.6/site-packages/telegram/ext/handler.py", line 119, in handle_update
    return self.callback(update, context)
  File "botik.py", line 67, in message_handler
    if random.random() < markov_chance/100 or update.message.reply_to_message.from_user.username == "puklengtime_bot":
AttributeError: 'NoneType' object has no attribute 'from_user'
telegram.ext.dispatcher - ERROR - No error handlers are registered, logging exception.
Traceback (most recent call last):
  File "/home/ubuntu/.local/lib/python3.6/site-packages/telegram/ext/dispatcher.py", line 340, in process_update
    handler.handle_update(update, self, check, context)
  File "/home/ubuntu/.local/lib/python3.6/site-packages/telegram/ext/handler.py", line 119, in handle_update
    return self.callback(update, context)
  File "botik.py", line 67, in message_handler
    if random.random() < markov_chance/100 or update.message.reply_to_message.from_user.username == "puklengtime_bot":
AttributeError: 'NoneType' object has no attribute 'from_user'
telegram.ext.dispatcher - ERROR - No error handlers are registered, logging exception.
Traceback (most recent call last):
  File "/home/ubuntu/.local/lib/python3.6/site-packages/telegram/ext/dispatcher.py", line 340, in process_update
    handler.handle_update(update, self, check, context)
  File "/home/ubuntu/.local/lib/python3.6/site-packages/telegram/ext/handler.py", line 119, in handle_update
    return self.callback(update, context)
  File "botik.py", line 67, in message_handler
    if random.random() < markov_chance/100 or update.message.reply_to_message.from_user.username == "puklengtime_bot":
AttributeError: 'NoneType' object has no attribute 'from_user'
telegram.ext.dispatcher - ERROR - No error handlers are registered, logging exception.
Traceback (most recent call last):
  File "/home/ubuntu/.local/lib/python3.6/site-packages/telegram/ext/dispatcher.py", line 340, in process_update
    handler.handle_update(update, self, check, context)
  File "/home/ubuntu/.local/lib/python3.6/site-packages/telegram/ext/handler.py", line 119, in handle_update
    return self.callback(update, context)
  File "botik.py", line 67, in message_handler
    if random.random() < markov_chance/100 or update.message.reply_to_message.from_user.username == "puklengtime_bot":
AttributeError: 'NoneType' object has no attribute 'from_user'
telegram.ext.dispatcher - ERROR - No error handlers are registered, logging exception.
Traceback (most recent call last):
  File "/home/ubuntu/.local/lib/python3.6/site-packages/telegram/ext/dispatcher.py", line 340, in process_update
    handler.handle_update(update, self, check, context)
  File "/home/ubuntu/.local/lib/python3.6/site-packages/telegram/ext/handler.py", line 119, in handle_update
    return self.callback(update, context)
  File "botik.py", line 67, in message_handler
    if random.random() < markov_chance/100 or update.message.reply_to_message.from_user.username == "puklengtime_bot":
AttributeError: 'NoneType' object has no attribute 'from_user'
telegram.ext.dispatcher - ERROR - No error handlers are registered, logging exception.
Traceback (most recent call last):
  File "/home/ubuntu/.local/lib/python3.6/site-packages/telegram/ext/dispatcher.py", line 340, in process_update
    handler.handle_update(update, self, check, context)
  File "/home/ubuntu/.local/lib/python3.6/site-packages/telegram/ext/handler.py", line 119, in handle_update
    return self.callback(update, context)
  File "botik.py", line 67, in message_handler
    if random.random() < markov_chance/100 or update.message.reply_to_message.from_user.username == "puklengtime_bot":
AttributeError: 'NoneType' object has no attribute 'from_user'
telegram.ext.dispatcher - ERROR - No error handlers are registered, logging exception.
Traceback (most recent call last):
  File "/home/ubuntu/.local/lib/python3.6/site-packages/telegram/ext/dispatcher.py", line 340, in process_update
    handler.handle_update(update, self, check, context)
  File "/home/ubuntu/.local/lib/python3.6/site-packages/telegram/ext/handler.py", line 119, in handle_update
    return self.callback(update, context)
  File "botik.py", line 67, in message_handler
    if random.random() < markov_chance/100 or update.message.reply_to_message.from_user.username == "puklengtime_bot":
AttributeError: 'NoneType' object has no attribute 'from_user'
telegram.ext.dispatcher - ERROR - No error handlers are registered, logging exception.
Traceback (most recent call last):
  File "/home/ubuntu/.local/lib/python3.6/site-packages/telegram/ext/dispatcher.py", line 340, in process_update
    handler.handle_update(update, self, check, context)
  File "/home/ubuntu/.local/lib/python3.6/site-packages/telegram/ext/handler.py", line 119, in handle_update
    return self.callback(update, context)
  File "botik.py", line 67, in message_handler
    if random.random() < markov_chance/100 or update.message.reply_to_message.from_user.username == "puklengtime_bot":
AttributeError: 'NoneType' object has no attribute 'from_user'
telegram.ext.dispatcher - ERROR - No error handlers are registered, logging exception.
Traceback (most recent call last):
  File "/home/ubuntu/.local/lib/python3.6/site-packages/telegram/ext/dispatcher.py", line 340, in process_update
    handler.handle_update(update, self, check, context)
  File "/home/ubuntu/.local/lib/python3.6/site-packages/telegram/ext/handler.py", line 119, in handle_update
    return self.callback(update, context)
  File "botik.py", line 67, in message_handler
    if random.random() < markov_chance/100 or update.message.reply_to_message.from_user.username == "puklengtime_bot":
AttributeError: 'NoneType' object has no attribute 'from_user'
telegram.ext.dispatcher - ERROR - No error handlers are registered, logging exception.
Traceback (most recent call last):
  File "/home/ubuntu/.local/lib/python3.6/site-packages/telegram/ext/dispatcher.py", line 340, in process_update
    handler.handle_update(update, self, check, context)
  File "/home/ubuntu/.local/lib/python3.6/site-packages/telegram/ext/handler.py", line 119, in handle_update
    return self.callback(update, context)
  File "botik.py", line 67, in message_handler
    if random.random() < markov_chance/100 or update.message.reply_to_message.from_user.username == "puklengtime_bot":
AttributeError: 'NoneType' object has no attribute 'from_user'
telegram.ext.dispatcher - ERROR - No error handlers are registered, logging exception.
Traceback (most recent call last):
  File "/home/ubuntu/.local/lib/python3.6/site-packages/telegram/ext/dispatcher.py", line 340, in process_update
    handler.handle_update(update, self, check, context)
  File "/home/ubuntu/.local/lib/python3.6/site-packages/telegram/ext/handler.py", line 119, in handle_update
    return self.callback(update, context)
  File "botik.py", line 67, in message_handler
    if random.random() < markov_chance/100 or update.message.reply_to_message.from_user.username == "puklengtime_bot":
AttributeError: 'NoneType' object has no attribute 'from_user'
telegram.ext.dispatcher - ERROR - No error handlers are registered, logging exception.
Traceback (most recent call last):
  File "/home/ubuntu/.local/lib/python3.6/site-packages/telegram/ext/dispatcher.py", line 340, in process_update
    handler.handle_update(update, self, check, context)
  File "/home/ubuntu/.local/lib/python3.6/site-packages/telegram/ext/handler.py", line 119, in handle_update
    return self.callback(update, context)
  File "botik.py", line 67, in message_handler
    if random.random() < markov_chance/100 or update.message.reply_to_message.from_user.username == "puklengtime_bot":
AttributeError: 'NoneType' object has no attribute 'from_user'
telegram.ext.dispatcher - ERROR - No error handlers are registered, logging exception.
Traceback (most recent call last):
  File "/home/ubuntu/.local/lib/python3.6/site-packages/telegram/ext/dispatcher.py", line 340, in process_update
    handler.handle_update(update, self, check, context)
  File "/home/ubuntu/.local/lib/python3.6/site-packages/telegram/ext/handler.py", line 119, in handle_update
    return self.callback(update, context)
  File "botik.py", line 67, in message_handler
    if random.random() < markov_chance/100 or update.message.reply_to_message.from_user.username == "puklengtime_bot":
AttributeError: 'NoneType' object has no attribute 'from_user'
telegram.ext.dispatcher - ERROR - No error handlers are registered, logging exception.
Traceback (most recent call last):
  File "/home/ubuntu/.local/lib/python3.6/site-packages/telegram/ext/dispatcher.py", line 340, in process_update
    handler.handle_update(update, self, check, context)
  File "/home/ubuntu/.local/lib/python3.6/site-packages/telegram/ext/handler.py", line 119, in handle_update
    return self.callback(update, context)
  File "botik.py", line 67, in message_handler
    if random.random() < markov_chance/100 or update.message.reply_to_message.from_user.username == "puklengtime_bot":
AttributeError: 'NoneType' object has no attribute 'from_user'
telegram.ext.dispatcher - ERROR - No error handlers are registered, logging exception.
Traceback (most recent call last):
  File "/home/ubuntu/.local/lib/python3.6/site-packages/telegram/ext/dispatcher.py", line 340, in process_update
    handler.handle_update(update, self, check, context)
  File "/home/ubuntu/.local/lib/python3.6/site-packages/telegram/ext/handler.py", line 119, in handle_update
    return self.callback(update, context)
  File "botik.py", line 67, in message_handler
    if random.random() < markov_chance/100 or update.message.reply_to_message.from_user.username == "puklengtime_bot":
AttributeError: 'NoneType' object has no attribute 'from_user'
telegram.ext.dispatcher - ERROR - No error handlers are registered, logging exception.
Traceback (most recent call last):
  File "/home/ubuntu/.local/lib/python3.6/site-packages/telegram/ext/dispatcher.py", line 340, in process_update
    handler.handle_update(update, self, check, context)
  File "/home/ubuntu/.local/lib/python3.6/site-packages/telegram/ext/handler.py", line 119, in handle_update
    return self.callback(update, context)
  File "botik.py", line 67, in message_handler
    if random.random() < markov_chance/100 or update.message.reply_to_message.from_user.username == "puklengtime_bot":
AttributeError: 'NoneType' object has no attribute 'from_user'
telegram.ext.dispatcher - ERROR - No error handlers are registered, logging exception.
Traceback (most recent call last):
  File "/home/ubuntu/.local/lib/python3.6/site-packages/telegram/ext/dispatcher.py", line 340, in process_update
    handler.handle_update(update, self, check, context)
  File "/home/ubuntu/.local/lib/python3.6/site-packages/telegram/ext/handler.py", line 119, in handle_update
    return self.callback(update, context)
  File "botik.py", line 67, in message_handler
    if random.random() < markov_chance/100 or update.message.reply_to_message.from_user.username == "puklengtime_bot":
AttributeError: 'NoneType' object has no attribute 'from_user'
telegram.ext.dispatcher - ERROR - No error handlers are registered, logging exception.
Traceback (most recent call last):
  File "/home/ubuntu/.local/lib/python3.6/site-packages/telegram/ext/dispatcher.py", line 340, in process_update
    handler.handle_update(update, self, check, context)
  File "/home/ubuntu/.local/lib/python3.6/site-packages/telegram/ext/handler.py", line 119, in handle_update
    return self.callback(update, context)
  File "botik.py", line 67, in message_handler
    if random.random() < markov_chance/100 or update.message.reply_to_message.from_user.username == "puklengtime_bot":
AttributeError: 'NoneType' object has no attribute 'from_user'
telegram.ext.dispatcher - ERROR - No error handlers are registered, logging exception.
Traceback (most recent call last):
  File "/home/ubuntu/.local/lib/python3.6/site-packages/telegram/ext/dispatcher.py", line 340, in process_update
    handler.handle_update(update, self, check, context)
  File "/home/ubuntu/.local/lib/python3.6/site-packages/telegram/ext/handler.py", line 119, in handle_update
    return self.callback(update, context)
  File "botik.py", line 67, in message_handler
    if random.random() < markov_chance/100 or update.message.reply_to_message.from_user.username == "puklengtime_bot":
AttributeError: 'NoneType' object has no attribute 'from_user'
telegram.ext.dispatcher - ERROR - No error handlers are registered, logging exception.
Traceback (most recent call last):
  File "/home/ubuntu/.local/lib/python3.6/site-packages/telegram/ext/dispatcher.py", line 340, in process_update
    handler.handle_update(update, self, check, context)
  File "/home/ubuntu/.local/lib/python3.6/site-packages/telegram/ext/handler.py", line 119, in handle_update
    return self.callback(update, context)
  File "botik.py", line 67, in message_handler
    if random.random() < markov_chance/100 or update.message.reply_to_message.from_user.username == "puklengtime_bot":
AttributeError: 'NoneType' object has no attribute 'from_user'
telegram.ext.dispatcher - ERROR - No error handlers are registered, logging exception.
Traceback (most recent call last):
  File "/home/ubuntu/.local/lib/python3.6/site-packages/telegram/ext/dispatcher.py", line 340, in process_update
    handler.handle_update(update, self, check, context)
  File "/home/ubuntu/.local/lib/python3.6/site-packages/telegram/ext/handler.py", line 119, in handle_update
    return self.callback(update, context)
  File "botik.py", line 67, in message_handler
    if random.random() < markov_chance/100 or update.message.reply_to_message.from_user.username == "puklengtime_bot":
AttributeError: 'NoneType' object has no attribute 'from_user'
telegram.ext.dispatcher - ERROR - No error handlers are registered, logging exception.
Traceback (most recent call last):
  File "/home/ubuntu/.local/lib/python3.6/site-packages/telegram/ext/dispatcher.py", line 340, in process_update
    handler.handle_update(update, self, check, context)
  File "/home/ubuntu/.local/lib/python3.6/site-packages/telegram/ext/handler.py", line 119, in handle_update
    return self.callback(update, context)
  File "botik.py", line 67, in message_handler
    if random.random() < markov_chance/100 or update.message.reply_to_message.from_user.username == "puklengtime_bot":
AttributeError: 'NoneType' object has no attribute 'from_user'
telegram.ext.dispatcher - ERROR - No error handlers are registered, logging exception.
Traceback (most recent call last):
  File "/home/ubuntu/.local/lib/python3.6/site-packages/telegram/ext/dispatcher.py", line 340, in process_update
    handler.handle_update(update, self, check, context)
  File "/home/ubuntu/.local/lib/python3.6/site-packages/telegram/ext/handler.py", line 119, in handle_update
    return self.callback(update, context)
  File "botik.py", line 67, in message_handler
    if random.random() < markov_chance/100 or update.message.reply_to_message.from_user.username == "puklengtime_bot":
AttributeError: 'NoneType' object has no attribute 'from_user'
telegram.ext.dispatcher - ERROR - No error handlers are registered, logging exception.
Traceback (most recent call last):
  File "/home/ubuntu/.local/lib/python3.6/site-packages/telegram/ext/dispatcher.py", line 340, in process_update
    handler.handle_update(update, self, check, context)
  File "/home/ubuntu/.local/lib/python3.6/site-packages/telegram/ext/handler.py", line 119, in handle_update
    return self.callback(update, context)
  File "botik.py", line 67, in message_handler
    if random.random() < markov_chance/100 or update.message.reply_to_message.from_user.username == "puklengtime_bot":
AttributeError: 'NoneType' object has no attribute 'from_user'
telegram.ext.dispatcher - ERROR - No error handlers are registered, logging exception.
Traceback (most recent call last):
  File "/home/ubuntu/.local/lib/python3.6/site-packages/telegram/ext/dispatcher.py", line 340, in process_update
    handler.handle_update(update, self, check, context)
  File "/home/ubuntu/.local/lib/python3.6/site-packages/telegram/ext/handler.py", line 119, in handle_update
    return self.callback(update, context)
  File "botik.py", line 67, in message_handler
    if random.random() < markov_chance/100 or update.message.reply_to_message.from_user.username == "puklengtime_bot":
AttributeError: 'NoneType' object has no attribute 'from_user'
telegram.ext.dispatcher - ERROR - No error handlers are registered, logging exception.
Traceback (most recent call last):
  File "/home/ubuntu/.local/lib/python3.6/site-packages/telegram/ext/dispatcher.py", line 340, in process_update
    handler.handle_update(update, self, check, context)
  File "/home/ubuntu/.local/lib/python3.6/site-packages/telegram/ext/handler.py", line 119, in handle_update
    return self.callback(update, context)
  File "botik.py", line 67, in message_handler
    if random.random() < markov_chance/100 or update.message.reply_to_message.from_user.username == "puklengtime_bot":
AttributeError: 'NoneType' object has no attribute 'from_user'
telegram.ext.dispatcher - ERROR - No error handlers are registered, logging exception.
Traceback (most recent call last):
  File "/home/ubuntu/.local/lib/python3.6/site-packages/telegram/ext/dispatcher.py", line 340, in process_update
    handler.handle_update(update, self, check, context)
  File "/home/ubuntu/.local/lib/python3.6/site-packages/telegram/ext/handler.py", line 119, in handle_update
    return self.callback(update, context)
  File "botik.py", line 67, in message_handler
    if random.random() < markov_chance/100 or update.message.reply_to_message.from_user.username == "puklengtime_bot":
AttributeError: 'NoneType' object has no attribute 'from_user'
telegram.ext.dispatcher - ERROR - No error handlers are registered, logging exception.
Traceback (most recent call last):
  File "/home/ubuntu/.local/lib/python3.6/site-packages/telegram/ext/dispatcher.py", line 340, in process_update
    handler.handle_update(update, self, check, context)
  File "/home/ubuntu/.local/lib/python3.6/site-packages/telegram/ext/handler.py", line 119, in handle_update
    return self.callback(update, context)
  File "botik.py", line 67, in message_handler
    if random.random() < markov_chance/100 or update.message.reply_to_message.from_user.username == "puklengtime_bot":
AttributeError: 'NoneType' object has no attribute 'from_user'
telegram.ext.dispatcher - ERROR - No error handlers are registered, logging exception.
Traceback (most recent call last):
  File "/home/ubuntu/.local/lib/python3.6/site-packages/telegram/ext/dispatcher.py", line 340, in process_update
    handler.handle_update(update, self, check, context)
  File "/home/ubuntu/.local/lib/python3.6/site-packages/telegram/ext/handler.py", line 119, in handle_update
    return self.callback(update, context)
  File "botik.py", line 67, in message_handler
    if random.random() < markov_chance/100 or update.message.reply_to_message.from_user.username == "puklengtime_bot":
AttributeError: 'NoneType' object has no attribute 'from_user'
telegram.ext.dispatcher - ERROR - No error handlers are registered, logging exception.
Traceback (most recent call last):
  File "/home/ubuntu/.local/lib/python3.6/site-packages/telegram/ext/dispatcher.py", line 340, in process_update
    handler.handle_update(update, self, check, context)
  File "/home/ubuntu/.local/lib/python3.6/site-packages/telegram/ext/handler.py", line 119, in handle_update
    return self.callback(update, context)
  File "botik.py", line 67, in message_handler
    if random.random() < markov_chance/100 or update.message.reply_to_message.from_user.username == "puklengtime_bot":
AttributeError: 'NoneType' object has no attribute 'from_user'
telegram.ext.dispatcher - ERROR - No error handlers are registered, logging exception.
Traceback (most recent call last):
  File "/home/ubuntu/.local/lib/python3.6/site-packages/telegram/ext/dispatcher.py", line 340, in process_update
    handler.handle_update(update, self, check, context)
  File "/home/ubuntu/.local/lib/python3.6/site-packages/telegram/ext/handler.py", line 119, in handle_update
    return self.callback(update, context)
  File "botik.py", line 67, in message_handler
    if random.random() < markov_chance/100 or update.message.reply_to_message.from_user.username == "puklengtime_bot":
AttributeError: 'NoneType' object has no attribute 'from_user'
telegram.ext.dispatcher - ERROR - No error handlers are registered, logging exception.
Traceback (most recent call last):
  File "/home/ubuntu/.local/lib/python3.6/site-packages/telegram/ext/dispatcher.py", line 340, in process_update
    handler.handle_update(update, self, check, context)
  File "/home/ubuntu/.local/lib/python3.6/site-packages/telegram/ext/handler.py", line 119, in handle_update
    return self.callback(update, context)
  File "botik.py", line 67, in message_handler
    if random.random() < markov_chance/100 or update.message.reply_to_message.from_user.username == "puklengtime_bot":
AttributeError: 'NoneType' object has no attribute 'from_user'
telegram.ext.dispatcher - ERROR - No error handlers are registered, logging exception.
Traceback (most recent call last):
  File "/home/ubuntu/.local/lib/python3.6/site-packages/telegram/ext/dispatcher.py", line 340, in process_update
    handler.handle_update(update, self, check, context)
  File "/home/ubuntu/.local/lib/python3.6/site-packages/telegram/ext/handler.py", line 119, in handle_update
    return self.callback(update, context)
  File "botik.py", line 67, in message_handler
    if random.random() < markov_chance/100 or update.message.reply_to_message.from_user.username == "puklengtime_bot":
AttributeError: 'NoneType' object has no attribute 'from_user'
telegram.ext.dispatcher - ERROR - No error handlers are registered, logging exception.
Traceback (most recent call last):
  File "/home/ubuntu/.local/lib/python3.6/site-packages/telegram/ext/dispatcher.py", line 340, in process_update
    handler.handle_update(update, self, check, context)
  File "/home/ubuntu/.local/lib/python3.6/site-packages/telegram/ext/handler.py", line 119, in handle_update
    return self.callback(update, context)
  File "botik.py", line 67, in message_handler
    if random.random() < markov_chance/100 or update.message.reply_to_message.from_user.username == "puklengtime_bot":
AttributeError: 'NoneType' object has no attribute 'from_user'
telegram.ext.dispatcher - ERROR - No error handlers are registered, logging exception.
Traceback (most recent call last):
  File "/home/ubuntu/.local/lib/python3.6/site-packages/telegram/ext/dispatcher.py", line 340, in process_update
    handler.handle_update(update, self, check, context)
  File "/home/ubuntu/.local/lib/python3.6/site-packages/telegram/ext/handler.py", line 119, in handle_update
    return self.callback(update, context)
  File "botik.py", line 67, in message_handler
    if random.random() < markov_chance/100 or update.message.reply_to_message.from_user.username == "puklengtime_bot":
AttributeError: 'NoneType' object has no attribute 'from_user'
telegram.ext.dispatcher - ERROR - No error handlers are registered, logging exception.
Traceback (most recent call last):
  File "/home/ubuntu/.local/lib/python3.6/site-packages/telegram/ext/dispatcher.py", line 340, in process_update
    handler.handle_update(update, self, check, context)
  File "/home/ubuntu/.local/lib/python3.6/site-packages/telegram/ext/handler.py", line 119, in handle_update
    return self.callback(update, context)
  File "botik.py", line 67, in message_handler
    if random.random() < markov_chance/100 or update.message.reply_to_message.from_user.username == "puklengtime_bot":
AttributeError: 'NoneType' object has no attribute 'from_user'
telegram.ext.dispatcher - ERROR - No error handlers are registered, logging exception.
Traceback (most recent call last):
  File "/home/ubuntu/.local/lib/python3.6/site-packages/telegram/ext/dispatcher.py", line 340, in process_update
    handler.handle_update(update, self, check, context)
  File "/home/ubuntu/.local/lib/python3.6/site-packages/telegram/ext/handler.py", line 119, in handle_update
    return self.callback(update, context)
  File "botik.py", line 67, in message_handler
    if random.random() < markov_chance/100 or update.message.reply_to_message.from_user.username == "puklengtime_bot":
AttributeError: 'NoneType' object has no attribute 'from_user'
telegram.ext.dispatcher - ERROR - No error handlers are registered, logging exception.
Traceback (most recent call last):
  File "/home/ubuntu/.local/lib/python3.6/site-packages/telegram/ext/dispatcher.py", line 340, in process_update
    handler.handle_update(update, self, check, context)
  File "/home/ubuntu/.local/lib/python3.6/site-packages/telegram/ext/handler.py", line 119, in handle_update
    return self.callback(update, context)
  File "botik.py", line 67, in message_handler
    if random.random() < markov_chance/100 or update.message.reply_to_message.from_user.username == "puklengtime_bot":
AttributeError: 'NoneType' object has no attribute 'from_user'
telegram.ext.dispatcher - ERROR - No error handlers are registered, logging exception.
Traceback (most recent call last):
  File "/home/ubuntu/.local/lib/python3.6/site-packages/telegram/ext/dispatcher.py", line 340, in process_update
    handler.handle_update(update, self, check, context)
  File "/home/ubuntu/.local/lib/python3.6/site-packages/telegram/ext/handler.py", line 119, in handle_update
    return self.callback(update, context)
  File "botik.py", line 67, in message_handler
    if random.random() < markov_chance/100 or update.message.reply_to_message.from_user.username == "puklengtime_bot":
AttributeError: 'NoneType' object has no attribute 'from_user'
telegram.ext.dispatcher - ERROR - No error handlers are registered, logging exception.
Traceback (most recent call last):
  File "/home/ubuntu/.local/lib/python3.6/site-packages/telegram/ext/dispatcher.py", line 340, in process_update
    handler.handle_update(update, self, check, context)
  File "/home/ubuntu/.local/lib/python3.6/site-packages/telegram/ext/handler.py", line 119, in handle_update
    return self.callback(update, context)
  File "botik.py", line 67, in message_handler
    if random.random() < markov_chance/100 or update.message.reply_to_message.from_user.username == "puklengtime_bot":
AttributeError: 'NoneType' object has no attribute 'from_user'
telegram.ext.dispatcher - ERROR - No error handlers are registered, logging exception.
Traceback (most recent call last):
  File "/home/ubuntu/.local/lib/python3.6/site-packages/telegram/ext/dispatcher.py", line 340, in process_update
    handler.handle_update(update, self, check, context)
  File "/home/ubuntu/.local/lib/python3.6/site-packages/telegram/ext/handler.py", line 119, in handle_update
    return self.callback(update, context)
  File "botik.py", line 67, in message_handler
    if random.random() < markov_chance/100 or update.message.reply_to_message.from_user.username == "puklengtime_bot":
AttributeError: 'NoneType' object has no attribute 'from_user'
telegram.ext.dispatcher - ERROR - No error handlers are registered, logging exception.
Traceback (most recent call last):
  File "/home/ubuntu/.local/lib/python3.6/site-packages/telegram/ext/dispatcher.py", line 340, in process_update
    handler.handle_update(update, self, check, context)
  File "/home/ubuntu/.local/lib/python3.6/site-packages/telegram/ext/handler.py", line 119, in handle_update
    return self.callback(update, context)
  File "botik.py", line 67, in message_handler
    if random.random() < markov_chance/100 or update.message.reply_to_message.from_user.username == "puklengtime_bot":
AttributeError: 'NoneType' object has no attribute 'from_user'
telegram.ext.dispatcher - ERROR - No error handlers are registered, logging exception.
Traceback (most recent call last):
  File "/home/ubuntu/.local/lib/python3.6/site-packages/telegram/ext/dispatcher.py", line 340, in process_update
    handler.handle_update(update, self, check, context)
  File "/home/ubuntu/.local/lib/python3.6/site-packages/telegram/ext/handler.py", line 119, in handle_update
    return self.callback(update, context)
  File "botik.py", line 67, in message_handler
    if random.random() < markov_chance/100 or update.message.reply_to_message.from_user.username == "puklengtime_bot":
AttributeError: 'NoneType' object has no attribute 'from_user'
telegram.ext.dispatcher - ERROR - No error handlers are registered, logging exception.
Traceback (most recent call last):
  File "/home/ubuntu/.local/lib/python3.6/site-packages/telegram/ext/dispatcher.py", line 340, in process_update
    handler.handle_update(update, self, check, context)
  File "/home/ubuntu/.local/lib/python3.6/site-packages/telegram/ext/handler.py", line 119, in handle_update
    return self.callback(update, context)
  File "botik.py", line 67, in message_handler
    if random.random() < markov_chance/100 or update.message.reply_to_message.from_user.username == "puklengtime_bot":
AttributeError: 'NoneType' object has no attribute 'from_user'
telegram.ext.dispatcher - ERROR - No error handlers are registered, logging exception.
Traceback (most recent call last):
  File "/home/ubuntu/.local/lib/python3.6/site-packages/telegram/ext/dispatcher.py", line 340, in process_update
    handler.handle_update(update, self, check, context)
  File "/home/ubuntu/.local/lib/python3.6/site-packages/telegram/ext/handler.py", line 119, in handle_update
    return self.callback(update, context)
  File "botik.py", line 67, in message_handler
    if random.random() < markov_chance/100 or update.message.reply_to_message.from_user.username == "puklengtime_bot":
AttributeError: 'NoneType' object has no attribute 'from_user'
telegram.ext.dispatcher - ERROR - No error handlers are registered, logging exception.
Traceback (most recent call last):
  File "/home/ubuntu/.local/lib/python3.6/site-packages/telegram/ext/dispatcher.py", line 340, in process_update
    handler.handle_update(update, self, check, context)
  File "/home/ubuntu/.local/lib/python3.6/site-packages/telegram/ext/handler.py", line 119, in handle_update
    return self.callback(update, context)
  File "botik.py", line 67, in message_handler
    if random.random() < markov_chance/100 or update.message.reply_to_message.from_user.username == "puklengtime_bot":
AttributeError: 'NoneType' object has no attribute 'from_user'
telegram.ext.dispatcher - ERROR - No error handlers are registered, logging exception.
Traceback (most recent call last):
  File "/home/ubuntu/.local/lib/python3.6/site-packages/telegram/ext/dispatcher.py", line 340, in process_update
    handler.handle_update(update, self, check, context)
  File "/home/ubuntu/.local/lib/python3.6/site-packages/telegram/ext/handler.py", line 119, in handle_update
    return self.callback(update, context)
  File "botik.py", line 67, in message_handler
    if random.random() < markov_chance/100 or update.message.reply_to_message.from_user.username == "puklengtime_bot":
AttributeError: 'NoneType' object has no attribute 'from_user'
telegram.ext.dispatcher - ERROR - No error handlers are registered, logging exception.
Traceback (most recent call last):
  File "/home/ubuntu/.local/lib/python3.6/site-packages/telegram/ext/dispatcher.py", line 340, in process_update
    handler.handle_update(update, self, check, context)
  File "/home/ubuntu/.local/lib/python3.6/site-packages/telegram/ext/handler.py", line 119, in handle_update
    return self.callback(update, context)
  File "botik.py", line 62, in message_handler
    message = re.sub(r'''(?i)\b((?:https?://|www\d{0,3}[.]|[a-z0-9.\-]+[.][a-z]{2,4}/)(?:[^\s()<>]+|\(([^\s()<>]+|(\([^\s()<>]+\)))*\))+(?:\(([^\s()<>]+|(\([^\s()<>]+\)))*\)|[^\s`!()\[\]{};:'".,<>?«»“”‘’]))''', " ", update.message.text)
AttributeError: 'NoneType' object has no attribute 'text'
telegram.ext.dispatcher - ERROR - No error handlers are registered, logging exception.
Traceback (most recent call last):
  File "/home/ubuntu/.local/lib/python3.6/site-packages/telegram/ext/dispatcher.py", line 340, in process_update
    handler.handle_update(update, self, check, context)
  File "/home/ubuntu/.local/lib/python3.6/site-packages/telegram/ext/handler.py", line 119, in handle_update
    return self.callback(update, context)
  File "botik.py", line 67, in message_handler
    if random.random() < markov_chance/100 or update.message.reply_to_message.from_user.username == "puklengtime_bot":
AttributeError: 'NoneType' object has no attribute 'from_user'
telegram.ext.dispatcher - ERROR - No error handlers are registered, logging exception.
Traceback (most recent call last):
  File "/home/ubuntu/.local/lib/python3.6/site-packages/telegram/ext/dispatcher.py", line 340, in process_update
    handler.handle_update(update, self, check, context)
  File "/home/ubuntu/.local/lib/python3.6/site-packages/telegram/ext/handler.py", line 119, in handle_update
    return self.callback(update, context)
  File "botik.py", line 67, in message_handler
    if random.random() < markov_chance/100 or update.message.reply_to_message.from_user.username == "puklengtime_bot":
AttributeError: 'NoneType' object has no attribute 'from_user'
telegram.ext.dispatcher - ERROR - No error handlers are registered, logging exception.
Traceback (most recent call last):
  File "/home/ubuntu/.local/lib/python3.6/site-packages/telegram/ext/dispatcher.py", line 340, in process_update
    handler.handle_update(update, self, check, context)
  File "/home/ubuntu/.local/lib/python3.6/site-packages/telegram/ext/handler.py", line 119, in handle_update
    return self.callback(update, context)
  File "botik.py", line 67, in message_handler
    if random.random() < markov_chance/100 or update.message.reply_to_message.from_user.username == "puklengtime_bot":
AttributeError: 'NoneType' object has no attribute 'from_user'
telegram.ext.dispatcher - ERROR - No error handlers are registered, logging exception.
Traceback (most recent call last):
  File "/home/ubuntu/.local/lib/python3.6/site-packages/telegram/ext/dispatcher.py", line 340, in process_update
    handler.handle_update(update, self, check, context)
  File "/home/ubuntu/.local/lib/python3.6/site-packages/telegram/ext/handler.py", line 119, in handle_update
    return self.callback(update, context)
  File "botik.py", line 67, in message_handler
    if random.random() < markov_chance/100 or update.message.reply_to_message.from_user.username == "puklengtime_bot":
AttributeError: 'NoneType' object has no attribute 'from_user'
telegram.ext.dispatcher - ERROR - No error handlers are registered, logging exception.
Traceback (most recent call last):
  File "/home/ubuntu/.local/lib/python3.6/site-packages/telegram/ext/dispatcher.py", line 340, in process_update
    handler.handle_update(update, self, check, context)
  File "/home/ubuntu/.local/lib/python3.6/site-packages/telegram/ext/handler.py", line 119, in handle_update
    return self.callback(update, context)
  File "botik.py", line 67, in message_handler
    if random.random() < markov_chance/100 or update.message.reply_to_message.from_user.username == "puklengtime_bot":
AttributeError: 'NoneType' object has no attribute 'from_user'
telegram.ext.dispatcher - ERROR - No error handlers are registered, logging exception.
Traceback (most recent call last):
  File "/home/ubuntu/.local/lib/python3.6/site-packages/telegram/ext/dispatcher.py", line 340, in process_update
    handler.handle_update(update, self, check, context)
  File "/home/ubuntu/.local/lib/python3.6/site-packages/telegram/ext/handler.py", line 119, in handle_update
    return self.callback(update, context)
  File "botik.py", line 67, in message_handler
    if random.random() < markov_chance/100 or update.message.reply_to_message.from_user.username == "puklengtime_bot":
AttributeError: 'NoneType' object has no attribute 'from_user'
telegram.ext.dispatcher - ERROR - No error handlers are registered, logging exception.
Traceback (most recent call last):
  File "/home/ubuntu/.local/lib/python3.6/site-packages/telegram/ext/dispatcher.py", line 340, in process_update
    handler.handle_update(update, self, check, context)
  File "/home/ubuntu/.local/lib/python3.6/site-packages/telegram/ext/handler.py", line 119, in handle_update
    return self.callback(update, context)
  File "botik.py", line 67, in message_handler
    if random.random() < markov_chance/100 or update.message.reply_to_message.from_user.username == "puklengtime_bot":
AttributeError: 'NoneType' object has no attribute 'from_user'
telegram.ext.dispatcher - ERROR - No error handlers are registered, logging exception.
Traceback (most recent call last):
  File "/home/ubuntu/.local/lib/python3.6/site-packages/telegram/ext/dispatcher.py", line 340, in process_update
    handler.handle_update(update, self, check, context)
  File "/home/ubuntu/.local/lib/python3.6/site-packages/telegram/ext/handler.py", line 119, in handle_update
    return self.callback(update, context)
  File "botik.py", line 67, in message_handler
    if random.random() < markov_chance/100 or update.message.reply_to_message.from_user.username == "puklengtime_bot":
AttributeError: 'NoneType' object has no attribute 'from_user'
telegram.ext.dispatcher - ERROR - No error handlers are registered, logging exception.
Traceback (most recent call last):
  File "/home/ubuntu/.local/lib/python3.6/site-packages/telegram/ext/dispatcher.py", line 340, in process_update
    handler.handle_update(update, self, check, context)
  File "/home/ubuntu/.local/lib/python3.6/site-packages/telegram/ext/handler.py", line 119, in handle_update
    return self.callback(update, context)
  File "botik.py", line 67, in message_handler
    if random.random() < markov_chance/100 or update.message.reply_to_message.from_user.username == "puklengtime_bot":
AttributeError: 'NoneType' object has no attribute 'from_user'
telegram.ext.dispatcher - ERROR - No error handlers are registered, logging exception.
Traceback (most recent call last):
  File "/home/ubuntu/.local/lib/python3.6/site-packages/telegram/ext/dispatcher.py", line 340, in process_update
    handler.handle_update(update, self, check, context)
  File "/home/ubuntu/.local/lib/python3.6/site-packages/telegram/ext/handler.py", line 119, in handle_update
    return self.callback(update, context)
  File "botik.py", line 67, in message_handler
    if random.random() < markov_chance/100 or update.message.reply_to_message.from_user.username == "puklengtime_bot":
AttributeError: 'NoneType' object has no attribute 'from_user'
telegram.ext.dispatcher - ERROR - No error handlers are registered, logging exception.
Traceback (most recent call last):
  File "/home/ubuntu/.local/lib/python3.6/site-packages/telegram/ext/dispatcher.py", line 340, in process_update
    handler.handle_update(update, self, check, context)
  File "/home/ubuntu/.local/lib/python3.6/site-packages/telegram/ext/handler.py", line 119, in handle_update
    return self.callback(update, context)
  File "botik.py", line 67, in message_handler
    if random.random() < markov_chance/100 or update.message.reply_to_message.from_user.username == "puklengtime_bot":
AttributeError: 'NoneType' object has no attribute 'from_user'
telegram.ext.dispatcher - ERROR - No error handlers are registered, logging exception.
Traceback (most recent call last):
  File "/home/ubuntu/.local/lib/python3.6/site-packages/telegram/ext/dispatcher.py", line 340, in process_update
    handler.handle_update(update, self, check, context)
  File "/home/ubuntu/.local/lib/python3.6/site-packages/telegram/ext/handler.py", line 119, in handle_update
    return self.callback(update, context)
  File "botik.py", line 67, in message_handler
    if random.random() < markov_chance/100 or update.message.reply_to_message.from_user.username == "puklengtime_bot":
AttributeError: 'NoneType' object has no attribute 'from_user'
telegram.ext.dispatcher - ERROR - No error handlers are registered, logging exception.
Traceback (most recent call last):
  File "/home/ubuntu/.local/lib/python3.6/site-packages/telegram/ext/dispatcher.py", line 340, in process_update
    handler.handle_update(update, self, check, context)
  File "/home/ubuntu/.local/lib/python3.6/site-packages/telegram/ext/handler.py", line 119, in handle_update
    return self.callback(update, context)
  File "botik.py", line 67, in message_handler
    if random.random() < markov_chance/100 or update.message.reply_to_message.from_user.username == "puklengtime_bot":
AttributeError: 'NoneType' object has no attribute 'from_user'
telegram.ext.dispatcher - ERROR - No error handlers are registered, logging exception.
Traceback (most recent call last):
  File "/home/ubuntu/.local/lib/python3.6/site-packages/telegram/ext/dispatcher.py", line 340, in process_update
    handler.handle_update(update, self, check, context)
  File "/home/ubuntu/.local/lib/python3.6/site-packages/telegram/ext/handler.py", line 119, in handle_update
    return self.callback(update, context)
  File "botik.py", line 67, in message_handler
    if random.random() < markov_chance/100 or update.message.reply_to_message.from_user.username == "puklengtime_bot":
AttributeError: 'NoneType' object has no attribute 'from_user'
telegram.ext.dispatcher - ERROR - No error handlers are registered, logging exception.
Traceback (most recent call last):
  File "/home/ubuntu/.local/lib/python3.6/site-packages/telegram/ext/dispatcher.py", line 340, in process_update
    handler.handle_update(update, self, check, context)
  File "/home/ubuntu/.local/lib/python3.6/site-packages/telegram/ext/handler.py", line 119, in handle_update
    return self.callback(update, context)
  File "botik.py", line 67, in message_handler
    if random.random() < markov_chance/100 or update.message.reply_to_message.from_user.username == "puklengtime_bot":
AttributeError: 'NoneType' object has no attribute 'from_user'
telegram.ext.dispatcher - ERROR - No error handlers are registered, logging exception.
Traceback (most recent call last):
  File "/home/ubuntu/.local/lib/python3.6/site-packages/telegram/ext/dispatcher.py", line 340, in process_update
    handler.handle_update(update, self, check, context)
  File "/home/ubuntu/.local/lib/python3.6/site-packages/telegram/ext/handler.py", line 119, in handle_update
    return self.callback(update, context)
  File "botik.py", line 67, in message_handler
    if random.random() < markov_chance/100 or update.message.reply_to_message.from_user.username == "puklengtime_bot":
AttributeError: 'NoneType' object has no attribute 'from_user'
telegram.ext.dispatcher - ERROR - No error handlers are registered, logging exception.
Traceback (most recent call last):
  File "/home/ubuntu/.local/lib/python3.6/site-packages/telegram/ext/dispatcher.py", line 340, in process_update
    handler.handle_update(update, self, check, context)
  File "/home/ubuntu/.local/lib/python3.6/site-packages/telegram/ext/handler.py", line 119, in handle_update
    return self.callback(update, context)
  File "botik.py", line 67, in message_handler
    if random.random() < markov_chance/100 or update.message.reply_to_message.from_user.username == "puklengtime_bot":
AttributeError: 'NoneType' object has no attribute 'from_user'
telegram.ext.dispatcher - ERROR - No error handlers are registered, logging exception.
Traceback (most recent call last):
  File "/home/ubuntu/.local/lib/python3.6/site-packages/telegram/ext/dispatcher.py", line 340, in process_update
    handler.handle_update(update, self, check, context)
  File "/home/ubuntu/.local/lib/python3.6/site-packages/telegram/ext/handler.py", line 119, in handle_update
    return self.callback(update, context)
  File "botik.py", line 67, in message_handler
    if random.random() < markov_chance/100 or update.message.reply_to_message.from_user.username == "puklengtime_bot":
AttributeError: 'NoneType' object has no attribute 'from_user'
telegram.ext.dispatcher - ERROR - No error handlers are registered, logging exception.
Traceback (most recent call last):
  File "/home/ubuntu/.local/lib/python3.6/site-packages/telegram/ext/dispatcher.py", line 340, in process_update
    handler.handle_update(update, self, check, context)
  File "/home/ubuntu/.local/lib/python3.6/site-packages/telegram/ext/handler.py", line 119, in handle_update
    return self.callback(update, context)
  File "botik.py", line 67, in message_handler
    if random.random() < markov_chance/100 or update.message.reply_to_message.from_user.username == "puklengtime_bot":
AttributeError: 'NoneType' object has no attribute 'from_user'
telegram.ext.dispatcher - ERROR - No error handlers are registered, logging exception.
Traceback (most recent call last):
  File "/home/ubuntu/.local/lib/python3.6/site-packages/telegram/ext/dispatcher.py", line 340, in process_update
    handler.handle_update(update, self, check, context)
  File "/home/ubuntu/.local/lib/python3.6/site-packages/telegram/ext/handler.py", line 119, in handle_update
    return self.callback(update, context)
  File "botik.py", line 67, in message_handler
    if random.random() < markov_chance/100 or update.message.reply_to_message.from_user.username == "puklengtime_bot":
AttributeError: 'NoneType' object has no attribute 'from_user'
telegram.ext.dispatcher - ERROR - No error handlers are registered, logging exception.
Traceback (most recent call last):
  File "/home/ubuntu/.local/lib/python3.6/site-packages/telegram/ext/dispatcher.py", line 340, in process_update
    handler.handle_update(update, self, check, context)
  File "/home/ubuntu/.local/lib/python3.6/site-packages/telegram/ext/handler.py", line 119, in handle_update
    return self.callback(update, context)
  File "botik.py", line 67, in message_handler
    if random.random() < markov_chance/100 or update.message.reply_to_message.from_user.username == "puklengtime_bot":
AttributeError: 'NoneType' object has no attribute 'from_user'
telegram.ext.dispatcher - ERROR - No error handlers are registered, logging exception.
Traceback (most recent call last):
  File "/home/ubuntu/.local/lib/python3.6/site-packages/telegram/ext/dispatcher.py", line 340, in process_update
    handler.handle_update(update, self, check, context)
  File "/home/ubuntu/.local/lib/python3.6/site-packages/telegram/ext/handler.py", line 119, in handle_update
    return self.callback(update, context)
  File "botik.py", line 67, in message_handler
    if random.random() < markov_chance/100 or update.message.reply_to_message.from_user.username == "puklengtime_bot":
AttributeError: 'NoneType' object has no attribute 'from_user'
telegram.ext.dispatcher - ERROR - No error handlers are registered, logging exception.
Traceback (most recent call last):
  File "/home/ubuntu/.local/lib/python3.6/site-packages/telegram/ext/dispatcher.py", line 340, in process_update
    handler.handle_update(update, self, check, context)
  File "/home/ubuntu/.local/lib/python3.6/site-packages/telegram/ext/handler.py", line 119, in handle_update
    return self.callback(update, context)
  File "botik.py", line 67, in message_handler
    if random.random() < markov_chance/100 or update.message.reply_to_message.from_user.username == "puklengtime_bot":
AttributeError: 'NoneType' object has no attribute 'from_user'
telegram.ext.dispatcher - ERROR - No error handlers are registered, logging exception.
Traceback (most recent call last):
  File "/home/ubuntu/.local/lib/python3.6/site-packages/telegram/ext/dispatcher.py", line 340, in process_update
    handler.handle_update(update, self, check, context)
  File "/home/ubuntu/.local/lib/python3.6/site-packages/telegram/ext/handler.py", line 119, in handle_update
    return self.callback(update, context)
  File "botik.py", line 67, in message_handler
    if random.random() < markov_chance/100 or update.message.reply_to_message.from_user.username == "puklengtime_bot":
AttributeError: 'NoneType' object has no attribute 'from_user'
telegram.ext.dispatcher - ERROR - No error handlers are registered, logging exception.
Traceback (most recent call last):
  File "/home/ubuntu/.local/lib/python3.6/site-packages/telegram/ext/dispatcher.py", line 340, in process_update
    handler.handle_update(update, self, check, context)
  File "/home/ubuntu/.local/lib/python3.6/site-packages/telegram/ext/handler.py", line 119, in handle_update
    return self.callback(update, context)
  File "botik.py", line 67, in message_handler
    if random.random() < markov_chance/100 or update.message.reply_to_message.from_user.username == "puklengtime_bot":
AttributeError: 'NoneType' object has no attribute 'from_user'
telegram.ext.dispatcher - ERROR - No error handlers are registered, logging exception.
Traceback (most recent call last):
  File "/home/ubuntu/.local/lib/python3.6/site-packages/telegram/ext/dispatcher.py", line 340, in process_update
    handler.handle_update(update, self, check, context)
  File "/home/ubuntu/.local/lib/python3.6/site-packages/telegram/ext/handler.py", line 119, in handle_update
    return self.callback(update, context)
  File "botik.py", line 67, in message_handler
    if random.random() < markov_chance/100 or update.message.reply_to_message.from_user.username == "puklengtime_bot":
AttributeError: 'NoneType' object has no attribute 'from_user'
telegram.ext.dispatcher - ERROR - No error handlers are registered, logging exception.
Traceback (most recent call last):
  File "/home/ubuntu/.local/lib/python3.6/site-packages/telegram/ext/dispatcher.py", line 340, in process_update
    handler.handle_update(update, self, check, context)
  File "/home/ubuntu/.local/lib/python3.6/site-packages/telegram/ext/handler.py", line 119, in handle_update
    return self.callback(update, context)
  File "botik.py", line 67, in message_handler
    if random.random() < markov_chance/100 or update.message.reply_to_message.from_user.username == "puklengtime_bot":
AttributeError: 'NoneType' object has no attribute 'from_user'
telegram.ext.dispatcher - ERROR - No error handlers are registered, logging exception.
Traceback (most recent call last):
  File "/home/ubuntu/.local/lib/python3.6/site-packages/telegram/ext/dispatcher.py", line 340, in process_update
    handler.handle_update(update, self, check, context)
  File "/home/ubuntu/.local/lib/python3.6/site-packages/telegram/ext/handler.py", line 119, in handle_update
    return self.callback(update, context)
  File "botik.py", line 67, in message_handler
    if random.random() < markov_chance/100 or update.message.reply_to_message.from_user.username == "puklengtime_bot":
AttributeError: 'NoneType' object has no attribute 'from_user'
telegram.ext.dispatcher - ERROR - No error handlers are registered, logging exception.
Traceback (most recent call last):
  File "/home/ubuntu/.local/lib/python3.6/site-packages/telegram/ext/dispatcher.py", line 340, in process_update
    handler.handle_update(update, self, check, context)
  File "/home/ubuntu/.local/lib/python3.6/site-packages/telegram/ext/handler.py", line 119, in handle_update
    return self.callback(update, context)
  File "botik.py", line 67, in message_handler
    if random.random() < markov_chance/100 or update.message.reply_to_message.from_user.username == "puklengtime_bot":
AttributeError: 'NoneType' object has no attribute 'from_user'
telegram.ext.dispatcher - ERROR - No error handlers are registered, logging exception.
Traceback (most recent call last):
  File "/home/ubuntu/.local/lib/python3.6/site-packages/telegram/ext/dispatcher.py", line 340, in process_update
    handler.handle_update(update, self, check, context)
  File "/home/ubuntu/.local/lib/python3.6/site-packages/telegram/ext/handler.py", line 119, in handle_update
    return self.callback(update, context)
  File "botik.py", line 67, in message_handler
    if random.random() < markov_chance/100 or update.message.reply_to_message.from_user.username == "puklengtime_bot":
AttributeError: 'NoneType' object has no attribute 'from_user'
telegram.ext.dispatcher - ERROR - No error handlers are registered, logging exception.
Traceback (most recent call last):
  File "/home/ubuntu/.local/lib/python3.6/site-packages/telegram/ext/dispatcher.py", line 340, in process_update
    handler.handle_update(update, self, check, context)
  File "/home/ubuntu/.local/lib/python3.6/site-packages/telegram/ext/handler.py", line 119, in handle_update
    return self.callback(update, context)
  File "botik.py", line 67, in message_handler
    if random.random() < markov_chance/100 or update.message.reply_to_message.from_user.username == "puklengtime_bot":
AttributeError: 'NoneType' object has no attribute 'from_user'
telegram.ext.dispatcher - ERROR - No error handlers are registered, logging exception.
Traceback (most recent call last):
  File "/home/ubuntu/.local/lib/python3.6/site-packages/telegram/ext/dispatcher.py", line 340, in process_update
    handler.handle_update(update, self, check, context)
  File "/home/ubuntu/.local/lib/python3.6/site-packages/telegram/ext/handler.py", line 119, in handle_update
    return self.callback(update, context)
  File "botik.py", line 67, in message_handler
    if random.random() < markov_chance/100 or update.message.reply_to_message.from_user.username == "puklengtime_bot":
AttributeError: 'NoneType' object has no attribute 'from_user'
telegram.ext.dispatcher - ERROR - No error handlers are registered, logging exception.
Traceback (most recent call last):
  File "/home/ubuntu/.local/lib/python3.6/site-packages/telegram/ext/dispatcher.py", line 340, in process_update
    handler.handle_update(update, self, check, context)
  File "/home/ubuntu/.local/lib/python3.6/site-packages/telegram/ext/handler.py", line 119, in handle_update
    return self.callback(update, context)
  File "botik.py", line 62, in message_handler
    message = re.sub(r'''(?i)\b((?:https?://|www\d{0,3}[.]|[a-z0-9.\-]+[.][a-z]{2,4}/)(?:[^\s()<>]+|\(([^\s()<>]+|(\([^\s()<>]+\)))*\))+(?:\(([^\s()<>]+|(\([^\s()<>]+\)))*\)|[^\s`!()\[\]{};:'".,<>?«»“”‘’]))''', " ", update.message.text)
AttributeError: 'NoneType' object has no attribute 'text'
telegram.ext.dispatcher - ERROR - No error handlers are registered, logging exception.
Traceback (most recent call last):
  File "/home/ubuntu/.local/lib/python3.6/site-packages/telegram/ext/dispatcher.py", line 340, in process_update
    handler.handle_update(update, self, check, context)
  File "/home/ubuntu/.local/lib/python3.6/site-packages/telegram/ext/handler.py", line 119, in handle_update
    return self.callback(update, context)
  File "botik.py", line 67, in message_handler
    if random.random() < markov_chance/100 or update.message.reply_to_message.from_user.username == "puklengtime_bot":
AttributeError: 'NoneType' object has no attribute 'from_user'
telegram.ext.dispatcher - ERROR - No error handlers are registered, logging exception.
Traceback (most recent call last):
  File "/home/ubuntu/.local/lib/python3.6/site-packages/telegram/ext/dispatcher.py", line 340, in process_update
    handler.handle_update(update, self, check, context)
  File "/home/ubuntu/.local/lib/python3.6/site-packages/telegram/ext/handler.py", line 119, in handle_update
    return self.callback(update, context)
  File "botik.py", line 67, in message_handler
    if random.random() < markov_chance/100 or update.message.reply_to_message.from_user.username == "puklengtime_bot":
AttributeError: 'NoneType' object has no attribute 'from_user'
telegram.ext.dispatcher - ERROR - No error handlers are registered, logging exception.
Traceback (most recent call last):
  File "/home/ubuntu/.local/lib/python3.6/site-packages/telegram/ext/dispatcher.py", line 340, in process_update
    handler.handle_update(update, self, check, context)
  File "/home/ubuntu/.local/lib/python3.6/site-packages/telegram/ext/handler.py", line 119, in handle_update
    return self.callback(update, context)
  File "botik.py", line 67, in message_handler
    if random.random() < markov_chance/100 or update.message.reply_to_message.from_user.username == "puklengtime_bot":
AttributeError: 'NoneType' object has no attribute 'from_user'
